{
  "version": 8,
  "blockIdVersion": 11,
  "anchorX": 0,
  "anchorY": 0,
  "anchorZ": 0,
  "blocks": [
    {
      "x": -7,
      "y": 0,
      "z": -2,
      "name": "Plant_Grass_Sharp",
      "support": 15
    },
    {
      "x": -7,
      "y": 0,
      "z": 0,
      "name": "Plant_Grass_Sharp",
      "support": 15
    },
    {
      "x": -7,
      "y": 0,
      "z": 2,
      "name": "Plant_Grass_Sharp",
      "rotation": 2
    },
    {
      "x": -6,
      "y": 0,
      "z": 0,
      "name": "Plant_Coral_Bush_Poisoned"
    },
    {
      "x": -6,
      "y": 0,
      "z": 4,
      "name": "Plant_Grass_Sharp",
      "support": 15
    },
    {
      "x": -5,
      "y": 0,
      "z": -1,
      "name": "Soil_Grass"
    },
    {
      "x": -5,
      "y": 1,
      "z": -1,
      "name": "Plant_Moss_Rug_Pink",
      "support": 15
    },
    {
      "x": -5,
      "y": 0,
      "z": 0,
      "name": "Soil_Dirt"
    },
    {
      "x": -5,
      "y": 1,
      "z": 0,
      "name": "Soil_Grass"
    },
    {
      "x": -5,
      "y": 2,
      "z": 0,
      "name": "Plant_Grass_Gnarled_Short",
      "support": 15
    },
    {
      "x": -5,
      "y": 0,
      "z": 1,
      "name": "Soil_Dirt"
    },
    {
      "x": -5,
      "y": 1,
      "z": 1,
      "name": "Soil_Grass"
    },
    {
      "x": -5,
      "y": 2,
      "z": 1,
      "name": "Plant_Moss_Rug_Pink",
      "support": 15
    },
    {
      "x": -5,
      "y": 0,
      "z": 2,
      "name": "Plant_Grass_Sharp",
      "rotation": 1
    },
    {
      "x": -5,
      "y": 0,
      "z": 3,
      "name": "Plant_Grass_Sharp"
    },
    {
      "x": -4,
      "y": 0,
      "z": -2,
      "name": "Plant_Grass_Sharp",
      "rotation": 2
    },
    {
      "x": -4,
      "y": 0,
      "z": -1,
      "name": "Soil_Dirt"
    },
    {
      "x": -4,
      "y": 1,
      "z": -1,
      "name": "Soil_Dirt"
    },
    {
      "x": -4,
      "y": 2,
      "z": -1,
      "name": "Soil_Dirt"
    },
    {
      "x": -4,
      "y": 3,
      "z": -1,
      "name": "Soil_Grass"
    },
    {
      "x": -4,
      "y": 4,
      "z": -1,
      "name": "Plant_Grass_Gnarled_Short",
      "support": 15
    },
    {
      "x": -4,
      "y": 0,
      "z": 0,
      "name": "Soil_Clay_Smooth_Purple"
    },
    {
      "x": -4,
      "y": 1,
      "z": 0,
      "name": "Soil_Clay_Smooth_Purple"
    },
    {
      "x": -4,
      "y": 2,
      "z": 0,
      "name": "Soil_Dirt"
    },
    {
      "x": -4,
      "y": 3,
      "z": 0,
      "name": "Soil_Dirt"
    },
    {
      "x": -4,
      "y": 4,
      "z": 0,
      "name": "Soil_Grass"
    },
    {
      "x": -4,
      "y": 5,
      "z": 0,
      "name": "Plant_Grass_Gnarled_Short",
      "support": 15
    },
    {
      "x": -4,
      "y": 0,
      "z": 1,
      "name": "Soil_Dirt"
    },
    {
      "x": -4,
      "y": 1,
      "z": 1,
      "name": "Plant_Crop_Mushroom_Block_Purple"
    },
    {
      "x": -4,
      "y": 2,
      "z": 1,
      "name": "Plant_Crop_Mushroom_Block_Purple"
    },
    {
      "x": -4,
      "y": 3,
      "z": 1,
      "name": "Soil_Grass"
    },
    {
      "x": -4,
      "y": 4,
      "z": 1,
      "name": "Plant_Petals_Purple"
    },
    {
      "x": -4,
      "y": 0,
      "z": 2,
      "name": "Plant_Coral_Bush_Poisoned"
    },
    {
      "x": -3,
      "y": 0,
      "z": -3,
      "name": "Plant_Grass_Sharp",
      "support": 15
    },
    {
      "x": -3,
      "y": 0,
      "z": -1,
      "name": "Soil_Dirt"
    },
    {
      "x": -3,
      "y": 1,
      "z": -1,
      "name": "Soil_Grass"
    },
    {
      "x": -3,
      "y": 4,
      "z": -1,
      "name": "Soil_Grass"
    },
    {
      "x": -3,
      "y": 5,
      "z": -1,
      "name": "Plant_Moss_Rug_Pink",
      "support": 15
    },
    {
      "x": -3,
      "y": 0,
      "z": 0,
      "name": "Plant_Crop_Mushroom_Block_Purple"
    },
    {
      "x": -3,
      "y": 1,
      "z": 0,
      "name": "Rock_Crystal_Pink_Block",
      "rotation": 5
    },
    {
      "x": -3,
      "y": 2,
      "z": 0,
      "name": "Soil_Dirt"
    },
    {
      "x": -3,
      "y": 3,
      "z": 0,
      "name": "Rock_Crystal_Pink_Block",
      "rotation": 4
    },
    {
      "x": -3,
      "y": 4,
      "z": 0,
      "name": "Soil_Grass"
    },
    {
      "x": -3,
      "y": 5,
      "z": 0,
      "name": "Plant_Grass_Sharp",
      "support": 15
    },
    {
      "x": -3,
      "y": 2,
      "z": 1,
      "name": "Soil_Dirt"
    },
    {
      "x": -3,
      "y": 3,
      "z": 1,
      "name": "Soil_Dirt"
    },
    {
      "x": -3,
      "y": 4,
      "z": 1,
      "name": "Soil_Grass"
    },
    {
      "x": -3,
      "y": 5,
      "z": 1,
      "name": "Plant_Petals_Purple"
    },
    {
      "x": -2,
      "y": 0,
      "z": 0,
      "name": "Plant_Coral_Bush_Poisoned"
    },
    {
      "x": -2,
      "y": 4,
      "z": 0,
      "name": "Soil_Dirt"
    },
    {
      "x": -2,
      "y": 5,
      "z": 0,
      "name": "Soil_Grass"
    },
    {
      "x": -2,
      "y": 6,
      "z": 0,
      "name": "Rock_Crystal_Purple_Small"
    },
    {
      "x": -2,
      "y": 3,
      "z": 1,
      "name": "Plant_Crop_Mushroom_Block_Purple"
    },
    {
      "x": -2,
      "y": 4,
      "z": 1,
      "name": "Rock_Crystal_Pink_Block",
      "rotation": 4
    },
    {
      "x": -2,
      "y": 5,
      "z": 1,
      "name": "Soil_Grass"
    },
    {
      "x": -2,
      "y": 0,
      "z": 4,
      "name": "Plant_Grass_Sharp",
      "support": 15
    },
    {
      "x": -1,
      "y": 5,
      "z": 0,
      "name": "Soil_Grass"
    },
    {
      "x": -1,
      "y": 6,
      "z": 0,
      "name": "Plant_Grass_Sharp",
      "support": 15
    },
    {
      "x": -1,
      "y": 4,
      "z": 1,
      "name": "Soil_Dirt"
    },
    {
      "x": -1,
      "y": 5,
      "z": 1,
      "name": "Soil_Grass"
    },
    {
      "x": -1,
      "y": 6,
      "z": 1,
      "name": "Plant_Grass_Sharp",
      "support": 15
    },
    {
      "x": -1,
      "y": 0,
      "z": 2,
      "name": "Plant_Grass_Sharp",
      "rotation": 2
    },
    {
      "x": -1,
      "y": 4,
      "z": 2,
      "name": "Soil_Grass"
    },
    {
      "x": -1,
      "y": 5,
      "z": 2,
      "name": "Plant_Moss_Rug_Pink",
      "support": 15
    },
    {
      "x": 0,
      "y": 0,
      "z": -2,
      "name": "Plant_Grass_Sharp",
      "support": 15
    },
    {
      "x": 0,
      "y": 0,
      "z": -1,
      "name": "Plant_Grass_Sharp",
      "rotation": 1
    },
    {
      "x": 0,
      "y": 4,
      "z": 0,
      "name": "Soil_Dirt"
    },
    {
      "x": 0,
      "y": 5,
      "z": 0,
      "name": "Soil_Grass"
    },
    {
      "x": 0,
      "y": 6,
      "z": 0,
      "name": "Plant_Petals_Purple"
    },
    {
      "x": 0,
      "y": 4,
      "z": 1,
      "name": "Soil_Grass"
    },
    {
      "x": 0,
      "y": 5,
      "z": 1,
      "name": "Plant_Grass_Gnarled_Short",
      "support": 15
    },
    {
      "x": 0,
      "y": 0,
      "z": 2,
      "name": "Plant_Grass_Sharp",
      "rotation": 2
    },
    {
      "x": 1,
      "y": 4,
      "z": -1,
      "name": "Soil_Grass"
    },
    {
      "x": 1,
      "y": 5,
      "z": -1,
      "name": "Plant_Moss_Rug_Pink",
      "support": 15
    },
    {
      "x": 1,
      "y": 4,
      "z": 0,
      "name": "Soil_Dirt"
    },
    {
      "x": 1,
      "y": 5,
      "z": 0,
      "name": "Soil_Grass"
    },
    {
      "x": 1,
      "y": 3,
      "z": 1,
      "name": "Soil_Dirt"
    },
    {
      "x": 1,
      "y": 4,
      "z": 1,
      "name": "Soil_Grass"
    },
    {
      "x": 1,
      "y": 0,
      "z": 3,
      "name": "Plant_Grass_Sharp",
      "support": 15
    },
    {
      "x": 2,
      "y": 3,
      "z": 0,
      "name": "Plant_Crop_Mushroom_Block_Purple"
    },
    {
      "x": 2,
      "y": 4,
      "z": 0,
      "name": "Soil_Grass"
    },
    {
      "x": 2,
      "y": 5,
      "z": 0,
      "name": "Plant_Grass_Sharp",
      "support": 15
    },
    {
      "x": 2,
      "y": 2,
      "z": 1,
      "name": "Soil_Dirt"
    },
    {
      "x": 2,
      "y": 3,
      "z": 1,
      "name": "Soil_Grass"
    },
    {
      "x": 2,
      "y": 4,
      "z": 1,
      "name": "Plant_Moss_Rug_Pink",
      "support": 15
    },
    {
      "x": 3,
      "y": 0,
      "z": -3,
      "name": "Plant_Grass_Sharp",
      "support": 15
    },
    {
      "x": 3,
      "y": 0,
      "z": -1,
      "name": "Plant_Coral_Bush_Poisoned"
    },
    {
      "x": 3,
      "y": 0,
      "z": 0,
      "name": "Plant_Crop_Mushroom_Block_Purple"
    },
    {
      "x": 3,
      "y": 1,
      "z": 0,
      "name": "Soil_Dirt"
    },
    {
      "x": 3,
      "y": 2,
      "z": 0,
      "name": "Rock_Crystal_Pink_Block",
      "rotation": 4
    },
    {
      "x": 3,
      "y": 3,
      "z": 0,
      "name": "Soil_Dirt"
    },
    {
      "x": 3,
      "y": 4,
      "z": 0,
      "name": "Soil_Grass"
    },
    {
      "x": 3,
      "y": 0,
      "z": 1,
      "name": "Plant_Petals_Purple"
    },
    {
      "x": 3,
      "y": 1,
      "z": 1,
      "name": "Plant_Crop_Mushroom_Block_Purple"
    },
    {
      "x": 3,
      "y": 2,
      "z": 1,
      "name": "Soil_Grass"
    },
    {
      "x": 3,
      "y": 3,
      "z": 1,
      "name": "Plant_Grass_Sharp",
      "support": 15
    },
    {
      "x": 3,
      "y": 0,
      "z": 3,
      "name": "Plant_Grass_Sharp",
      "support": 15
    },
    {
      "x": 3,
      "y": 0,
      "z": 4,
      "name": "Plant_Grass_Sharp",
      "support": 15
    },
    {
      "x": 4,
      "y": 0,
      "z": -1,
      "name": "Soil_Dirt"
    },
    {
      "x": 4,
      "y": 1,
      "z": -1,
      "name": "Soil_Dirt"
    },
    {
      "x": 4,
      "y": 2,
      "z": -1,
      "name": "Soil_Grass"
    },
    {
      "x": 4,
      "y": 3,
      "z": -1,
      "name": "Plant_Moss_Rug_Pink",
      "support": 15
    },
    {
      "x": 4,
      "y": 0,
      "z": 0,
      "name": "Soil_Dirt"
    },
    {
      "x": 4,
      "y": 1,
      "z": 0,
      "name": "Soil_Dirt"
    },
    {
      "x": 4,
      "y": 2,
      "z": 0,
      "name": "Soil_Dirt"
    },
    {
      "x": 4,
      "y": 3,
      "z": 0,
      "name": "Soil_Grass"
    },
    {
      "x": 4,
      "y": 4,
      "z": 0,
      "name": "Plant_Petals_Purple"
    },
    {
      "x": 4,
      "y": 0,
      "z": 1,
      "name": "Rock_Crystal_Pink_Block"
    },
    {
      "x": 4,
      "y": 1,
      "z": 1,
      "name": "Soil_Grass"
    },
    {
      "x": 4,
      "y": 2,
      "z": 1,
      "name": "Plant_Grass_Sharp",
      "support": 15
    },
    {
      "x": 4,
      "y": 0,
      "z": 2,
      "name": "Plant_Coral_Bush_Poisoned"
    },
    {
      "x": 5,
      "y": 0,
      "z": -1,
      "name": "Plant_Coral_Bush_Poisoned"
    },
    {
      "x": 5,
      "y": 0,
      "z": 0,
      "name": "Plant_Crop_Mushroom_Block_Purple"
    },
    {
      "x": 5,
      "y": 1,
      "z": 0,
      "name": "Soil_Grass"
    },
    {
      "x": 5,
      "y": 2,
      "z": 0,
      "name": "Plant_Grass_Gnarled_Short",
      "support": 15
    },
    {
      "x": 5,
      "y": 0,
      "z": 1,
      "name": "Plant_Moss_Rug_Pink",
      "support": 15
    },
    {
      "x": 6,
      "y": 0,
      "z": -3,
      "name": "Plant_Grass_Sharp",
      "support": 15
    },
    {
      "x": 6,
      "y": 0,
      "z": 0,
      "name": "Plant_Coral_Bush_Poisoned"
    },
    {
      "x": 6,
      "y": 0,
      "z": 2,
      "name": "Plant_Grass_Sharp",
      "support": 15
    },
    {
      "x": 6,
      "y": 0,
      "z": 3,
      "name": "Plant_Grass_Sharp",
      "support": 15
    },
    {
      "x": 7,
      "y": 0,
      "z": -1,
      "name": "Plant_Grass_Sharp",
      "support": 15
    },
    {
      "x": 7,
      "y": 0,
      "z": 4,
      "name": "Plant_Grass_Sharp",
      "rotation": 3
    }
  ],
  "fluids": [
    {
      "x": -7,
      "y": 0,
      "z": -2,
      "name": "Empty",
      "level": 0
    },
    {
      "x": -7,
      "y": 0,
      "z": 0,
      "name": "Empty",
      "level": 0
    },
    {
      "x": -7,
      "y": 0,
      "z": 2,
      "name": "Empty",
      "level": 0
    },
    {
      "x": -6,
      "y": 0,
      "z": 0,
      "name": "Empty",
      "level": 0
    },
    {
      "x": -6,
      "y": 0,
      "z": 4,
      "name": "Empty",
      "level": 0
    },
    {
      "x": -5,
      "y": 0,
      "z": -1,
      "name": "Empty",
      "level": 0
    },
    {
      "x": -5,
      "y": 1,
      "z": -1,
      "name": "Empty",
      "level": 0
    },
    {
      "x": -5,
      "y": 0,
      "z": 0,
      "name": "Empty",
      "level": 0
    },
    {
      "x": -5,
      "y": 1,
      "z": 0,
      "name": "Empty",
      "level": 0
    },
    {
      "x": -5,
      "y": 2,
      "z": 0,
      "name": "Empty",
      "level": 0
    },
    {
      "x": -5,
      "y": 0,
      "z": 1,
      "name": "Empty",
      "level": 0
    },
    {
      "x": -5,
      "y": 1,
      "z": 1,
      "name": "Empty",
      "level": 0
    },
    {
      "x": -5,
      "y": 2,
      "z": 1,
      "name": "Empty",
      "level": 0
    },
    {
      "x": -5,
      "y": 0,
      "z": 2,
      "name": "Empty",
      "level": 0
    },
    {
      "x": -5,
      "y": 0,
      "z": 3,
      "name": "Empty",
      "level": 0
    },
    {
      "x": -4,
      "y": 0,
      "z": -2,
      "name": "Empty",
      "level": 0
    },
    {
      "x": -4,
      "y": 0,
      "z": -1,
      "name": "Empty",
      "level": 0
    },
    {
      "x": -4,
      "y": 1,
      "z": -1,
      "name": "Empty",
      "level": 0
    },
    {
      "x": -4,
      "y": 2,
      "z": -1,
      "name": "Empty",
      "level": 0
    },
    {
      "x": -4,
      "y": 3,
      "z": -1,
      "name": "Empty",
      "level": 0
    },
    {
      "x": -4,
      "y": 4,
      "z": -1,
      "name": "Empty",
      "level": 0
    },
    {
      "x": -4,
      "y": 0,
      "z": 0,
      "name": "Empty",
      "level": 0
    },
    {
      "x": -4,
      "y": 1,
      "z": 0,
      "name": "Empty",
      "level": 0
    },
    {
      "x": -4,
      "y": 2,
      "z": 0,
      "name": "Empty",
      "level": 0
    },
    {
      "x": -4,
      "y": 3,
      "z": 0,
      "name": "Empty",
      "level": 0
    },
    {
      "x": -4,
      "y": 4,
      "z": 0,
      "name": "Empty",
      "level": 0
    },
    {
      "x": -4,
      "y": 5,
      "z": 0,
      "name": "Empty",
      "level": 0
    },
    {
      "x": -4,
      "y": 0,
      "z": 1,
      "name": "Empty",
      "level": 0
    },
    {
      "x": -4,
      "y": 1,
      "z": 1,
      "name": "Empty",
      "level": 0
    },
    {
      "x": -4,
      "y": 2,
      "z": 1,
      "name": "Empty",
      "level": 0
    },
    {
      "x": -4,
      "y": 3,
      "z": 1,
      "name": "Empty",
      "level": 0
    },
    {
      "x": -4,
      "y": 4,
      "z": 1,
      "name": "Empty",
      "level": 0
    },
    {
      "x": -4,
      "y": 0,
      "z": 2,
      "name": "Empty",
      "level": 0
    },
    {
      "x": -3,
      "y": 0,
      "z": -3,
      "name": "Empty",
      "level": 0
    },
    {
      "x": -3,
      "y": 0,
      "z": -1,
      "name": "Empty",
      "level": 0
    },
    {
      "x": -3,
      "y": 1,
      "z": -1,
      "name": "Empty",
      "level": 0
    },
    {
      "x": -3,
      "y": 4,
      "z": -1,
      "name": "Empty",
      "level": 0
    },
    {
      "x": -3,
      "y": 5,
      "z": -1,
      "name": "Empty",
      "level": 0
    },
    {
      "x": -3,
      "y": 0,
      "z": 0,
      "name": "Empty",
      "level": 0
    },
    {
      "x": -3,
      "y": 1,
      "z": 0,
      "name": "Empty",
      "level": 0
    },
    {
      "x": -3,
      "y": 2,
      "z": 0,
      "name": "Empty",
      "level": 0
    },
    {
      "x": -3,
      "y": 3,
      "z": 0,
      "name": "Empty",
      "level": 0
    },
    {
      "x": -3,
      "y": 4,
      "z": 0,
      "name": "Empty",
      "level": 0
    },
    {
      "x": -3,
      "y": 5,
      "z": 0,
      "name": "Empty",
      "level": 0
    },
    {
      "x": -3,
      "y": 2,
      "z": 1,
      "name": "Empty",
      "level": 0
    },
    {
      "x": -3,
      "y": 3,
      "z": 1,
      "name": "Empty",
      "level": 0
    },
    {
      "x": -3,
      "y": 4,
      "z": 1,
      "name": "Empty",
      "level": 0
    },
    {
      "x": -3,
      "y": 5,
      "z": 1,
      "name": "Empty",
      "level": 0
    },
    {
      "x": -2,
      "y": 0,
      "z": 0,
      "name": "Empty",
      "level": 0
    },
    {
      "x": -2,
      "y": 4,
      "z": 0,
      "name": "Empty",
      "level": 0
    },
    {
      "x": -2,
      "y": 5,
      "z": 0,
      "name": "Empty",
      "level": 0
    },
    {
      "x": -2,
      "y": 6,
      "z": 0,
      "name": "Empty",
      "level": 0
    },
    {
      "x": -2,
      "y": 3,
      "z": 1,
      "name": "Empty",
      "level": 0
    },
    {
      "x": -2,
      "y": 4,
      "z": 1,
      "name": "Empty",
      "level": 0
    },
    {
      "x": -2,
      "y": 5,
      "z": 1,
      "name": "Empty",
      "level": 0
    },
    {
      "x": -2,
      "y": 0,
      "z": 4,
      "name": "Empty",
      "level": 0
    },
    {
      "x": -1,
      "y": 5,
      "z": 0,
      "name": "Empty",
      "level": 0
    },
    {
      "x": -1,
      "y": 6,
      "z": 0,
      "name": "Empty",
      "level": 0
    },
    {
      "x": -1,
      "y": 4,
      "z": 1,
      "name": "Empty",
      "level": 0
    },
    {
      "x": -1,
      "y": 5,
      "z": 1,
      "name": "Empty",
      "level": 0
    },
    {
      "x": -1,
      "y": 6,
      "z": 1,
      "name": "Empty",
      "level": 0
    },
    {
      "x": -1,
      "y": 0,
      "z": 2,
      "name": "Empty",
      "level": 0
    },
    {
      "x": -1,
      "y": 4,
      "z": 2,
      "name": "Empty",
      "level": 0
    },
    {
      "x": -1,
      "y": 5,
      "z": 2,
      "name": "Empty",
      "level": 0
    },
    {
      "x": 0,
      "y": 0,
      "z": -2,
      "name": "Empty",
      "level": 0
    },
    {
      "x": 0,
      "y": 0,
      "z": -1,
      "name": "Empty",
      "level": 0
    },
    {
      "x": 0,
      "y": 4,
      "z": 0,
      "name": "Empty",
      "level": 0
    },
    {
      "x": 0,
      "y": 5,
      "z": 0,
      "name": "Empty",
      "level": 0
    },
    {
      "x": 0,
      "y": 6,
      "z": 0,
      "name": "Empty",
      "level": 0
    },
    {
      "x": 0,
      "y": 4,
      "z": 1,
      "name": "Empty",
      "level": 0
    },
    {
      "x": 0,
      "y": 5,
      "z": 1,
      "name": "Empty",
      "level": 0
    },
    {
      "x": 0,
      "y": 0,
      "z": 2,
      "name": "Empty",
      "level": 0
    },
    {
      "x": 1,
      "y": 4,
      "z": -1,
      "name": "Empty",
      "level": 0
    },
    {
      "x": 1,
      "y": 5,
      "z": -1,
      "name": "Empty",
      "level": 0
    },
    {
      "x": 1,
      "y": 4,
      "z": 0,
      "name": "Empty",
      "level": 0
    },
    {
      "x": 1,
      "y": 5,
      "z": 0,
      "name": "Empty",
      "level": 0
    },
    {
      "x": 1,
      "y": 3,
      "z": 1,
      "name": "Empty",
      "level": 0
    },
    {
      "x": 1,
      "y": 4,
      "z": 1,
      "name": "Empty",
      "level": 0
    },
    {
      "x": 1,
      "y": 0,
      "z": 3,
      "name": "Empty",
      "level": 0
    },
    {
      "x": 2,
      "y": 3,
      "z": 0,
      "name": "Empty",
      "level": 0
    },
    {
      "x": 2,
      "y": 4,
      "z": 0,
      "name": "Empty",
      "level": 0
    },
    {
      "x": 2,
      "y": 5,
      "z": 0,
      "name": "Empty",
      "level": 0
    },
    {
      "x": 2,
      "y": 2,
      "z": 1,
      "name": "Empty",
      "level": 0
    },
    {
      "x": 2,
      "y": 3,
      "z": 1,
      "name": "Empty",
      "level": 0
    },
    {
      "x": 2,
      "y": 4,
      "z": 1,
      "name": "Empty",
      "level": 0
    },
    {
      "x": 3,
      "y": 0,
      "z": -3,
      "name": "Empty",
      "level": 0
    },
    {
      "x": 3,
      "y": 0,
      "z": -1,
      "name": "Empty",
      "level": 0
    },
    {
      "x": 3,
      "y": 0,
      "z": 0,
      "name": "Empty",
      "level": 0
    },
    {
      "x": 3,
      "y": 1,
      "z": 0,
      "name": "Empty",
      "level": 0
    },
    {
      "x": 3,
      "y": 2,
      "z": 0,
      "name": "Empty",
      "level": 0
    },
    {
      "x": 3,
      "y": 3,
      "z": 0,
      "name": "Empty",
      "level": 0
    },
    {
      "x": 3,
      "y": 4,
      "z": 0,
      "name": "Empty",
      "level": 0
    },
    {
      "x": 3,
      "y": 0,
      "z": 1,
      "name": "Empty",
      "level": 0
    },
    {
      "x": 3,
      "y": 1,
      "z": 1,
      "name": "Empty",
      "level": 0
    },
    {
      "x": 3,
      "y": 2,
      "z": 1,
      "name": "Empty",
      "level": 0
    },
    {
      "x": 3,
      "y": 3,
      "z": 1,
      "name": "Empty",
      "level": 0
    },
    {
      "x": 3,
      "y": 0,
      "z": 3,
      "name": "Empty",
      "level": 0
    },
    {
      "x": 3,
      "y": 0,
      "z": 4,
      "name": "Empty",
      "level": 0
    },
    {
      "x": 4,
      "y": 0,
      "z": -1,
      "name": "Empty",
      "level": 0
    },
    {
      "x": 4,
      "y": 1,
      "z": -1,
      "name": "Empty",
      "level": 0
    },
    {
      "x": 4,
      "y": 2,
      "z": -1,
      "name": "Empty",
      "level": 0
    },
    {
      "x": 4,
      "y": 3,
      "z": -1,
      "name": "Empty",
      "level": 0
    },
    {
      "x": 4,
      "y": 0,
      "z": 0,
      "name": "Empty",
      "level": 0
    },
    {
      "x": 4,
      "y": 1,
      "z": 0,
      "name": "Empty",
      "level": 0
    },
    {
      "x": 4,
      "y": 2,
      "z": 0,
      "name": "Empty",
      "level": 0
    },
    {
      "x": 4,
      "y": 3,
      "z": 0,
      "name": "Empty",
      "level": 0
    },
    {
      "x": 4,
      "y": 4,
      "z": 0,
      "name": "Empty",
      "level": 0
    },
    {
      "x": 4,
      "y": 0,
      "z": 1,
      "name": "Empty",
      "level": 0
    },
    {
      "x": 4,
      "y": 1,
      "z": 1,
      "name": "Empty",
      "level": 0
    },
    {
      "x": 4,
      "y": 2,
      "z": 1,
      "name": "Empty",
      "level": 0
    },
    {
      "x": 4,
      "y": 0,
      "z": 2,
      "name": "Empty",
      "level": 0
    },
    {
      "x": 5,
      "y": 0,
      "z": -1,
      "name": "Empty",
      "level": 0
    },
    {
      "x": 5,
      "y": 0,
      "z": 0,
      "name": "Empty",
      "level": 0
    },
    {
      "x": 5,
      "y": 1,
      "z": 0,
      "name": "Empty",
      "level": 0
    },
    {
      "x": 5,
      "y": 2,
      "z": 0,
      "name": "Empty",
      "level": 0
    },
    {
      "x": 5,
      "y": 0,
      "z": 1,
      "name": "Empty",
      "level": 0
    },
    {
      "x": 6,
      "y": 0,
      "z": -3,
      "name": "Empty",
      "level": 0
    },
    {
      "x": 6,
      "y": 0,
      "z": 0,
      "name": "Empty",
      "level": 0
    },
    {
      "x": 6,
      "y": 0,
      "z": 2,
      "name": "Empty",
      "level": 0
    },
    {
      "x": 6,
      "y": 0,
      "z": 3,
      "name": "Empty",
      "level": 0
    },
    {
      "x": 7,
      "y": 0,
      "z": -1,
      "name": "Empty",
      "level": 0
    },
    {
      "x": 7,
      "y": 0,
      "z": 4,
      "name": "Empty",
      "level": 0
    }
  ]
}