{
  "version": 8,
  "blockIdVersion": 11,
  "anchorX": 0,
  "anchorY": 0,
  "anchorZ": 0,
  "blocks": [
    {
      "x": -3,
      "y": 21,
      "z": -2,
      "name": "Soil_Clay_Smooth_Pink"
    },
    {
      "x": -3,
      "y": 22,
      "z": -2,
      "name": "Plant_Coral_Block_Pink"
    },
    {
      "x": -3,
      "y": 21,
      "z": -1,
      "name": "Soil_Clay_Smooth_Pink"
    },
    {
      "x": -3,
      "y": 22,
      "z": -1,
      "name": "Soil_Clay_Smooth_Pink"
    },
    {
      "x": -3,
      "y": 23,
      "z": -1,
      "name": "Plant_Coral_Block_Pink"
    },
    {
      "x": -3,
      "y": 10,
      "z": 0,
      "name": "Furniture_Kweebec_Ladder",
      "rotation": 3
    },
    {
      "x": -3,
      "y": 11,
      "z": 0,
      "name": "Furniture_Kweebec_Ladder",
      "rotation": 3
    },
    {
      "x": -3,
      "y": 12,
      "z": 0,
      "name": "Furniture_Kweebec_Ladder",
      "rotation": 3
    },
    {
      "x": -3,
      "y": 13,
      "z": 0,
      "name": "Furniture_Kweebec_Ladder",
      "rotation": 3
    },
    {
      "x": -3,
      "y": 20,
      "z": 0,
      "name": "Soil_Clay_Smooth_Pink"
    },
    {
      "x": -3,
      "y": 21,
      "z": 0,
      "name": "Soil_Clay_Smooth_Pink"
    },
    {
      "x": -3,
      "y": 22,
      "z": 0,
      "name": "Rock_Crystal_Pink_Large",
      "rotation": 8
    },
    {
      "x": -3,
      "y": 23,
      "z": 0,
      "name": "Soil_Clay_Smooth_Pink"
    },
    {
      "x": -3,
      "y": 21,
      "z": 1,
      "name": "Soil_Clay_Smooth_Pink"
    },
    {
      "x": -3,
      "y": 22,
      "z": 1,
      "name": "Soil_Clay_Smooth_Pink"
    },
    {
      "x": -3,
      "y": 23,
      "z": 1,
      "name": "Soil_Clay_Smooth_Pink"
    },
    {
      "x": -3,
      "y": 22,
      "z": 2,
      "name": "Soil_Clay_Smooth_Pink"
    },
    {
      "x": -2,
      "y": 21,
      "z": -3,
      "name": "Plant_Coral_Block_Pink"
    },
    {
      "x": -2,
      "y": 22,
      "z": -3,
      "name": "Soil_Clay_Smooth_Pink"
    },
    {
      "x": -2,
      "y": 14,
      "z": -2,
      "name": "Rock_Crystal_Pink_Large",
      "rotation": 7
    },
    {
      "x": -2,
      "y": 15,
      "z": -2,
      "name": "Furniture_Scarak_Hive_Ladder"
    },
    {
      "x": -2,
      "y": 16,
      "z": -2,
      "name": "Furniture_Scarak_Hive_Ladder"
    },
    {
      "x": -2,
      "y": 17,
      "z": -2,
      "name": "Furniture_Scarak_Hive_Ladder"
    },
    {
      "x": -2,
      "y": 18,
      "z": -2,
      "name": "Furniture_Scarak_Hive_Ladder"
    },
    {
      "x": -2,
      "y": 19,
      "z": -2,
      "name": "Furniture_Scarak_Hive_Ladder"
    },
    {
      "x": -2,
      "y": 20,
      "z": -2,
      "name": "Soil_Clay_Smooth_Pink"
    },
    {
      "x": -2,
      "y": 21,
      "z": -2,
      "name": "Soil_Clay_Smooth_Pink"
    },
    {
      "x": -2,
      "y": 22,
      "z": -2,
      "name": "Soil_Clay_Smooth_Pink"
    },
    {
      "x": -2,
      "y": 23,
      "z": -2,
      "name": "Soil_Clay_Smooth_Pink"
    },
    {
      "x": -2,
      "y": 13,
      "z": -1,
      "name": "Wood_Lightwood_Planks_Half",
      "rotation": 8
    },
    {
      "x": -2,
      "y": 14,
      "z": -1,
      "name": "Wood_Lightwood_Planks"
    },
    {
      "x": -2,
      "y": 19,
      "z": -1,
      "name": "Rock_Crystal_Pink_Large",
      "rotation": 8
    },
    {
      "x": -2,
      "y": 20,
      "z": -1,
      "name": "Soil_Clay_Smooth_Pink"
    },
    {
      "x": -2,
      "y": 21,
      "z": -1,
      "name": "Soil_Clay_Smooth_Pink"
    },
    {
      "x": -2,
      "y": 22,
      "z": -1,
      "name": "Soil_Clay_Smooth_Pink"
    },
    {
      "x": -2,
      "y": 23,
      "z": -1,
      "name": "Soil_Clay_Smooth_Pink"
    },
    {
      "x": -2,
      "y": 24,
      "z": -1,
      "name": "Soil_Clay_Smooth_Pink"
    },
    {
      "x": -2,
      "y": 13,
      "z": 0,
      "name": "Wood_Lightwood_Planks"
    },
    {
      "x": -2,
      "y": 18,
      "z": 0,
      "name": "Plant_Coral_Block_Pink"
    },
    {
      "x": -2,
      "y": 19,
      "z": 0,
      "name": "Soil_Clay_Smooth_Pink"
    },
    {
      "x": -2,
      "y": 20,
      "z": 0,
      "name": "Soil_Clay_Smooth_Pink"
    },
    {
      "x": -2,
      "y": 21,
      "z": 0,
      "name": "Soil_Clay_Smooth_Pink"
    },
    {
      "x": -2,
      "y": 22,
      "z": 0,
      "name": "Soil_Clay_Smooth_Pink"
    },
    {
      "x": -2,
      "y": 23,
      "z": 0,
      "name": "Soil_Clay_Smooth_Pink"
    },
    {
      "x": -2,
      "y": 24,
      "z": 0,
      "name": "Plant_Coral_Block_Pink"
    },
    {
      "x": -2,
      "y": 13,
      "z": 1,
      "name": "Wood_Lightwood_Planks_Half",
      "rotation": 8
    },
    {
      "x": -2,
      "y": 14,
      "z": 1,
      "name": "Wood_Lightwood_Planks"
    },
    {
      "x": -2,
      "y": 19,
      "z": 1,
      "name": "Plant_Coral_Block_Pink"
    },
    {
      "x": -2,
      "y": 20,
      "z": 1,
      "name": "Soil_Clay_Smooth_Pink"
    },
    {
      "x": -2,
      "y": 21,
      "z": 1,
      "name": "Soil_Clay_Smooth_Pink"
    },
    {
      "x": -2,
      "y": 22,
      "z": 1,
      "name": "Soil_Clay_Smooth_Pink"
    },
    {
      "x": -2,
      "y": 23,
      "z": 1,
      "name": "Soil_Clay_Smooth_Pink"
    },
    {
      "x": -2,
      "y": 24,
      "z": 1,
      "name": "Plant_Coral_Block_Pink"
    },
    {
      "x": -2,
      "y": 14,
      "z": 2,
      "name": "Rock_Crystal_Pink_Large",
      "rotation": 4
    },
    {
      "x": -2,
      "y": 15,
      "z": 2,
      "name": "Furniture_Scarak_Hive_Ladder"
    },
    {
      "x": -2,
      "y": 16,
      "z": 2,
      "name": "Furniture_Scarak_Hive_Ladder"
    },
    {
      "x": -2,
      "y": 17,
      "z": 2,
      "name": "Furniture_Scarak_Hive_Ladder"
    },
    {
      "x": -2,
      "y": 18,
      "z": 2,
      "name": "Furniture_Scarak_Hive_Ladder"
    },
    {
      "x": -2,
      "y": 19,
      "z": 2,
      "name": "Furniture_Scarak_Hive_Ladder"
    },
    {
      "x": -2,
      "y": 20,
      "z": 2,
      "name": "Plant_Coral_Block_Pink"
    },
    {
      "x": -2,
      "y": 21,
      "z": 2,
      "name": "Soil_Clay_Smooth_Pink"
    },
    {
      "x": -2,
      "y": 22,
      "z": 2,
      "name": "Soil_Clay_Smooth_Pink"
    },
    {
      "x": -2,
      "y": 23,
      "z": 2,
      "name": "Plant_Coral_Block_Pink"
    },
    {
      "x": -1,
      "y": 21,
      "z": -3,
      "name": "Soil_Clay_Smooth_Pink"
    },
    {
      "x": -1,
      "y": 22,
      "z": -3,
      "name": "Soil_Clay_Smooth_Pink"
    },
    {
      "x": -1,
      "y": 23,
      "z": -3,
      "name": "Soil_Clay_Smooth_Pink"
    },
    {
      "x": -1,
      "y": 13,
      "z": -2,
      "name": "Wood_Lightwood_Planks_Half",
      "rotation": 8
    },
    {
      "x": -1,
      "y": 14,
      "z": -2,
      "name": "Wood_Lightwood_Planks"
    },
    {
      "x": -1,
      "y": 19,
      "z": -2,
      "name": "Soil_Clay_Smooth_Pink"
    },
    {
      "x": -1,
      "y": 20,
      "z": -2,
      "name": "Plant_Coral_Block_Pink"
    },
    {
      "x": -1,
      "y": 21,
      "z": -2,
      "name": "Soil_Clay_Smooth_Pink"
    },
    {
      "x": -1,
      "y": 22,
      "z": -2,
      "name": "Soil_Clay_Smooth_Pink"
    },
    {
      "x": -1,
      "y": 23,
      "z": -2,
      "name": "Soil_Clay_Smooth_Pink"
    },
    {
      "x": -1,
      "y": 24,
      "z": -2,
      "name": "Soil_Clay_Smooth_Pink"
    },
    {
      "x": -1,
      "y": 13,
      "z": -1,
      "name": "Wood_Lightwood_Planks"
    },
    {
      "x": -1,
      "y": 18,
      "z": -1,
      "name": "Plant_Coral_Block_Pink"
    },
    {
      "x": -1,
      "y": 19,
      "z": -1,
      "name": "Soil_Clay_Smooth_Pink"
    },
    {
      "x": -1,
      "y": 24,
      "z": -1,
      "name": "Soil_Clay_Smooth_Pink"
    },
    {
      "x": -1,
      "y": 13,
      "z": 0,
      "name": "Wood_Lightwood_Planks"
    },
    {
      "x": -1,
      "y": 17,
      "z": 0,
      "name": "Soil_Clay_Smooth_Pink"
    },
    {
      "x": -1,
      "y": 24,
      "z": 0,
      "name": "Soil_Clay_Smooth_Pink"
    },
    {
      "x": -1,
      "y": 13,
      "z": 1,
      "name": "Wood_Lightwood_Planks"
    },
    {
      "x": -1,
      "y": 18,
      "z": 1,
      "name": "Soil_Clay_Smooth_Pink"
    },
    {
      "x": -1,
      "y": 24,
      "z": 1,
      "name": "Soil_Clay_Smooth_Pink"
    },
    {
      "x": -1,
      "y": 13,
      "z": 2,
      "name": "Wood_Lightwood_Planks_Half",
      "rotation": 8
    },
    {
      "x": -1,
      "y": 14,
      "z": 2,
      "name": "Wood_Lightwood_Planks"
    },
    {
      "x": -1,
      "y": 19,
      "z": 2,
      "name": "Soil_Clay_Smooth_Pink"
    },
    {
      "x": -1,
      "y": 20,
      "z": 2,
      "name": "Soil_Clay_Smooth_Pink"
    },
    {
      "x": -1,
      "y": 21,
      "z": 2,
      "name": "Soil_Clay_Smooth_Pink"
    },
    {
      "x": -1,
      "y": 22,
      "z": 2,
      "name": "Soil_Clay_Smooth_Pink"
    },
    {
      "x": -1,
      "y": 23,
      "z": 2,
      "name": "Soil_Clay_Smooth_Pink"
    },
    {
      "x": -1,
      "y": 24,
      "z": 2,
      "name": "Soil_Clay_Smooth_Pink"
    },
    {
      "x": -1,
      "y": 21,
      "z": 3,
      "name": "Plant_Coral_Block_Pink"
    },
    {
      "x": -1,
      "y": 22,
      "z": 3,
      "name": "Soil_Clay_Smooth_Pink"
    },
    {
      "x": 0,
      "y": 14,
      "z": -3,
      "name": "Wood_Lightwood_Planks_Half",
      "rotation": 6
    },
    {
      "x": 0,
      "y": 20,
      "z": -3,
      "name": "Soil_Clay_Smooth_Pink"
    },
    {
      "x": 0,
      "y": 21,
      "z": -3,
      "name": "Rock_Crystal_Pink_Large",
      "rotation": 7
    },
    {
      "x": 0,
      "y": 22,
      "z": -3,
      "name": "Soil_Clay_Smooth_Pink"
    },
    {
      "x": 0,
      "y": 23,
      "z": -3,
      "name": "Soil_Clay_Smooth_Pink"
    },
    {
      "x": 0,
      "y": 13,
      "z": -2,
      "name": "Wood_Lightwood_Planks"
    },
    {
      "x": 0,
      "y": 14,
      "z": -2,
      "name": "Wood_Lightwood_Planks_Half",
      "rotation": 4
    },
    {
      "x": 0,
      "y": 18,
      "z": -2,
      "name": "Soil_Clay_Smooth_Pink"
    },
    {
      "x": 0,
      "y": 19,
      "z": -2,
      "name": "Plant_Coral_Block_Pink"
    },
    {
      "x": 0,
      "y": 20,
      "z": -2,
      "name": "Soil_Clay_Smooth_Pink"
    },
    {
      "x": 0,
      "y": 21,
      "z": -2,
      "name": "Soil_Clay_Smooth_Pink"
    },
    {
      "x": 0,
      "y": 22,
      "z": -2,
      "name": "Soil_Clay_Smooth_Pink"
    },
    {
      "x": 0,
      "y": 23,
      "z": -2,
      "name": "Soil_Clay_Smooth_Pink"
    },
    {
      "x": 0,
      "y": 24,
      "z": -2,
      "name": "Soil_Clay_Smooth_Pink"
    },
    {
      "x": 0,
      "y": 13,
      "z": -1,
      "name": "Wood_Lightwood_Planks"
    },
    {
      "x": 0,
      "y": 17,
      "z": -1,
      "name": "Soil_Clay_Smooth_Pink"
    },
    {
      "x": 0,
      "y": 24,
      "z": -1,
      "name": "Soil_Clay_Smooth_Pink"
    },
    {
      "x": 0,
      "y": 12,
      "z": 0,
      "name": "Wood_Lightwood_Planks_Half",
      "rotation": 8
    },
    {
      "x": 0,
      "y": 13,
      "z": 0,
      "name": "Wood_Lightwood_Planks"
    },
    {
      "x": 0,
      "y": 14,
      "z": 0,
      "name": "Deco_Rope"
    },
    {
      "x": 0,
      "y": 15,
      "z": 0,
      "name": "Deco_Rope"
    },
    {
      "x": 0,
      "y": 16,
      "z": 0,
      "name": "Deco_Rope"
    },
    {
      "x": 0,
      "y": 17,
      "z": 0,
      "name": "Deco_Rope"
    },
    {
      "x": 0,
      "y": 18,
      "z": 0,
      "name": "Deco_Rope"
    },
    {
      "x": 0,
      "y": 19,
      "z": 0,
      "name": "Deco_Rope"
    },
    {
      "x": 0,
      "y": 20,
      "z": 0,
      "name": "Deco_Rope"
    },
    {
      "x": 0,
      "y": 21,
      "z": 0,
      "name": "Deco_Rope"
    },
    {
      "x": 0,
      "y": 22,
      "z": 0,
      "name": "Deco_Rope"
    },
    {
      "x": 0,
      "y": 23,
      "z": 0,
      "name": "Wood_Lightwood_Planks"
    },
    {
      "x": 0,
      "y": 24,
      "z": 0,
      "name": "Soil_Clay_Smooth_Pink"
    },
    {
      "x": 0,
      "y": 25,
      "z": 0,
      "name": "Soil_Clay_Smooth_Pink"
    },
    {
      "x": 0,
      "y": 13,
      "z": 1,
      "name": "Wood_Lightwood_Planks"
    },
    {
      "x": 0,
      "y": 17,
      "z": 1,
      "name": "Soil_Clay_Smooth_Pink"
    },
    {
      "x": 0,
      "y": 18,
      "z": 1,
      "name": "Soil_Clay_Smooth_Pink"
    },
    {
      "x": 0,
      "y": 24,
      "z": 1,
      "name": "Soil_Clay_Smooth_Pink"
    },
    {
      "x": 0,
      "y": 25,
      "z": 1,
      "name": "Soil_Clay_Smooth_Pink"
    },
    {
      "x": 0,
      "y": 13,
      "z": 2,
      "name": "Wood_Lightwood_Planks"
    },
    {
      "x": 0,
      "y": 14,
      "z": 2,
      "name": "Wood_Lightwood_Planks_Half",
      "rotation": 6
    },
    {
      "x": 0,
      "y": 18,
      "z": 2,
      "name": "Soil_Clay_Smooth_Pink"
    },
    {
      "x": 0,
      "y": 19,
      "z": 2,
      "name": "Rock_Crystal_Pink_Large",
      "rotation": 8
    },
    {
      "x": 0,
      "y": 20,
      "z": 2,
      "name": "Soil_Clay_Smooth_Pink"
    },
    {
      "x": 0,
      "y": 21,
      "z": 2,
      "name": "Soil_Clay_Smooth_Pink"
    },
    {
      "x": 0,
      "y": 22,
      "z": 2,
      "name": "Soil_Clay_Smooth_Pink"
    },
    {
      "x": 0,
      "y": 23,
      "z": 2,
      "name": "Soil_Clay_Smooth_Pink"
    },
    {
      "x": 0,
      "y": 24,
      "z": 2,
      "name": "Soil_Clay_Smooth_Pink"
    },
    {
      "x": 0,
      "y": 14,
      "z": 3,
      "name": "Wood_Lightwood_Planks_Half",
      "rotation": 4
    },
    {
      "x": 0,
      "y": 20,
      "z": 3,
      "name": "Plant_Coral_Block_Pink"
    },
    {
      "x": 0,
      "y": 21,
      "z": 3,
      "name": "Soil_Clay_Smooth_Pink"
    },
    {
      "x": 0,
      "y": 22,
      "z": 3,
      "name": "Soil_Clay_Smooth_Pink"
    },
    {
      "x": 0,
      "y": 23,
      "z": 3,
      "name": "Soil_Clay_Smooth_Pink"
    },
    {
      "x": 1,
      "y": 21,
      "z": -3,
      "name": "Soil_Clay_Smooth_Pink"
    },
    {
      "x": 1,
      "y": 22,
      "z": -3,
      "name": "Soil_Clay_Smooth_Pink"
    },
    {
      "x": 1,
      "y": 23,
      "z": -3,
      "name": "Soil_Clay_Smooth_Pink"
    },
    {
      "x": 1,
      "y": 13,
      "z": -2,
      "name": "Wood_Lightwood_Planks_Half",
      "rotation": 8
    },
    {
      "x": 1,
      "y": 14,
      "z": -2,
      "name": "Wood_Lightwood_Planks"
    },
    {
      "x": 1,
      "y": 19,
      "z": -2,
      "name": "Plant_Coral_Block_Pink"
    },
    {
      "x": 1,
      "y": 20,
      "z": -2,
      "name": "Soil_Clay_Smooth_Pink"
    },
    {
      "x": 1,
      "y": 21,
      "z": -2,
      "name": "Soil_Clay_Smooth_Pink"
    },
    {
      "x": 1,
      "y": 22,
      "z": -2,
      "name": "Soil_Clay_Smooth_Pink"
    },
    {
      "x": 1,
      "y": 23,
      "z": -2,
      "name": "Soil_Clay_Smooth_Pink"
    },
    {
      "x": 1,
      "y": 24,
      "z": -2,
      "name": "Soil_Clay_Smooth_Pink"
    },
    {
      "x": 1,
      "y": 13,
      "z": -1,
      "name": "Wood_Lightwood_Planks"
    },
    {
      "x": 1,
      "y": 18,
      "z": -1,
      "name": "Soil_Clay_Smooth_Pink"
    },
    {
      "x": 1,
      "y": 19,
      "z": -1,
      "name": "Plant_Coral_Block_Pink"
    },
    {
      "x": 1,
      "y": 24,
      "z": -1,
      "name": "Soil_Clay_Smooth_Pink"
    },
    {
      "x": 1,
      "y": 13,
      "z": 0,
      "name": "Wood_Lightwood_Planks"
    },
    {
      "x": 1,
      "y": 17,
      "z": 0,
      "name": "Soil_Clay_Smooth_Pink"
    },
    {
      "x": 1,
      "y": 18,
      "z": 0,
      "name": "Soil_Clay_Smooth_Pink"
    },
    {
      "x": 1,
      "y": 24,
      "z": 0,
      "name": "Soil_Clay_Smooth_Pink"
    },
    {
      "x": 1,
      "y": 25,
      "z": 0,
      "name": "Soil_Clay_Smooth_Pink"
    },
    {
      "x": 1,
      "y": 13,
      "z": 1,
      "name": "Wood_Lightwood_Planks"
    },
    {
      "x": 1,
      "y": 18,
      "z": 1,
      "name": "Soil_Clay_Smooth_Pink"
    },
    {
      "x": 1,
      "y": 24,
      "z": 1,
      "name": "Soil_Clay_Smooth_Pink"
    },
    {
      "x": 1,
      "y": 13,
      "z": 2,
      "name": "Wood_Lightwood_Planks_Half",
      "rotation": 8
    },
    {
      "x": 1,
      "y": 14,
      "z": 2,
      "name": "Wood_Lightwood_Planks"
    },
    {
      "x": 1,
      "y": 19,
      "z": 2,
      "name": "Soil_Clay_Smooth_Pink"
    },
    {
      "x": 1,
      "y": 20,
      "z": 2,
      "name": "Soil_Clay_Smooth_Pink"
    },
    {
      "x": 1,
      "y": 21,
      "z": 2,
      "name": "Soil_Clay_Smooth_Pink"
    },
    {
      "x": 1,
      "y": 22,
      "z": 2,
      "name": "Soil_Clay_Smooth_Pink"
    },
    {
      "x": 1,
      "y": 23,
      "z": 2,
      "name": "Soil_Clay_Smooth_Pink"
    },
    {
      "x": 1,
      "y": 24,
      "z": 2,
      "name": "Rock_Crystal_Pink_Large",
      "rotation": 4
    },
    {
      "x": 1,
      "y": 20,
      "z": 3,
      "name": "Plant_Coral_Block_Pink"
    },
    {
      "x": 1,
      "y": 21,
      "z": 3,
      "name": "Soil_Clay_Smooth_Pink"
    },
    {
      "x": 1,
      "y": 22,
      "z": 3,
      "name": "Rock_Crystal_Pink_Large"
    },
    {
      "x": 1,
      "y": 23,
      "z": 3,
      "name": "Soil_Clay_Smooth_Pink"
    },
    {
      "x": 2,
      "y": 21,
      "z": -3,
      "name": "Soil_Clay_Smooth_Pink"
    },
    {
      "x": 2,
      "y": 22,
      "z": -3,
      "name": "Soil_Clay_Smooth_Pink"
    },
    {
      "x": 2,
      "y": 14,
      "z": -2,
      "name": "Rock_Crystal_Pink_Large",
      "rotation": 6
    },
    {
      "x": 2,
      "y": 15,
      "z": -2,
      "name": "Furniture_Scarak_Hive_Ladder"
    },
    {
      "x": 2,
      "y": 16,
      "z": -2,
      "name": "Furniture_Scarak_Hive_Ladder"
    },
    {
      "x": 2,
      "y": 17,
      "z": -2,
      "name": "Furniture_Scarak_Hive_Ladder"
    },
    {
      "x": 2,
      "y": 18,
      "z": -2,
      "name": "Furniture_Scarak_Hive_Ladder"
    },
    {
      "x": 2,
      "y": 19,
      "z": -2,
      "name": "Furniture_Scarak_Hive_Ladder"
    },
    {
      "x": 2,
      "y": 20,
      "z": -2,
      "name": "Soil_Clay_Smooth_Pink"
    },
    {
      "x": 2,
      "y": 21,
      "z": -2,
      "name": "Soil_Clay_Smooth_Pink"
    },
    {
      "x": 2,
      "y": 22,
      "z": -2,
      "name": "Soil_Clay_Smooth_Pink"
    },
    {
      "x": 2,
      "y": 23,
      "z": -2,
      "name": "Soil_Clay_Smooth_Pink"
    },
    {
      "x": 2,
      "y": 13,
      "z": -1,
      "name": "Wood_Lightwood_Planks_Half",
      "rotation": 8
    },
    {
      "x": 2,
      "y": 14,
      "z": -1,
      "name": "Wood_Lightwood_Planks"
    },
    {
      "x": 2,
      "y": 20,
      "z": -1,
      "name": "Soil_Clay_Smooth_Pink"
    },
    {
      "x": 2,
      "y": 21,
      "z": -1,
      "name": "Soil_Clay_Smooth_Pink"
    },
    {
      "x": 2,
      "y": 22,
      "z": -1,
      "name": "Soil_Clay_Smooth_Pink"
    },
    {
      "x": 2,
      "y": 23,
      "z": -1,
      "name": "Soil_Clay_Smooth_Pink"
    },
    {
      "x": 2,
      "y": 24,
      "z": -1,
      "name": "Soil_Clay_Smooth_Pink"
    },
    {
      "x": 2,
      "y": 13,
      "z": 0,
      "name": "Wood_Lightwood_Planks"
    },
    {
      "x": 2,
      "y": 14,
      "z": 0,
      "name": "Wood_Lightwood_Planks_Half",
      "rotation": 7
    },
    {
      "x": 2,
      "y": 19,
      "z": 0,
      "name": "Soil_Clay_Smooth_Pink"
    },
    {
      "x": 2,
      "y": 20,
      "z": 0,
      "name": "Soil_Clay_Smooth_Pink"
    },
    {
      "x": 2,
      "y": 21,
      "z": 0,
      "name": "Soil_Clay_Smooth_Pink"
    },
    {
      "x": 2,
      "y": 22,
      "z": 0,
      "name": "Soil_Clay_Smooth_Pink"
    },
    {
      "x": 2,
      "y": 23,
      "z": 0,
      "name": "Soil_Clay_Smooth_Pink"
    },
    {
      "x": 2,
      "y": 24,
      "z": 0,
      "name": "Soil_Clay_Smooth_Pink"
    },
    {
      "x": 2,
      "y": 13,
      "z": 1,
      "name": "Wood_Lightwood_Planks_Half",
      "rotation": 8
    },
    {
      "x": 2,
      "y": 14,
      "z": 1,
      "name": "Wood_Lightwood_Planks"
    },
    {
      "x": 2,
      "y": 19,
      "z": 1,
      "name": "Soil_Clay_Smooth_Pink"
    },
    {
      "x": 2,
      "y": 20,
      "z": 1,
      "name": "Rock_Crystal_Pink_Large",
      "rotation": 8
    },
    {
      "x": 2,
      "y": 21,
      "z": 1,
      "name": "Soil_Clay_Smooth_Pink"
    },
    {
      "x": 2,
      "y": 22,
      "z": 1,
      "name": "Soil_Clay_Smooth_Pink"
    },
    {
      "x": 2,
      "y": 23,
      "z": 1,
      "name": "Soil_Clay_Smooth_Pink"
    },
    {
      "x": 2,
      "y": 24,
      "z": 1,
      "name": "Soil_Clay_Smooth_Pink"
    },
    {
      "x": 2,
      "y": 14,
      "z": 2,
      "name": "Rock_Crystal_Pink_Large",
      "rotation": 5
    },
    {
      "x": 2,
      "y": 15,
      "z": 2,
      "name": "Furniture_Scarak_Hive_Ladder"
    },
    {
      "x": 2,
      "y": 16,
      "z": 2,
      "name": "Furniture_Scarak_Hive_Ladder"
    },
    {
      "x": 2,
      "y": 17,
      "z": 2,
      "name": "Furniture_Scarak_Hive_Ladder"
    },
    {
      "x": 2,
      "y": 18,
      "z": 2,
      "name": "Furniture_Scarak_Hive_Ladder"
    },
    {
      "x": 2,
      "y": 19,
      "z": 2,
      "name": "Furniture_Scarak_Hive_Ladder"
    },
    {
      "x": 2,
      "y": 20,
      "z": 2,
      "name": "Soil_Clay_Smooth_Pink"
    },
    {
      "x": 2,
      "y": 21,
      "z": 2,
      "name": "Soil_Clay_Smooth_Pink"
    },
    {
      "x": 2,
      "y": 22,
      "z": 2,
      "name": "Soil_Clay_Smooth_Pink"
    },
    {
      "x": 2,
      "y": 23,
      "z": 2,
      "name": "Soil_Clay_Smooth_Pink"
    },
    {
      "x": 2,
      "y": 24,
      "z": 2,
      "name": "Soil_Clay_Smooth_Pink"
    },
    {
      "x": 2,
      "y": 21,
      "z": 3,
      "name": "Soil_Clay_Smooth_Pink"
    },
    {
      "x": 2,
      "y": 22,
      "z": 3,
      "name": "Soil_Clay_Smooth_Pink"
    },
    {
      "x": 3,
      "y": 21,
      "z": -2,
      "name": "Soil_Clay_Smooth_Pink"
    },
    {
      "x": 3,
      "y": 22,
      "z": -2,
      "name": "Soil_Clay_Smooth_Pink"
    },
    {
      "x": 3,
      "y": 23,
      "z": -2,
      "name": "Soil_Clay_Smooth_Pink"
    },
    {
      "x": 3,
      "y": 20,
      "z": -1,
      "name": "Soil_Clay_Smooth_Pink"
    },
    {
      "x": 3,
      "y": 21,
      "z": -1,
      "name": "Soil_Clay_Smooth_Pink"
    },
    {
      "x": 3,
      "y": 22,
      "z": -1,
      "name": "Soil_Clay_Smooth_Pink"
    },
    {
      "x": 3,
      "y": 23,
      "z": -1,
      "name": "Soil_Clay_Smooth_Pink"
    },
    {
      "x": 3,
      "y": 14,
      "z": 0,
      "name": "Wood_Lightwood_Planks_Half",
      "rotation": 5
    },
    {
      "x": 3,
      "y": 20,
      "z": 0,
      "name": "Soil_Clay_Smooth_Pink"
    },
    {
      "x": 3,
      "y": 21,
      "z": 0,
      "name": "Soil_Clay_Smooth_Pink"
    },
    {
      "x": 3,
      "y": 22,
      "z": 0,
      "name": "Soil_Clay_Smooth_Pink"
    },
    {
      "x": 3,
      "y": 23,
      "z": 0,
      "name": "Soil_Clay_Smooth_Pink"
    },
    {
      "x": 3,
      "y": 21,
      "z": 1,
      "name": "Soil_Clay_Smooth_Pink"
    },
    {
      "x": 3,
      "y": 22,
      "z": 1,
      "name": "Soil_Clay_Smooth_Pink"
    },
    {
      "x": 3,
      "y": 23,
      "z": 1,
      "name": "Soil_Clay_Smooth_Pink"
    },
    {
      "x": 3,
      "y": 21,
      "z": 2,
      "name": "Soil_Clay_Smooth_Pink"
    },
    {
      "x": 3,
      "y": 22,
      "z": 2,
      "name": "Soil_Clay_Smooth_Pink"
    },
    {
      "x": 4,
      "y": 21,
      "z": -1,
      "name": "Soil_Clay_Smooth_Pink"
    },
    {
      "x": 4,
      "y": 22,
      "z": -1,
      "name": "Soil_Clay_Smooth_Pink"
    },
    {
      "x": 4,
      "y": 21,
      "z": 0,
      "name": "Soil_Clay_Smooth_Pink"
    },
    {
      "x": 4,
      "y": 22,
      "z": 0,
      "name": "Soil_Clay_Smooth_Pink"
    }
  ],
  "fluids": [
    {
      "x": -3,
      "y": 21,
      "z": -2,
      "name": "Empty",
      "level": 0
    },
    {
      "x": -3,
      "y": 22,
      "z": -2,
      "name": "Empty",
      "level": 0
    },
    {
      "x": -3,
      "y": 21,
      "z": -1,
      "name": "Empty",
      "level": 0
    },
    {
      "x": -3,
      "y": 22,
      "z": -1,
      "name": "Empty",
      "level": 0
    },
    {
      "x": -3,
      "y": 23,
      "z": -1,
      "name": "Empty",
      "level": 0
    },
    {
      "x": -3,
      "y": 10,
      "z": 0,
      "name": "Empty",
      "level": 0
    },
    {
      "x": -3,
      "y": 11,
      "z": 0,
      "name": "Empty",
      "level": 0
    },
    {
      "x": -3,
      "y": 12,
      "z": 0,
      "name": "Empty",
      "level": 0
    },
    {
      "x": -3,
      "y": 13,
      "z": 0,
      "name": "Empty",
      "level": 0
    },
    {
      "x": -3,
      "y": 20,
      "z": 0,
      "name": "Empty",
      "level": 0
    },
    {
      "x": -3,
      "y": 21,
      "z": 0,
      "name": "Empty",
      "level": 0
    },
    {
      "x": -3,
      "y": 22,
      "z": 0,
      "name": "Empty",
      "level": 0
    },
    {
      "x": -3,
      "y": 23,
      "z": 0,
      "name": "Empty",
      "level": 0
    },
    {
      "x": -3,
      "y": 21,
      "z": 1,
      "name": "Empty",
      "level": 0
    },
    {
      "x": -3,
      "y": 22,
      "z": 1,
      "name": "Empty",
      "level": 0
    },
    {
      "x": -3,
      "y": 23,
      "z": 1,
      "name": "Empty",
      "level": 0
    },
    {
      "x": -3,
      "y": 22,
      "z": 2,
      "name": "Empty",
      "level": 0
    },
    {
      "x": -2,
      "y": 21,
      "z": -3,
      "name": "Empty",
      "level": 0
    },
    {
      "x": -2,
      "y": 22,
      "z": -3,
      "name": "Empty",
      "level": 0
    },
    {
      "x": -2,
      "y": 14,
      "z": -2,
      "name": "Empty",
      "level": 0
    },
    {
      "x": -2,
      "y": 15,
      "z": -2,
      "name": "Empty",
      "level": 0
    },
    {
      "x": -2,
      "y": 16,
      "z": -2,
      "name": "Empty",
      "level": 0
    },
    {
      "x": -2,
      "y": 17,
      "z": -2,
      "name": "Empty",
      "level": 0
    },
    {
      "x": -2,
      "y": 18,
      "z": -2,
      "name": "Empty",
      "level": 0
    },
    {
      "x": -2,
      "y": 19,
      "z": -2,
      "name": "Empty",
      "level": 0
    },
    {
      "x": -2,
      "y": 20,
      "z": -2,
      "name": "Empty",
      "level": 0
    },
    {
      "x": -2,
      "y": 21,
      "z": -2,
      "name": "Empty",
      "level": 0
    },
    {
      "x": -2,
      "y": 22,
      "z": -2,
      "name": "Empty",
      "level": 0
    },
    {
      "x": -2,
      "y": 23,
      "z": -2,
      "name": "Empty",
      "level": 0
    },
    {
      "x": -2,
      "y": 13,
      "z": -1,
      "name": "Empty",
      "level": 0
    },
    {
      "x": -2,
      "y": 14,
      "z": -1,
      "name": "Empty",
      "level": 0
    },
    {
      "x": -2,
      "y": 19,
      "z": -1,
      "name": "Empty",
      "level": 0
    },
    {
      "x": -2,
      "y": 20,
      "z": -1,
      "name": "Empty",
      "level": 0
    },
    {
      "x": -2,
      "y": 21,
      "z": -1,
      "name": "Empty",
      "level": 0
    },
    {
      "x": -2,
      "y": 22,
      "z": -1,
      "name": "Empty",
      "level": 0
    },
    {
      "x": -2,
      "y": 23,
      "z": -1,
      "name": "Empty",
      "level": 0
    },
    {
      "x": -2,
      "y": 24,
      "z": -1,
      "name": "Empty",
      "level": 0
    },
    {
      "x": -2,
      "y": 13,
      "z": 0,
      "name": "Empty",
      "level": 0
    },
    {
      "x": -2,
      "y": 18,
      "z": 0,
      "name": "Empty",
      "level": 0
    },
    {
      "x": -2,
      "y": 19,
      "z": 0,
      "name": "Empty",
      "level": 0
    },
    {
      "x": -2,
      "y": 20,
      "z": 0,
      "name": "Empty",
      "level": 0
    },
    {
      "x": -2,
      "y": 21,
      "z": 0,
      "name": "Empty",
      "level": 0
    },
    {
      "x": -2,
      "y": 22,
      "z": 0,
      "name": "Empty",
      "level": 0
    },
    {
      "x": -2,
      "y": 23,
      "z": 0,
      "name": "Empty",
      "level": 0
    },
    {
      "x": -2,
      "y": 24,
      "z": 0,
      "name": "Empty",
      "level": 0
    },
    {
      "x": -2,
      "y": 13,
      "z": 1,
      "name": "Empty",
      "level": 0
    },
    {
      "x": -2,
      "y": 14,
      "z": 1,
      "name": "Empty",
      "level": 0
    },
    {
      "x": -2,
      "y": 19,
      "z": 1,
      "name": "Empty",
      "level": 0
    },
    {
      "x": -2,
      "y": 20,
      "z": 1,
      "name": "Empty",
      "level": 0
    },
    {
      "x": -2,
      "y": 21,
      "z": 1,
      "name": "Empty",
      "level": 0
    },
    {
      "x": -2,
      "y": 22,
      "z": 1,
      "name": "Empty",
      "level": 0
    },
    {
      "x": -2,
      "y": 23,
      "z": 1,
      "name": "Empty",
      "level": 0
    },
    {
      "x": -2,
      "y": 24,
      "z": 1,
      "name": "Empty",
      "level": 0
    },
    {
      "x": -2,
      "y": 14,
      "z": 2,
      "name": "Empty",
      "level": 0
    },
    {
      "x": -2,
      "y": 15,
      "z": 2,
      "name": "Empty",
      "level": 0
    },
    {
      "x": -2,
      "y": 16,
      "z": 2,
      "name": "Empty",
      "level": 0
    },
    {
      "x": -2,
      "y": 17,
      "z": 2,
      "name": "Empty",
      "level": 0
    },
    {
      "x": -2,
      "y": 18,
      "z": 2,
      "name": "Empty",
      "level": 0
    },
    {
      "x": -2,
      "y": 19,
      "z": 2,
      "name": "Empty",
      "level": 0
    },
    {
      "x": -2,
      "y": 20,
      "z": 2,
      "name": "Empty",
      "level": 0
    },
    {
      "x": -2,
      "y": 21,
      "z": 2,
      "name": "Empty",
      "level": 0
    },
    {
      "x": -2,
      "y": 22,
      "z": 2,
      "name": "Empty",
      "level": 0
    },
    {
      "x": -2,
      "y": 23,
      "z": 2,
      "name": "Empty",
      "level": 0
    },
    {
      "x": -1,
      "y": 21,
      "z": -3,
      "name": "Empty",
      "level": 0
    },
    {
      "x": -1,
      "y": 22,
      "z": -3,
      "name": "Empty",
      "level": 0
    },
    {
      "x": -1,
      "y": 23,
      "z": -3,
      "name": "Empty",
      "level": 0
    },
    {
      "x": -1,
      "y": 13,
      "z": -2,
      "name": "Empty",
      "level": 0
    },
    {
      "x": -1,
      "y": 14,
      "z": -2,
      "name": "Empty",
      "level": 0
    },
    {
      "x": -1,
      "y": 19,
      "z": -2,
      "name": "Empty",
      "level": 0
    },
    {
      "x": -1,
      "y": 20,
      "z": -2,
      "name": "Empty",
      "level": 0
    },
    {
      "x": -1,
      "y": 21,
      "z": -2,
      "name": "Empty",
      "level": 0
    },
    {
      "x": -1,
      "y": 22,
      "z": -2,
      "name": "Empty",
      "level": 0
    },
    {
      "x": -1,
      "y": 23,
      "z": -2,
      "name": "Empty",
      "level": 0
    },
    {
      "x": -1,
      "y": 24,
      "z": -2,
      "name": "Empty",
      "level": 0
    },
    {
      "x": -1,
      "y": 13,
      "z": -1,
      "name": "Empty",
      "level": 0
    },
    {
      "x": -1,
      "y": 18,
      "z": -1,
      "name": "Empty",
      "level": 0
    },
    {
      "x": -1,
      "y": 19,
      "z": -1,
      "name": "Empty",
      "level": 0
    },
    {
      "x": -1,
      "y": 24,
      "z": -1,
      "name": "Empty",
      "level": 0
    },
    {
      "x": -1,
      "y": 13,
      "z": 0,
      "name": "Empty",
      "level": 0
    },
    {
      "x": -1,
      "y": 17,
      "z": 0,
      "name": "Empty",
      "level": 0
    },
    {
      "x": -1,
      "y": 24,
      "z": 0,
      "name": "Empty",
      "level": 0
    },
    {
      "x": -1,
      "y": 13,
      "z": 1,
      "name": "Empty",
      "level": 0
    },
    {
      "x": -1,
      "y": 18,
      "z": 1,
      "name": "Empty",
      "level": 0
    },
    {
      "x": -1,
      "y": 24,
      "z": 1,
      "name": "Empty",
      "level": 0
    },
    {
      "x": -1,
      "y": 13,
      "z": 2,
      "name": "Empty",
      "level": 0
    },
    {
      "x": -1,
      "y": 14,
      "z": 2,
      "name": "Empty",
      "level": 0
    },
    {
      "x": -1,
      "y": 19,
      "z": 2,
      "name": "Empty",
      "level": 0
    },
    {
      "x": -1,
      "y": 20,
      "z": 2,
      "name": "Empty",
      "level": 0
    },
    {
      "x": -1,
      "y": 21,
      "z": 2,
      "name": "Empty",
      "level": 0
    },
    {
      "x": -1,
      "y": 22,
      "z": 2,
      "name": "Empty",
      "level": 0
    },
    {
      "x": -1,
      "y": 23,
      "z": 2,
      "name": "Empty",
      "level": 0
    },
    {
      "x": -1,
      "y": 24,
      "z": 2,
      "name": "Empty",
      "level": 0
    },
    {
      "x": -1,
      "y": 21,
      "z": 3,
      "name": "Empty",
      "level": 0
    },
    {
      "x": -1,
      "y": 22,
      "z": 3,
      "name": "Empty",
      "level": 0
    },
    {
      "x": 0,
      "y": 14,
      "z": -3,
      "name": "Empty",
      "level": 0
    },
    {
      "x": 0,
      "y": 20,
      "z": -3,
      "name": "Empty",
      "level": 0
    },
    {
      "x": 0,
      "y": 21,
      "z": -3,
      "name": "Empty",
      "level": 0
    },
    {
      "x": 0,
      "y": 22,
      "z": -3,
      "name": "Empty",
      "level": 0
    },
    {
      "x": 0,
      "y": 23,
      "z": -3,
      "name": "Empty",
      "level": 0
    },
    {
      "x": 0,
      "y": 13,
      "z": -2,
      "name": "Empty",
      "level": 0
    },
    {
      "x": 0,
      "y": 14,
      "z": -2,
      "name": "Empty",
      "level": 0
    },
    {
      "x": 0,
      "y": 18,
      "z": -2,
      "name": "Empty",
      "level": 0
    },
    {
      "x": 0,
      "y": 19,
      "z": -2,
      "name": "Empty",
      "level": 0
    },
    {
      "x": 0,
      "y": 20,
      "z": -2,
      "name": "Empty",
      "level": 0
    },
    {
      "x": 0,
      "y": 21,
      "z": -2,
      "name": "Empty",
      "level": 0
    },
    {
      "x": 0,
      "y": 22,
      "z": -2,
      "name": "Empty",
      "level": 0
    },
    {
      "x": 0,
      "y": 23,
      "z": -2,
      "name": "Empty",
      "level": 0
    },
    {
      "x": 0,
      "y": 24,
      "z": -2,
      "name": "Empty",
      "level": 0
    },
    {
      "x": 0,
      "y": 13,
      "z": -1,
      "name": "Empty",
      "level": 0
    },
    {
      "x": 0,
      "y": 17,
      "z": -1,
      "name": "Empty",
      "level": 0
    },
    {
      "x": 0,
      "y": 24,
      "z": -1,
      "name": "Empty",
      "level": 0
    },
    {
      "x": 0,
      "y": 12,
      "z": 0,
      "name": "Empty",
      "level": 0
    },
    {
      "x": 0,
      "y": 13,
      "z": 0,
      "name": "Empty",
      "level": 0
    },
    {
      "x": 0,
      "y": 14,
      "z": 0,
      "name": "Empty",
      "level": 0
    },
    {
      "x": 0,
      "y": 15,
      "z": 0,
      "name": "Empty",
      "level": 0
    },
    {
      "x": 0,
      "y": 16,
      "z": 0,
      "name": "Empty",
      "level": 0
    },
    {
      "x": 0,
      "y": 17,
      "z": 0,
      "name": "Empty",
      "level": 0
    },
    {
      "x": 0,
      "y": 18,
      "z": 0,
      "name": "Empty",
      "level": 0
    },
    {
      "x": 0,
      "y": 19,
      "z": 0,
      "name": "Empty",
      "level": 0
    },
    {
      "x": 0,
      "y": 20,
      "z": 0,
      "name": "Empty",
      "level": 0
    },
    {
      "x": 0,
      "y": 21,
      "z": 0,
      "name": "Empty",
      "level": 0
    },
    {
      "x": 0,
      "y": 22,
      "z": 0,
      "name": "Empty",
      "level": 0
    },
    {
      "x": 0,
      "y": 23,
      "z": 0,
      "name": "Empty",
      "level": 0
    },
    {
      "x": 0,
      "y": 24,
      "z": 0,
      "name": "Empty",
      "level": 0
    },
    {
      "x": 0,
      "y": 25,
      "z": 0,
      "name": "Empty",
      "level": 0
    },
    {
      "x": 0,
      "y": 13,
      "z": 1,
      "name": "Empty",
      "level": 0
    },
    {
      "x": 0,
      "y": 17,
      "z": 1,
      "name": "Empty",
      "level": 0
    },
    {
      "x": 0,
      "y": 18,
      "z": 1,
      "name": "Empty",
      "level": 0
    },
    {
      "x": 0,
      "y": 24,
      "z": 1,
      "name": "Empty",
      "level": 0
    },
    {
      "x": 0,
      "y": 25,
      "z": 1,
      "name": "Empty",
      "level": 0
    },
    {
      "x": 0,
      "y": 13,
      "z": 2,
      "name": "Empty",
      "level": 0
    },
    {
      "x": 0,
      "y": 14,
      "z": 2,
      "name": "Empty",
      "level": 0
    },
    {
      "x": 0,
      "y": 18,
      "z": 2,
      "name": "Empty",
      "level": 0
    },
    {
      "x": 0,
      "y": 19,
      "z": 2,
      "name": "Empty",
      "level": 0
    },
    {
      "x": 0,
      "y": 20,
      "z": 2,
      "name": "Empty",
      "level": 0
    },
    {
      "x": 0,
      "y": 21,
      "z": 2,
      "name": "Empty",
      "level": 0
    },
    {
      "x": 0,
      "y": 22,
      "z": 2,
      "name": "Empty",
      "level": 0
    },
    {
      "x": 0,
      "y": 23,
      "z": 2,
      "name": "Empty",
      "level": 0
    },
    {
      "x": 0,
      "y": 24,
      "z": 2,
      "name": "Empty",
      "level": 0
    },
    {
      "x": 0,
      "y": 14,
      "z": 3,
      "name": "Empty",
      "level": 0
    },
    {
      "x": 0,
      "y": 20,
      "z": 3,
      "name": "Empty",
      "level": 0
    },
    {
      "x": 0,
      "y": 21,
      "z": 3,
      "name": "Empty",
      "level": 0
    },
    {
      "x": 0,
      "y": 22,
      "z": 3,
      "name": "Empty",
      "level": 0
    },
    {
      "x": 0,
      "y": 23,
      "z": 3,
      "name": "Empty",
      "level": 0
    },
    {
      "x": 1,
      "y": 21,
      "z": -3,
      "name": "Empty",
      "level": 0
    },
    {
      "x": 1,
      "y": 22,
      "z": -3,
      "name": "Empty",
      "level": 0
    },
    {
      "x": 1,
      "y": 23,
      "z": -3,
      "name": "Empty",
      "level": 0
    },
    {
      "x": 1,
      "y": 13,
      "z": -2,
      "name": "Empty",
      "level": 0
    },
    {
      "x": 1,
      "y": 14,
      "z": -2,
      "name": "Empty",
      "level": 0
    },
    {
      "x": 1,
      "y": 19,
      "z": -2,
      "name": "Empty",
      "level": 0
    },
    {
      "x": 1,
      "y": 20,
      "z": -2,
      "name": "Empty",
      "level": 0
    },
    {
      "x": 1,
      "y": 21,
      "z": -2,
      "name": "Empty",
      "level": 0
    },
    {
      "x": 1,
      "y": 22,
      "z": -2,
      "name": "Empty",
      "level": 0
    },
    {
      "x": 1,
      "y": 23,
      "z": -2,
      "name": "Empty",
      "level": 0
    },
    {
      "x": 1,
      "y": 24,
      "z": -2,
      "name": "Empty",
      "level": 0
    },
    {
      "x": 1,
      "y": 13,
      "z": -1,
      "name": "Empty",
      "level": 0
    },
    {
      "x": 1,
      "y": 18,
      "z": -1,
      "name": "Empty",
      "level": 0
    },
    {
      "x": 1,
      "y": 19,
      "z": -1,
      "name": "Empty",
      "level": 0
    },
    {
      "x": 1,
      "y": 24,
      "z": -1,
      "name": "Empty",
      "level": 0
    },
    {
      "x": 1,
      "y": 13,
      "z": 0,
      "name": "Empty",
      "level": 0
    },
    {
      "x": 1,
      "y": 17,
      "z": 0,
      "name": "Empty",
      "level": 0
    },
    {
      "x": 1,
      "y": 18,
      "z": 0,
      "name": "Empty",
      "level": 0
    },
    {
      "x": 1,
      "y": 24,
      "z": 0,
      "name": "Empty",
      "level": 0
    },
    {
      "x": 1,
      "y": 25,
      "z": 0,
      "name": "Empty",
      "level": 0
    },
    {
      "x": 1,
      "y": 13,
      "z": 1,
      "name": "Empty",
      "level": 0
    },
    {
      "x": 1,
      "y": 18,
      "z": 1,
      "name": "Empty",
      "level": 0
    },
    {
      "x": 1,
      "y": 24,
      "z": 1,
      "name": "Empty",
      "level": 0
    },
    {
      "x": 1,
      "y": 13,
      "z": 2,
      "name": "Empty",
      "level": 0
    },
    {
      "x": 1,
      "y": 14,
      "z": 2,
      "name": "Empty",
      "level": 0
    },
    {
      "x": 1,
      "y": 19,
      "z": 2,
      "name": "Empty",
      "level": 0
    },
    {
      "x": 1,
      "y": 20,
      "z": 2,
      "name": "Empty",
      "level": 0
    },
    {
      "x": 1,
      "y": 21,
      "z": 2,
      "name": "Empty",
      "level": 0
    },
    {
      "x": 1,
      "y": 22,
      "z": 2,
      "name": "Empty",
      "level": 0
    },
    {
      "x": 1,
      "y": 23,
      "z": 2,
      "name": "Empty",
      "level": 0
    },
    {
      "x": 1,
      "y": 24,
      "z": 2,
      "name": "Empty",
      "level": 0
    },
    {
      "x": 1,
      "y": 20,
      "z": 3,
      "name": "Empty",
      "level": 0
    },
    {
      "x": 1,
      "y": 21,
      "z": 3,
      "name": "Empty",
      "level": 0
    },
    {
      "x": 1,
      "y": 22,
      "z": 3,
      "name": "Empty",
      "level": 0
    },
    {
      "x": 1,
      "y": 23,
      "z": 3,
      "name": "Empty",
      "level": 0
    },
    {
      "x": 2,
      "y": 21,
      "z": -3,
      "name": "Empty",
      "level": 0
    },
    {
      "x": 2,
      "y": 22,
      "z": -3,
      "name": "Empty",
      "level": 0
    },
    {
      "x": 2,
      "y": 14,
      "z": -2,
      "name": "Empty",
      "level": 0
    },
    {
      "x": 2,
      "y": 15,
      "z": -2,
      "name": "Empty",
      "level": 0
    },
    {
      "x": 2,
      "y": 16,
      "z": -2,
      "name": "Empty",
      "level": 0
    },
    {
      "x": 2,
      "y": 17,
      "z": -2,
      "name": "Empty",
      "level": 0
    },
    {
      "x": 2,
      "y": 18,
      "z": -2,
      "name": "Empty",
      "level": 0
    },
    {
      "x": 2,
      "y": 19,
      "z": -2,
      "name": "Empty",
      "level": 0
    },
    {
      "x": 2,
      "y": 20,
      "z": -2,
      "name": "Empty",
      "level": 0
    },
    {
      "x": 2,
      "y": 21,
      "z": -2,
      "name": "Empty",
      "level": 0
    },
    {
      "x": 2,
      "y": 22,
      "z": -2,
      "name": "Empty",
      "level": 0
    },
    {
      "x": 2,
      "y": 23,
      "z": -2,
      "name": "Empty",
      "level": 0
    },
    {
      "x": 2,
      "y": 13,
      "z": -1,
      "name": "Empty",
      "level": 0
    },
    {
      "x": 2,
      "y": 14,
      "z": -1,
      "name": "Empty",
      "level": 0
    },
    {
      "x": 2,
      "y": 20,
      "z": -1,
      "name": "Empty",
      "level": 0
    },
    {
      "x": 2,
      "y": 21,
      "z": -1,
      "name": "Empty",
      "level": 0
    },
    {
      "x": 2,
      "y": 22,
      "z": -1,
      "name": "Empty",
      "level": 0
    },
    {
      "x": 2,
      "y": 23,
      "z": -1,
      "name": "Empty",
      "level": 0
    },
    {
      "x": 2,
      "y": 24,
      "z": -1,
      "name": "Empty",
      "level": 0
    },
    {
      "x": 2,
      "y": 13,
      "z": 0,
      "name": "Empty",
      "level": 0
    },
    {
      "x": 2,
      "y": 14,
      "z": 0,
      "name": "Empty",
      "level": 0
    },
    {
      "x": 2,
      "y": 19,
      "z": 0,
      "name": "Empty",
      "level": 0
    },
    {
      "x": 2,
      "y": 20,
      "z": 0,
      "name": "Empty",
      "level": 0
    },
    {
      "x": 2,
      "y": 21,
      "z": 0,
      "name": "Empty",
      "level": 0
    },
    {
      "x": 2,
      "y": 22,
      "z": 0,
      "name": "Empty",
      "level": 0
    },
    {
      "x": 2,
      "y": 23,
      "z": 0,
      "name": "Empty",
      "level": 0
    },
    {
      "x": 2,
      "y": 24,
      "z": 0,
      "name": "Empty",
      "level": 0
    },
    {
      "x": 2,
      "y": 13,
      "z": 1,
      "name": "Empty",
      "level": 0
    },
    {
      "x": 2,
      "y": 14,
      "z": 1,
      "name": "Empty",
      "level": 0
    },
    {
      "x": 2,
      "y": 19,
      "z": 1,
      "name": "Empty",
      "level": 0
    },
    {
      "x": 2,
      "y": 20,
      "z": 1,
      "name": "Empty",
      "level": 0
    },
    {
      "x": 2,
      "y": 21,
      "z": 1,
      "name": "Empty",
      "level": 0
    },
    {
      "x": 2,
      "y": 22,
      "z": 1,
      "name": "Empty",
      "level": 0
    },
    {
      "x": 2,
      "y": 23,
      "z": 1,
      "name": "Empty",
      "level": 0
    },
    {
      "x": 2,
      "y": 24,
      "z": 1,
      "name": "Empty",
      "level": 0
    },
    {
      "x": 2,
      "y": 14,
      "z": 2,
      "name": "Empty",
      "level": 0
    },
    {
      "x": 2,
      "y": 15,
      "z": 2,
      "name": "Empty",
      "level": 0
    },
    {
      "x": 2,
      "y": 16,
      "z": 2,
      "name": "Empty",
      "level": 0
    },
    {
      "x": 2,
      "y": 17,
      "z": 2,
      "name": "Empty",
      "level": 0
    },
    {
      "x": 2,
      "y": 18,
      "z": 2,
      "name": "Empty",
      "level": 0
    },
    {
      "x": 2,
      "y": 19,
      "z": 2,
      "name": "Empty",
      "level": 0
    },
    {
      "x": 2,
      "y": 20,
      "z": 2,
      "name": "Empty",
      "level": 0
    },
    {
      "x": 2,
      "y": 21,
      "z": 2,
      "name": "Empty",
      "level": 0
    },
    {
      "x": 2,
      "y": 22,
      "z": 2,
      "name": "Empty",
      "level": 0
    },
    {
      "x": 2,
      "y": 23,
      "z": 2,
      "name": "Empty",
      "level": 0
    },
    {
      "x": 2,
      "y": 24,
      "z": 2,
      "name": "Empty",
      "level": 0
    },
    {
      "x": 2,
      "y": 21,
      "z": 3,
      "name": "Empty",
      "level": 0
    },
    {
      "x": 2,
      "y": 22,
      "z": 3,
      "name": "Empty",
      "level": 0
    },
    {
      "x": 3,
      "y": 21,
      "z": -2,
      "name": "Empty",
      "level": 0
    },
    {
      "x": 3,
      "y": 22,
      "z": -2,
      "name": "Empty",
      "level": 0
    },
    {
      "x": 3,
      "y": 23,
      "z": -2,
      "name": "Empty",
      "level": 0
    },
    {
      "x": 3,
      "y": 20,
      "z": -1,
      "name": "Empty",
      "level": 0
    },
    {
      "x": 3,
      "y": 21,
      "z": -1,
      "name": "Empty",
      "level": 0
    },
    {
      "x": 3,
      "y": 22,
      "z": -1,
      "name": "Empty",
      "level": 0
    },
    {
      "x": 3,
      "y": 23,
      "z": -1,
      "name": "Empty",
      "level": 0
    },
    {
      "x": 3,
      "y": 14,
      "z": 0,
      "name": "Empty",
      "level": 0
    },
    {
      "x": 3,
      "y": 20,
      "z": 0,
      "name": "Empty",
      "level": 0
    },
    {
      "x": 3,
      "y": 21,
      "z": 0,
      "name": "Empty",
      "level": 0
    },
    {
      "x": 3,
      "y": 22,
      "z": 0,
      "name": "Empty",
      "level": 0
    },
    {
      "x": 3,
      "y": 23,
      "z": 0,
      "name": "Empty",
      "level": 0
    },
    {
      "x": 3,
      "y": 21,
      "z": 1,
      "name": "Empty",
      "level": 0
    },
    {
      "x": 3,
      "y": 22,
      "z": 1,
      "name": "Empty",
      "level": 0
    },
    {
      "x": 3,
      "y": 23,
      "z": 1,
      "name": "Empty",
      "level": 0
    },
    {
      "x": 3,
      "y": 21,
      "z": 2,
      "name": "Empty",
      "level": 0
    },
    {
      "x": 3,
      "y": 22,
      "z": 2,
      "name": "Empty",
      "level": 0
    },
    {
      "x": 4,
      "y": 21,
      "z": -1,
      "name": "Empty",
      "level": 0
    },
    {
      "x": 4,
      "y": 22,
      "z": -1,
      "name": "Empty",
      "level": 0
    },
    {
      "x": 4,
      "y": 21,
      "z": 0,
      "name": "Empty",
      "level": 0
    },
    {
      "x": 4,
      "y": 22,
      "z": 0,
      "name": "Empty",
      "level": 0
    }
  ]
}