{
  "version": 8,
  "blockIdVersion": 8,
  "anchorX": 11,
  "anchorY": 7,
  "anchorZ": 10,
  "blocks": [
    {
      "x": 6,
      "y": 13,
      "z": 9,
      "name": "Plant_Leaves_Light"
    },
    {
      "x": 6,
      "y": 14,
      "z": 9,
      "name": "Plant_Leaves_Light"
    },
    {
      "x": 6,
      "y": 15,
      "z": 9,
      "name": "Plant_Leaves_Light"
    },
    {
      "x": 6,
      "y": 13,
      "z": 10,
      "name": "Plant_Leaves_Light"
    },
    {
      "x": 6,
      "y": 14,
      "z": 10,
      "name": "Plant_Leaves_Light"
    },
    {
      "x": 6,
      "y": 15,
      "z": 10,
      "name": "Plant_Leaves_Light"
    },
    {
      "x": 6,
      "y": 13,
      "z": 11,
      "name": "Plant_Leaves_Light"
    },
    {
      "x": 6,
      "y": 14,
      "z": 11,
      "name": "Plant_Leaves_Light"
    },
    {
      "x": 7,
      "y": 13,
      "z": 7,
      "name": "Plant_Leaves_Light"
    },
    {
      "x": 7,
      "y": 14,
      "z": 7,
      "name": "Plant_Leaves_Light"
    },
    {
      "x": 7,
      "y": 13,
      "z": 8,
      "name": "Plant_Leaves_Light"
    },
    {
      "x": 7,
      "y": 14,
      "z": 8,
      "name": "Plant_Leaves_Light"
    },
    {
      "x": 7,
      "y": 15,
      "z": 8,
      "name": "Plant_Leaves_Light"
    },
    {
      "x": 7,
      "y": 13,
      "z": 9,
      "name": "Plant_Leaves_Light"
    },
    {
      "x": 7,
      "y": 14,
      "z": 9,
      "name": "Plant_Leaves_Light"
    },
    {
      "x": 7,
      "y": 15,
      "z": 9,
      "name": "Plant_Leaves_Light"
    },
    {
      "x": 7,
      "y": 16,
      "z": 9,
      "name": "Plant_Leaves_Light"
    },
    {
      "x": 7,
      "y": 17,
      "z": 9,
      "name": "Plant_Leaves_Light"
    },
    {
      "x": 7,
      "y": 11,
      "z": 10,
      "name": "Plant_Leaves_Light"
    },
    {
      "x": 7,
      "y": 14,
      "z": 10,
      "name": "Wood_Beech_Branch_Long",
      "rotation": 5
    },
    {
      "x": 7,
      "y": 15,
      "z": 10,
      "name": "Plant_Leaves_Light"
    },
    {
      "x": 7,
      "y": 16,
      "z": 10,
      "name": "Plant_Leaves_Light"
    },
    {
      "x": 7,
      "y": 19,
      "z": 10,
      "name": "Plant_Leaves_Light"
    },
    {
      "x": 7,
      "y": 21,
      "z": 10,
      "name": "Plant_Leaves_Light"
    },
    {
      "x": 7,
      "y": 13,
      "z": 11,
      "name": "Plant_Leaves_Light"
    },
    {
      "x": 7,
      "y": 14,
      "z": 11,
      "name": "Plant_Leaves_Light"
    },
    {
      "x": 7,
      "y": 15,
      "z": 11,
      "name": "Plant_Leaves_Light"
    },
    {
      "x": 7,
      "y": 16,
      "z": 11,
      "name": "Plant_Leaves_Light"
    },
    {
      "x": 7,
      "y": 14,
      "z": 12,
      "name": "Plant_Leaves_Light"
    },
    {
      "x": 7,
      "y": 15,
      "z": 12,
      "name": "Plant_Leaves_Light"
    },
    {
      "x": 7,
      "y": 14,
      "z": 14,
      "name": "Plant_Leaves_Light"
    },
    {
      "x": 8,
      "y": 14,
      "z": 6,
      "name": "Plant_Leaves_Light"
    },
    {
      "x": 8,
      "y": 13,
      "z": 7,
      "name": "Plant_Leaves_Light"
    },
    {
      "x": 8,
      "y": 14,
      "z": 7,
      "name": "Plant_Leaves_Light"
    },
    {
      "x": 8,
      "y": 15,
      "z": 7,
      "name": "Plant_Leaves_Light"
    },
    {
      "x": 8,
      "y": 13,
      "z": 8,
      "name": "Plant_Leaves_Light"
    },
    {
      "x": 8,
      "y": 14,
      "z": 8,
      "name": "Plant_Leaves_Light"
    },
    {
      "x": 8,
      "y": 15,
      "z": 8,
      "name": "Plant_Leaves_Light"
    },
    {
      "x": 8,
      "y": 11,
      "z": 9,
      "name": "Plant_Leaves_Light"
    },
    {
      "x": 8,
      "y": 17,
      "z": 9,
      "name": "Plant_Leaves_Light"
    },
    {
      "x": 8,
      "y": 18,
      "z": 9,
      "name": "Plant_Leaves_Light"
    },
    {
      "x": 8,
      "y": 19,
      "z": 9,
      "name": "Plant_Leaves_Light"
    },
    {
      "x": 8,
      "y": 21,
      "z": 9,
      "name": "Plant_Leaves_Light"
    },
    {
      "x": 8,
      "y": 11,
      "z": 10,
      "name": "Plant_Leaves_Light"
    },
    {
      "x": 8,
      "y": 12,
      "z": 10,
      "name": "Plant_Leaves_Light"
    },
    {
      "x": 8,
      "y": 14,
      "z": 10,
      "name": "Wood_Beech_Branch_Long",
      "rotation": 5
    },
    {
      "x": 8,
      "y": 17,
      "z": 10,
      "name": "Plant_Leaves_Light"
    },
    {
      "x": 8,
      "y": 18,
      "z": 10,
      "name": "Plant_Leaves_Light"
    },
    {
      "x": 8,
      "y": 19,
      "z": 10,
      "name": "Plant_Leaves_Light"
    },
    {
      "x": 8,
      "y": 20,
      "z": 10,
      "name": "Plant_Leaves_Light"
    },
    {
      "x": 8,
      "y": 21,
      "z": 10,
      "name": "Plant_Leaves_Light"
    },
    {
      "x": 8,
      "y": 22,
      "z": 10,
      "name": "Plant_Leaves_Light"
    },
    {
      "x": 8,
      "y": 11,
      "z": 11,
      "name": "Plant_Leaves_Light"
    },
    {
      "x": 8,
      "y": 17,
      "z": 11,
      "name": "Plant_Leaves_Light"
    },
    {
      "x": 8,
      "y": 18,
      "z": 11,
      "name": "Plant_Leaves_Light"
    },
    {
      "x": 8,
      "y": 19,
      "z": 11,
      "name": "Plant_Leaves_Light"
    },
    {
      "x": 8,
      "y": 21,
      "z": 11,
      "name": "Plant_Leaves_Light"
    },
    {
      "x": 8,
      "y": 17,
      "z": 12,
      "name": "Plant_Leaves_Light"
    },
    {
      "x": 8,
      "y": 18,
      "z": 12,
      "name": "Plant_Leaves_Light"
    },
    {
      "x": 8,
      "y": 19,
      "z": 12,
      "name": "Plant_Leaves_Light"
    },
    {
      "x": 8,
      "y": 20,
      "z": 12,
      "name": "Plant_Leaves_Light"
    },
    {
      "x": 8,
      "y": 17,
      "z": 13,
      "name": "Plant_Leaves_Light"
    },
    {
      "x": 8,
      "y": 19,
      "z": 13,
      "name": "Plant_Leaves_Light"
    },
    {
      "x": 8,
      "y": 14,
      "z": 14,
      "name": "Plant_Leaves_Light"
    },
    {
      "x": 8,
      "y": 15,
      "z": 14,
      "name": "Plant_Leaves_Light"
    },
    {
      "x": 8,
      "y": 17,
      "z": 14,
      "name": "Plant_Leaves_Light"
    },
    {
      "x": 8,
      "y": 14,
      "z": 15,
      "name": "Plant_Leaves_Light"
    },
    {
      "x": 8,
      "y": 15,
      "z": 15,
      "name": "Plant_Leaves_Light"
    },
    {
      "x": 9,
      "y": 13,
      "z": 6,
      "name": "Plant_Leaves_Light"
    },
    {
      "x": 9,
      "y": 14,
      "z": 6,
      "name": "Plant_Leaves_Light"
    },
    {
      "x": 9,
      "y": 20,
      "z": 6,
      "name": "Plant_Leaves_Light"
    },
    {
      "x": 9,
      "y": 21,
      "z": 6,
      "name": "Plant_Leaves_Light"
    },
    {
      "x": 9,
      "y": 16,
      "z": 7,
      "name": "Plant_Leaves_Light"
    },
    {
      "x": 9,
      "y": 14,
      "z": 8,
      "name": "Plant_Leaves_Light"
    },
    {
      "x": 9,
      "y": 15,
      "z": 8,
      "name": "Plant_Leaves_Light"
    },
    {
      "x": 9,
      "y": 16,
      "z": 8,
      "name": "Plant_Leaves_Light"
    },
    {
      "x": 9,
      "y": 17,
      "z": 8,
      "name": "Plant_Leaves_Light"
    },
    {
      "x": 9,
      "y": 12,
      "z": 9,
      "name": "Plant_Leaves_Light"
    },
    {
      "x": 9,
      "y": 14,
      "z": 9,
      "name": "Wood_Beech_Branch_Long",
      "rotation": 4
    },
    {
      "x": 9,
      "y": 17,
      "z": 9,
      "name": "Plant_Leaves_Light"
    },
    {
      "x": 9,
      "y": 18,
      "z": 9,
      "name": "Plant_Leaves_Light"
    },
    {
      "x": 9,
      "y": 20,
      "z": 9,
      "name": "Plant_Leaves_Light"
    },
    {
      "x": 9,
      "y": 22,
      "z": 9,
      "name": "Plant_Leaves_Light"
    },
    {
      "x": 9,
      "y": 26,
      "z": 9,
      "name": "Plant_Leaves_Light"
    },
    {
      "x": 9,
      "y": 27,
      "z": 9,
      "name": "Plant_Leaves_Light"
    },
    {
      "x": 9,
      "y": 11,
      "z": 10,
      "name": "Wood_Beech_Branch_Long",
      "rotation": 5
    },
    {
      "x": 9,
      "y": 12,
      "z": 10,
      "name": "Plant_Leaves_Light"
    },
    {
      "x": 9,
      "y": 13,
      "z": 10,
      "name": "Wood_Beech_Trunk_Full"
    },
    {
      "x": 9,
      "y": 14,
      "z": 10,
      "name": "Wood_Beech_Trunk_Full"
    },
    {
      "x": 9,
      "y": 15,
      "z": 10,
      "name": "Wood_Beech_Branch_Long"
    },
    {
      "x": 9,
      "y": 16,
      "z": 10,
      "name": "Wood_Beech_Branch_Long"
    },
    {
      "x": 9,
      "y": 17,
      "z": 10,
      "name": "Plant_Leaves_Light"
    },
    {
      "x": 9,
      "y": 18,
      "z": 10,
      "name": "Plant_Leaves_Light"
    },
    {
      "x": 9,
      "y": 19,
      "z": 10,
      "name": "Wood_Beech_Branch_Long",
      "rotation": 5
    },
    {
      "x": 9,
      "y": 20,
      "z": 10,
      "name": "Plant_Leaves_Light"
    },
    {
      "x": 9,
      "y": 21,
      "z": 10,
      "name": "Wood_Beech_Branch_Long",
      "rotation": 5
    },
    {
      "x": 9,
      "y": 22,
      "z": 10,
      "name": "Plant_Leaves_Light"
    },
    {
      "x": 9,
      "y": 27,
      "z": 10,
      "name": "Plant_Leaves_Light"
    },
    {
      "x": 9,
      "y": 11,
      "z": 11,
      "name": "Plant_Leaves_Light"
    },
    {
      "x": 9,
      "y": 17,
      "z": 11,
      "name": "Plant_Leaves_Light"
    },
    {
      "x": 9,
      "y": 19,
      "z": 11,
      "name": "Plant_Leaves_Light"
    },
    {
      "x": 9,
      "y": 21,
      "z": 11,
      "name": "Plant_Leaves_Light"
    },
    {
      "x": 9,
      "y": 22,
      "z": 11,
      "name": "Plant_Leaves_Light"
    },
    {
      "x": 9,
      "y": 27,
      "z": 11,
      "name": "Plant_Leaves_Light"
    },
    {
      "x": 9,
      "y": 17,
      "z": 12,
      "name": "Plant_Leaves_Light"
    },
    {
      "x": 9,
      "y": 18,
      "z": 12,
      "name": "Plant_Leaves_Light"
    },
    {
      "x": 9,
      "y": 19,
      "z": 12,
      "name": "Plant_Leaves_Light"
    },
    {
      "x": 9,
      "y": 20,
      "z": 12,
      "name": "Plant_Leaves_Light"
    },
    {
      "x": 9,
      "y": 22,
      "z": 12,
      "name": "Plant_Leaves_Light"
    },
    {
      "x": 9,
      "y": 17,
      "z": 13,
      "name": "Plant_Leaves_Light"
    },
    {
      "x": 9,
      "y": 18,
      "z": 13,
      "name": "Plant_Leaves_Light"
    },
    {
      "x": 9,
      "y": 19,
      "z": 13,
      "name": "Plant_Leaves_Light"
    },
    {
      "x": 9,
      "y": 21,
      "z": 13,
      "name": "Plant_Leaves_Light"
    },
    {
      "x": 9,
      "y": 22,
      "z": 13,
      "name": "Plant_Leaves_Light"
    },
    {
      "x": 9,
      "y": 14,
      "z": 14,
      "name": "Plant_Leaves_Light"
    },
    {
      "x": 9,
      "y": 17,
      "z": 14,
      "name": "Plant_Leaves_Light"
    },
    {
      "x": 9,
      "y": 18,
      "z": 14,
      "name": "Plant_Leaves_Light"
    },
    {
      "x": 9,
      "y": 14,
      "z": 15,
      "name": "Plant_Leaves_Light"
    },
    {
      "x": 9,
      "y": 15,
      "z": 15,
      "name": "Plant_Leaves_Light"
    },
    {
      "x": 9,
      "y": 14,
      "z": 16,
      "name": "Plant_Leaves_Light"
    },
    {
      "x": 10,
      "y": 14,
      "z": 5,
      "name": "Plant_Leaves_Light"
    },
    {
      "x": 10,
      "y": 15,
      "z": 5,
      "name": "Plant_Leaves_Light"
    },
    {
      "x": 10,
      "y": 19,
      "z": 5,
      "name": "Plant_Leaves_Light"
    },
    {
      "x": 10,
      "y": 20,
      "z": 5,
      "name": "Plant_Leaves_Light"
    },
    {
      "x": 10,
      "y": 12,
      "z": 6,
      "name": "Plant_Leaves_Light"
    },
    {
      "x": 10,
      "y": 13,
      "z": 6,
      "name": "Plant_Leaves_Light"
    },
    {
      "x": 10,
      "y": 14,
      "z": 6,
      "name": "Plant_Leaves_Light"
    },
    {
      "x": 10,
      "y": 15,
      "z": 6,
      "name": "Plant_Leaves_Light"
    },
    {
      "x": 10,
      "y": 16,
      "z": 6,
      "name": "Plant_Leaves_Light"
    },
    {
      "x": 10,
      "y": 19,
      "z": 6,
      "name": "Plant_Leaves_Light"
    },
    {
      "x": 10,
      "y": 20,
      "z": 6,
      "name": "Plant_Leaves_Light"
    },
    {
      "x": 10,
      "y": 21,
      "z": 6,
      "name": "Plant_Leaves_Light"
    },
    {
      "x": 10,
      "y": 22,
      "z": 6,
      "name": "Plant_Leaves_Light"
    },
    {
      "x": 10,
      "y": 16,
      "z": 7,
      "name": "Plant_Leaves_Light"
    },
    {
      "x": 10,
      "y": 17,
      "z": 7,
      "name": "Plant_Leaves_Light"
    },
    {
      "x": 10,
      "y": 23,
      "z": 7,
      "name": "Plant_Leaves_Light"
    },
    {
      "x": 10,
      "y": 14,
      "z": 8,
      "name": "Wood_Beech_Branch_Long",
      "rotation": 5
    },
    {
      "x": 10,
      "y": 17,
      "z": 8,
      "name": "Plant_Leaves_Light"
    },
    {
      "x": 10,
      "y": 18,
      "z": 8,
      "name": "Plant_Leaves_Light"
    },
    {
      "x": 10,
      "y": 23,
      "z": 8,
      "name": "Plant_Leaves_Light"
    },
    {
      "x": 10,
      "y": 17,
      "z": 9,
      "name": "Plant_Leaves_Light"
    },
    {
      "x": 10,
      "y": 26,
      "z": 9,
      "name": "Plant_Leaves_Light"
    },
    {
      "x": 10,
      "y": 27,
      "z": 9,
      "name": "Plant_Leaves_Light"
    },
    {
      "x": 10,
      "y": 11,
      "z": 10,
      "name": "Wood_Beech_Branch_Long",
      "rotation": 5
    },
    {
      "x": 10,
      "y": 13,
      "z": 10,
      "name": "Wood_Beech_Trunk_Full"
    },
    {
      "x": 10,
      "y": 19,
      "z": 10,
      "name": "Wood_Beech_Branch_Long",
      "rotation": 5
    },
    {
      "x": 10,
      "y": 21,
      "z": 10,
      "name": "Wood_Beech_Branch_Long",
      "rotation": 5
    },
    {
      "x": 10,
      "y": 24,
      "z": 10,
      "name": "Wood_Beech_Branch_Corner",
      "rotation": 3
    },
    {
      "x": 10,
      "y": 25,
      "z": 10,
      "name": "Wood_Beech_Branch_Long"
    },
    {
      "x": 10,
      "y": 26,
      "z": 10,
      "name": "Wood_Beech_Branch_Long"
    },
    {
      "x": 10,
      "y": 27,
      "z": 10,
      "name": "Wood_Beech_Branch_Long"
    },
    {
      "x": 10,
      "y": 28,
      "z": 10,
      "name": "Plant_Leaves_Light"
    },
    {
      "x": 10,
      "y": 22,
      "z": 11,
      "name": "Plant_Leaves_Light"
    },
    {
      "x": 10,
      "y": 27,
      "z": 11,
      "name": "Plant_Leaves_Light"
    },
    {
      "x": 10,
      "y": 28,
      "z": 11,
      "name": "Plant_Leaves_Light"
    },
    {
      "x": 10,
      "y": 17,
      "z": 12,
      "name": "Wood_Beech_Branch_Long",
      "rotation": 5
    },
    {
      "x": 10,
      "y": 22,
      "z": 12,
      "name": "Plant_Leaves_Light"
    },
    {
      "x": 10,
      "y": 23,
      "z": 12,
      "name": "Plant_Leaves_Light"
    },
    {
      "x": 10,
      "y": 26,
      "z": 12,
      "name": "Plant_Leaves_Light"
    },
    {
      "x": 10,
      "y": 27,
      "z": 12,
      "name": "Plant_Leaves_Light"
    },
    {
      "x": 10,
      "y": 21,
      "z": 13,
      "name": "Plant_Leaves_Light"
    },
    {
      "x": 10,
      "y": 22,
      "z": 13,
      "name": "Plant_Leaves_Light"
    },
    {
      "x": 10,
      "y": 26,
      "z": 13,
      "name": "Plant_Leaves_Light"
    },
    {
      "x": 10,
      "y": 11,
      "z": 14,
      "name": "Plant_Leaves_Light"
    },
    {
      "x": 10,
      "y": 12,
      "z": 14,
      "name": "Plant_Leaves_Light"
    },
    {
      "x": 10,
      "y": 14,
      "z": 14,
      "name": "Plant_Leaves_Light"
    },
    {
      "x": 10,
      "y": 18,
      "z": 14,
      "name": "Plant_Leaves_Light"
    },
    {
      "x": 10,
      "y": 19,
      "z": 14,
      "name": "Plant_Leaves_Light"
    },
    {
      "x": 10,
      "y": 21,
      "z": 14,
      "name": "Plant_Leaves_Light"
    },
    {
      "x": 10,
      "y": 11,
      "z": 15,
      "name": "Plant_Leaves_Light"
    },
    {
      "x": 10,
      "y": 12,
      "z": 15,
      "name": "Plant_Leaves_Light"
    },
    {
      "x": 10,
      "y": 14,
      "z": 15,
      "name": "Plant_Leaves_Light"
    },
    {
      "x": 10,
      "y": 15,
      "z": 15,
      "name": "Plant_Leaves_Light"
    },
    {
      "x": 10,
      "y": 16,
      "z": 15,
      "name": "Plant_Leaves_Light"
    },
    {
      "x": 10,
      "y": 17,
      "z": 15,
      "name": "Plant_Leaves_Light"
    },
    {
      "x": 10,
      "y": 18,
      "z": 15,
      "name": "Plant_Leaves_Light"
    },
    {
      "x": 10,
      "y": 19,
      "z": 15,
      "name": "Plant_Leaves_Light"
    },
    {
      "x": 10,
      "y": 14,
      "z": 16,
      "name": "Plant_Leaves_Light"
    },
    {
      "x": 10,
      "y": 15,
      "z": 16,
      "name": "Plant_Leaves_Light"
    },
    {
      "x": 11,
      "y": 12,
      "z": 5,
      "name": "Plant_Leaves_Light"
    },
    {
      "x": 11,
      "y": 13,
      "z": 5,
      "name": "Plant_Leaves_Light"
    },
    {
      "x": 11,
      "y": 14,
      "z": 5,
      "name": "Plant_Leaves_Light"
    },
    {
      "x": 11,
      "y": 19,
      "z": 5,
      "name": "Plant_Leaves_Light"
    },
    {
      "x": 11,
      "y": 20,
      "z": 5,
      "name": "Plant_Leaves_Light"
    },
    {
      "x": 11,
      "y": 21,
      "z": 5,
      "name": "Plant_Leaves_Light"
    },
    {
      "x": 11,
      "y": 14,
      "z": 6,
      "name": "Wood_Beech_Branch_Long",
      "rotation": 4
    },
    {
      "x": 11,
      "y": 15,
      "z": 6,
      "name": "Plant_Leaves_Light"
    },
    {
      "x": 11,
      "y": 16,
      "z": 6,
      "name": "Plant_Leaves_Light"
    },
    {
      "x": 11,
      "y": 20,
      "z": 6,
      "name": "Wood_Beech_Branch_Long",
      "rotation": 4
    },
    {
      "x": 11,
      "y": 21,
      "z": 6,
      "name": "Plant_Leaves_Light"
    },
    {
      "x": 11,
      "y": 22,
      "z": 6,
      "name": "Plant_Leaves_Light"
    },
    {
      "x": 11,
      "y": 14,
      "z": 7,
      "name": "Wood_Beech_Branch_Long",
      "rotation": 4
    },
    {
      "x": 11,
      "y": 17,
      "z": 7,
      "name": "Plant_Leaves_Light"
    },
    {
      "x": 11,
      "y": 20,
      "z": 7,
      "name": "Wood_Beech_Branch_Long",
      "rotation": 4
    },
    {
      "x": 11,
      "y": 23,
      "z": 7,
      "name": "Plant_Leaves_Light"
    },
    {
      "x": 11,
      "y": 24,
      "z": 7,
      "name": "Plant_Leaves_Light"
    },
    {
      "x": 11,
      "y": 25,
      "z": 7,
      "name": "Plant_Leaves_Light"
    },
    {
      "x": 11,
      "y": 26,
      "z": 7,
      "name": "Plant_Leaves_Light"
    },
    {
      "x": 11,
      "y": 13,
      "z": 8,
      "name": "Wood_Beech_Trunk_Full"
    },
    {
      "x": 11,
      "y": 14,
      "z": 8,
      "name": "Wood_Beech_Trunk_Full"
    },
    {
      "x": 11,
      "y": 15,
      "z": 8,
      "name": "Wood_Beech_Branch_Long"
    },
    {
      "x": 11,
      "y": 16,
      "z": 8,
      "name": "Wood_Beech_Branch_Long"
    },
    {
      "x": 11,
      "y": 17,
      "z": 8,
      "name": "Plant_Leaves_Light"
    },
    {
      "x": 11,
      "y": 18,
      "z": 8,
      "name": "Plant_Leaves_Light"
    },
    {
      "x": 11,
      "y": 19,
      "z": 8,
      "name": "Wood_Beech_Trunk_Full"
    },
    {
      "x": 11,
      "y": 20,
      "z": 8,
      "name": "Wood_Beech_Trunk_Full"
    },
    {
      "x": 11,
      "y": 21,
      "z": 8,
      "name": "Wood_Beech_Branch_Long"
    },
    {
      "x": 11,
      "y": 22,
      "z": 8,
      "name": "Wood_Beech_Branch_Long"
    },
    {
      "x": 11,
      "y": 23,
      "z": 8,
      "name": "Plant_Leaves_Light"
    },
    {
      "x": 11,
      "y": 24,
      "z": 8,
      "name": "Plant_Leaves_Light"
    },
    {
      "x": 11,
      "y": 25,
      "z": 8,
      "name": "Plant_Leaves_Light"
    },
    {
      "x": 11,
      "y": 26,
      "z": 8,
      "name": "Plant_Leaves_Light"
    },
    {
      "x": 11,
      "y": 13,
      "z": 9,
      "name": "Wood_Beech_Trunk_Full"
    },
    {
      "x": 11,
      "y": 19,
      "z": 9,
      "name": "Wood_Beech_Trunk_Full"
    },
    {
      "x": 11,
      "y": 25,
      "z": 9,
      "name": "Wood_Beech_Branch_Long",
      "rotation": 4
    },
    {
      "x": 11,
      "y": 28,
      "z": 9,
      "name": "Plant_Leaves_Light"
    },
    {
      "x": 11,
      "y": 5,
      "z": 10,
      "name": "Wood_Beech_Trunk"
    },
    {
      "x": 11,
      "y": 6,
      "z": 10,
      "name": "Wood_Beech_Trunk"
    },
    {
      "x": 11,
      "y": 7,
      "z": 10,
      "name": "Wood_Beech_Trunk"
    },
    {
      "x": 11,
      "y": 8,
      "z": 10,
      "name": "Wood_Beech_Trunk"
    },
    {
      "x": 11,
      "y": 9,
      "z": 10,
      "name": "Wood_Beech_Trunk"
    },
    {
      "x": 11,
      "y": 10,
      "z": 10,
      "name": "Wood_Beech_Trunk"
    },
    {
      "x": 11,
      "y": 11,
      "z": 10,
      "name": "Wood_Beech_Trunk"
    },
    {
      "x": 11,
      "y": 12,
      "z": 10,
      "name": "Wood_Beech_Trunk"
    },
    {
      "x": 11,
      "y": 13,
      "z": 10,
      "name": "Wood_Beech_Trunk"
    },
    {
      "x": 11,
      "y": 14,
      "z": 10,
      "name": "Wood_Beech_Trunk"
    },
    {
      "x": 11,
      "y": 15,
      "z": 10,
      "name": "Wood_Beech_Trunk"
    },
    {
      "x": 11,
      "y": 16,
      "z": 10,
      "name": "Wood_Beech_Trunk"
    },
    {
      "x": 11,
      "y": 17,
      "z": 10,
      "name": "Wood_Beech_Trunk"
    },
    {
      "x": 11,
      "y": 18,
      "z": 10,
      "name": "Wood_Beech_Trunk"
    },
    {
      "x": 11,
      "y": 19,
      "z": 10,
      "name": "Wood_Beech_Trunk"
    },
    {
      "x": 11,
      "y": 20,
      "z": 10,
      "name": "Wood_Beech_Trunk"
    },
    {
      "x": 11,
      "y": 21,
      "z": 10,
      "name": "Wood_Beech_Trunk"
    },
    {
      "x": 11,
      "y": 22,
      "z": 10,
      "name": "Wood_Beech_Trunk"
    },
    {
      "x": 11,
      "y": 23,
      "z": 10,
      "name": "Wood_Beech_Trunk"
    },
    {
      "x": 11,
      "y": 24,
      "z": 10,
      "name": "Wood_Beech_Trunk"
    },
    {
      "x": 11,
      "y": 25,
      "z": 10,
      "name": "Wood_Beech_Trunk_Full"
    },
    {
      "x": 11,
      "y": 29,
      "z": 10,
      "name": "Plant_Leaves_Light"
    },
    {
      "x": 11,
      "y": 11,
      "z": 11,
      "name": "Wood_Beech_Branch_Long",
      "rotation": 4
    },
    {
      "x": 11,
      "y": 14,
      "z": 11,
      "name": "Wood_Beech_Trunk_Full"
    },
    {
      "x": 11,
      "y": 17,
      "z": 11,
      "name": "Wood_Beech_Trunk_Full"
    },
    {
      "x": 11,
      "y": 25,
      "z": 11,
      "name": "Wood_Beech_Branch_Corner"
    },
    {
      "x": 11,
      "y": 26,
      "z": 11,
      "name": "Plant_Leaves_Light"
    },
    {
      "x": 11,
      "y": 27,
      "z": 11,
      "name": "Plant_Leaves_Light"
    },
    {
      "x": 11,
      "y": 29,
      "z": 11,
      "name": "Plant_Leaves_Light"
    },
    {
      "x": 11,
      "y": 11,
      "z": 12,
      "name": "Wood_Beech_Branch_Long",
      "rotation": 4
    },
    {
      "x": 11,
      "y": 14,
      "z": 12,
      "name": "Wood_Beech_Trunk_Full"
    },
    {
      "x": 11,
      "y": 17,
      "z": 12,
      "name": "Wood_Beech_Trunk_Full"
    },
    {
      "x": 11,
      "y": 18,
      "z": 12,
      "name": "Wood_Beech_Branch_Long"
    },
    {
      "x": 11,
      "y": 19,
      "z": 12,
      "name": "Wood_Beech_Branch_Long"
    },
    {
      "x": 11,
      "y": 20,
      "z": 12,
      "name": "Wood_Beech_Branch_Long"
    },
    {
      "x": 11,
      "y": 21,
      "z": 12,
      "name": "Wood_Beech_Branch_Long"
    },
    {
      "x": 11,
      "y": 22,
      "z": 12,
      "name": "Plant_Leaves_Light"
    },
    {
      "x": 11,
      "y": 23,
      "z": 12,
      "name": "Plant_Leaves_Light"
    },
    {
      "x": 11,
      "y": 26,
      "z": 12,
      "name": "Plant_Leaves_Light"
    },
    {
      "x": 11,
      "y": 27,
      "z": 12,
      "name": "Plant_Leaves_Light"
    },
    {
      "x": 11,
      "y": 11,
      "z": 13,
      "name": "Wood_Beech_Branch_Long",
      "rotation": 4
    },
    {
      "x": 11,
      "y": 14,
      "z": 13,
      "name": "Wood_Beech_Branch_Long",
      "rotation": 4
    },
    {
      "x": 11,
      "y": 17,
      "z": 13,
      "name": "Wood_Beech_Branch_Long",
      "rotation": 4
    },
    {
      "x": 11,
      "y": 21,
      "z": 13,
      "name": "Plant_Leaves_Light"
    },
    {
      "x": 11,
      "y": 22,
      "z": 13,
      "name": "Plant_Leaves_Light"
    },
    {
      "x": 11,
      "y": 23,
      "z": 13,
      "name": "Plant_Leaves_Light"
    },
    {
      "x": 11,
      "y": 25,
      "z": 13,
      "name": "Plant_Leaves_Light"
    },
    {
      "x": 11,
      "y": 26,
      "z": 13,
      "name": "Plant_Leaves_Light"
    },
    {
      "x": 11,
      "y": 27,
      "z": 13,
      "name": "Plant_Leaves_Light"
    },
    {
      "x": 11,
      "y": 11,
      "z": 14,
      "name": "Wood_Beech_Branch_Corner"
    },
    {
      "x": 11,
      "y": 12,
      "z": 14,
      "name": "Plant_Leaves_Light"
    },
    {
      "x": 11,
      "y": 14,
      "z": 14,
      "name": "Wood_Beech_Branch_Long",
      "rotation": 4
    },
    {
      "x": 11,
      "y": 17,
      "z": 14,
      "name": "Wood_Beech_Branch_Long",
      "rotation": 4
    },
    {
      "x": 11,
      "y": 18,
      "z": 14,
      "name": "Plant_Leaves_Light"
    },
    {
      "x": 11,
      "y": 19,
      "z": 14,
      "name": "Plant_Leaves_Light"
    },
    {
      "x": 11,
      "y": 21,
      "z": 14,
      "name": "Plant_Leaves_Light"
    },
    {
      "x": 11,
      "y": 22,
      "z": 14,
      "name": "Plant_Leaves_Light"
    },
    {
      "x": 11,
      "y": 11,
      "z": 15,
      "name": "Plant_Leaves_Light"
    },
    {
      "x": 11,
      "y": 12,
      "z": 15,
      "name": "Plant_Leaves_Light"
    },
    {
      "x": 11,
      "y": 14,
      "z": 15,
      "name": "Wood_Beech_Branch_Corner"
    },
    {
      "x": 11,
      "y": 15,
      "z": 15,
      "name": "Plant_Leaves_Light"
    },
    {
      "x": 11,
      "y": 16,
      "z": 15,
      "name": "Plant_Leaves_Light"
    },
    {
      "x": 11,
      "y": 17,
      "z": 15,
      "name": "Plant_Leaves_Light"
    },
    {
      "x": 11,
      "y": 18,
      "z": 15,
      "name": "Plant_Leaves_Light"
    },
    {
      "x": 11,
      "y": 19,
      "z": 15,
      "name": "Plant_Leaves_Light"
    },
    {
      "x": 11,
      "y": 14,
      "z": 16,
      "name": "Plant_Leaves_Light"
    },
    {
      "x": 11,
      "y": 15,
      "z": 16,
      "name": "Plant_Leaves_Light"
    },
    {
      "x": 11,
      "y": 16,
      "z": 16,
      "name": "Plant_Leaves_Light"
    },
    {
      "x": 12,
      "y": 13,
      "z": 5,
      "name": "Plant_Leaves_Light"
    },
    {
      "x": 12,
      "y": 14,
      "z": 5,
      "name": "Plant_Leaves_Light"
    },
    {
      "x": 12,
      "y": 15,
      "z": 5,
      "name": "Plant_Leaves_Light"
    },
    {
      "x": 12,
      "y": 19,
      "z": 5,
      "name": "Plant_Leaves_Light"
    },
    {
      "x": 12,
      "y": 20,
      "z": 5,
      "name": "Plant_Leaves_Light"
    },
    {
      "x": 12,
      "y": 21,
      "z": 5,
      "name": "Plant_Leaves_Light"
    },
    {
      "x": 12,
      "y": 14,
      "z": 6,
      "name": "Plant_Leaves_Light"
    },
    {
      "x": 12,
      "y": 15,
      "z": 6,
      "name": "Plant_Leaves_Light"
    },
    {
      "x": 12,
      "y": 19,
      "z": 6,
      "name": "Plant_Leaves_Light"
    },
    {
      "x": 12,
      "y": 20,
      "z": 6,
      "name": "Plant_Leaves_Light"
    },
    {
      "x": 12,
      "y": 21,
      "z": 6,
      "name": "Plant_Leaves_Light"
    },
    {
      "x": 12,
      "y": 22,
      "z": 6,
      "name": "Plant_Leaves_Light"
    },
    {
      "x": 12,
      "y": 23,
      "z": 6,
      "name": "Plant_Leaves_Light"
    },
    {
      "x": 12,
      "y": 17,
      "z": 7,
      "name": "Plant_Leaves_Light"
    },
    {
      "x": 12,
      "y": 23,
      "z": 7,
      "name": "Plant_Leaves_Light"
    },
    {
      "x": 12,
      "y": 24,
      "z": 7,
      "name": "Plant_Leaves_Light"
    },
    {
      "x": 12,
      "y": 14,
      "z": 8,
      "name": "Wood_Beech_Branch_Long",
      "rotation": 5
    },
    {
      "x": 12,
      "y": 17,
      "z": 8,
      "name": "Plant_Leaves_Light"
    },
    {
      "x": 12,
      "y": 20,
      "z": 8,
      "name": "Wood_Beech_Branch_Long",
      "rotation": 5
    },
    {
      "x": 12,
      "y": 23,
      "z": 8,
      "name": "Plant_Leaves_Light"
    },
    {
      "x": 12,
      "y": 24,
      "z": 8,
      "name": "Plant_Leaves_Light"
    },
    {
      "x": 12,
      "y": 25,
      "z": 8,
      "name": "Plant_Leaves_Light"
    },
    {
      "x": 12,
      "y": 26,
      "z": 8,
      "name": "Plant_Leaves_Light"
    },
    {
      "x": 12,
      "y": 25,
      "z": 9,
      "name": "Plant_Leaves_Light"
    },
    {
      "x": 12,
      "y": 26,
      "z": 9,
      "name": "Plant_Leaves_Light"
    },
    {
      "x": 12,
      "y": 28,
      "z": 9,
      "name": "Plant_Leaves_Light"
    },
    {
      "x": 12,
      "y": 29,
      "z": 9,
      "name": "Plant_Leaves_Light"
    },
    {
      "x": 12,
      "y": 12,
      "z": 10,
      "name": "Wood_Beech_Trunk_Full"
    },
    {
      "x": 12,
      "y": 18,
      "z": 10,
      "name": "Wood_Beech_Trunk_Full"
    },
    {
      "x": 12,
      "y": 25,
      "z": 10,
      "name": "Wood_Beech_Branch_Corner",
      "rotation": 1
    },
    {
      "x": 12,
      "y": 26,
      "z": 10,
      "name": "Wood_Beech_Branch_Long"
    },
    {
      "x": 12,
      "y": 27,
      "z": 10,
      "name": "Wood_Beech_Branch_Long"
    },
    {
      "x": 12,
      "y": 28,
      "z": 10,
      "name": "Wood_Beech_Branch_Long"
    },
    {
      "x": 12,
      "y": 29,
      "z": 10,
      "name": "Plant_Leaves_Light"
    },
    {
      "x": 12,
      "y": 23,
      "z": 11,
      "name": "Plant_Leaves_Light"
    },
    {
      "x": 12,
      "y": 26,
      "z": 11,
      "name": "Plant_Leaves_Light"
    },
    {
      "x": 12,
      "y": 28,
      "z": 11,
      "name": "Plant_Leaves_Light"
    },
    {
      "x": 12,
      "y": 29,
      "z": 11,
      "name": "Plant_Leaves_Light"
    },
    {
      "x": 12,
      "y": 14,
      "z": 12,
      "name": "Wood_Beech_Branch_Long",
      "rotation": 5
    },
    {
      "x": 12,
      "y": 20,
      "z": 12,
      "name": "Plant_Leaves_Light"
    },
    {
      "x": 12,
      "y": 23,
      "z": 12,
      "name": "Plant_Leaves_Light"
    },
    {
      "x": 12,
      "y": 26,
      "z": 12,
      "name": "Plant_Leaves_Light"
    },
    {
      "x": 12,
      "y": 27,
      "z": 12,
      "name": "Plant_Leaves_Light"
    },
    {
      "x": 12,
      "y": 11,
      "z": 13,
      "name": "Plant_Leaves_Light"
    },
    {
      "x": 12,
      "y": 19,
      "z": 13,
      "name": "Plant_Leaves_Light"
    },
    {
      "x": 12,
      "y": 21,
      "z": 13,
      "name": "Plant_Leaves_Light"
    },
    {
      "x": 12,
      "y": 25,
      "z": 13,
      "name": "Plant_Leaves_Light"
    },
    {
      "x": 12,
      "y": 26,
      "z": 13,
      "name": "Plant_Leaves_Light"
    },
    {
      "x": 12,
      "y": 11,
      "z": 14,
      "name": "Plant_Leaves_Light"
    },
    {
      "x": 12,
      "y": 12,
      "z": 14,
      "name": "Plant_Leaves_Light"
    },
    {
      "x": 12,
      "y": 17,
      "z": 14,
      "name": "Plant_Leaves_Light"
    },
    {
      "x": 12,
      "y": 18,
      "z": 14,
      "name": "Plant_Leaves_Light"
    },
    {
      "x": 12,
      "y": 19,
      "z": 14,
      "name": "Plant_Leaves_Light"
    },
    {
      "x": 12,
      "y": 21,
      "z": 14,
      "name": "Plant_Leaves_Light"
    },
    {
      "x": 12,
      "y": 22,
      "z": 14,
      "name": "Plant_Leaves_Light"
    },
    {
      "x": 12,
      "y": 11,
      "z": 15,
      "name": "Plant_Leaves_Light"
    },
    {
      "x": 12,
      "y": 12,
      "z": 15,
      "name": "Plant_Leaves_Light"
    },
    {
      "x": 12,
      "y": 14,
      "z": 15,
      "name": "Plant_Leaves_Light"
    },
    {
      "x": 12,
      "y": 15,
      "z": 15,
      "name": "Plant_Leaves_Light"
    },
    {
      "x": 12,
      "y": 16,
      "z": 15,
      "name": "Plant_Leaves_Light"
    },
    {
      "x": 12,
      "y": 17,
      "z": 15,
      "name": "Plant_Leaves_Light"
    },
    {
      "x": 12,
      "y": 18,
      "z": 15,
      "name": "Plant_Leaves_Light"
    },
    {
      "x": 12,
      "y": 11,
      "z": 16,
      "name": "Plant_Leaves_Light"
    },
    {
      "x": 12,
      "y": 14,
      "z": 16,
      "name": "Plant_Leaves_Light"
    },
    {
      "x": 12,
      "y": 15,
      "z": 16,
      "name": "Plant_Leaves_Light"
    },
    {
      "x": 13,
      "y": 14,
      "z": 5,
      "name": "Plant_Leaves_Light"
    },
    {
      "x": 13,
      "y": 14,
      "z": 6,
      "name": "Plant_Leaves_Light"
    },
    {
      "x": 13,
      "y": 15,
      "z": 6,
      "name": "Plant_Leaves_Light"
    },
    {
      "x": 13,
      "y": 20,
      "z": 6,
      "name": "Plant_Leaves_Light"
    },
    {
      "x": 13,
      "y": 21,
      "z": 6,
      "name": "Plant_Leaves_Light"
    },
    {
      "x": 13,
      "y": 15,
      "z": 7,
      "name": "Plant_Leaves_Light"
    },
    {
      "x": 13,
      "y": 20,
      "z": 7,
      "name": "Plant_Leaves_Light"
    },
    {
      "x": 13,
      "y": 14,
      "z": 8,
      "name": "Wood_Beech_Branch_Long",
      "rotation": 5
    },
    {
      "x": 13,
      "y": 15,
      "z": 8,
      "name": "Plant_Leaves_Light"
    },
    {
      "x": 13,
      "y": 20,
      "z": 8,
      "name": "Plant_Leaves_Light"
    },
    {
      "x": 13,
      "y": 21,
      "z": 8,
      "name": "Plant_Leaves_Light"
    },
    {
      "x": 13,
      "y": 23,
      "z": 8,
      "name": "Plant_Leaves_Light"
    },
    {
      "x": 13,
      "y": 26,
      "z": 9,
      "name": "Plant_Leaves_Light"
    },
    {
      "x": 13,
      "y": 28,
      "z": 9,
      "name": "Plant_Leaves_Light"
    },
    {
      "x": 13,
      "y": 12,
      "z": 10,
      "name": "Wood_Beech_Trunk_Full"
    },
    {
      "x": 13,
      "y": 18,
      "z": 10,
      "name": "Wood_Beech_Trunk_Full"
    },
    {
      "x": 13,
      "y": 19,
      "z": 10,
      "name": "Wood_Beech_Branch_Long"
    },
    {
      "x": 13,
      "y": 20,
      "z": 10,
      "name": "Wood_Beech_Branch_Long"
    },
    {
      "x": 13,
      "y": 21,
      "z": 10,
      "name": "Wood_Beech_Branch_Long"
    },
    {
      "x": 13,
      "y": 22,
      "z": 10,
      "name": "Wood_Beech_Branch_Long"
    },
    {
      "x": 13,
      "y": 23,
      "z": 10,
      "name": "Plant_Leaves_Light"
    },
    {
      "x": 13,
      "y": 24,
      "z": 10,
      "name": "Plant_Leaves_Light"
    },
    {
      "x": 13,
      "y": 28,
      "z": 10,
      "name": "Plant_Leaves_Light"
    },
    {
      "x": 13,
      "y": 29,
      "z": 10,
      "name": "Plant_Leaves_Light"
    },
    {
      "x": 13,
      "y": 18,
      "z": 11,
      "name": "Wood_Beech_Branch_Long",
      "rotation": 4
    },
    {
      "x": 13,
      "y": 23,
      "z": 11,
      "name": "Plant_Leaves_Light"
    },
    {
      "x": 13,
      "y": 24,
      "z": 11,
      "name": "Plant_Leaves_Light"
    },
    {
      "x": 13,
      "y": 26,
      "z": 11,
      "name": "Plant_Leaves_Light"
    },
    {
      "x": 13,
      "y": 14,
      "z": 12,
      "name": "Wood_Beech_Branch_Long",
      "rotation": 5
    },
    {
      "x": 13,
      "y": 18,
      "z": 12,
      "name": "Plant_Leaves_Light"
    },
    {
      "x": 13,
      "y": 19,
      "z": 12,
      "name": "Plant_Leaves_Light"
    },
    {
      "x": 13,
      "y": 20,
      "z": 12,
      "name": "Plant_Leaves_Light"
    },
    {
      "x": 13,
      "y": 21,
      "z": 12,
      "name": "Plant_Leaves_Light"
    },
    {
      "x": 13,
      "y": 23,
      "z": 12,
      "name": "Plant_Leaves_Light"
    },
    {
      "x": 13,
      "y": 25,
      "z": 12,
      "name": "Plant_Leaves_Light"
    },
    {
      "x": 13,
      "y": 26,
      "z": 12,
      "name": "Plant_Leaves_Light"
    },
    {
      "x": 13,
      "y": 11,
      "z": 13,
      "name": "Plant_Leaves_Light"
    },
    {
      "x": 13,
      "y": 18,
      "z": 13,
      "name": "Plant_Leaves_Light"
    },
    {
      "x": 13,
      "y": 19,
      "z": 13,
      "name": "Plant_Leaves_Light"
    },
    {
      "x": 13,
      "y": 20,
      "z": 13,
      "name": "Plant_Leaves_Light"
    },
    {
      "x": 13,
      "y": 21,
      "z": 13,
      "name": "Plant_Leaves_Light"
    },
    {
      "x": 13,
      "y": 11,
      "z": 14,
      "name": "Plant_Leaves_Light"
    },
    {
      "x": 13,
      "y": 17,
      "z": 14,
      "name": "Plant_Leaves_Light"
    },
    {
      "x": 13,
      "y": 18,
      "z": 14,
      "name": "Plant_Leaves_Light"
    },
    {
      "x": 13,
      "y": 11,
      "z": 15,
      "name": "Plant_Leaves_Light"
    },
    {
      "x": 13,
      "y": 15,
      "z": 15,
      "name": "Plant_Leaves_Light"
    },
    {
      "x": 13,
      "y": 17,
      "z": 15,
      "name": "Plant_Leaves_Light"
    },
    {
      "x": 14,
      "y": 14,
      "z": 7,
      "name": "Plant_Leaves_Light"
    },
    {
      "x": 14,
      "y": 13,
      "z": 8,
      "name": "Plant_Leaves_Light"
    },
    {
      "x": 14,
      "y": 14,
      "z": 8,
      "name": "Plant_Leaves_Light"
    },
    {
      "x": 14,
      "y": 19,
      "z": 8,
      "name": "Plant_Leaves_Light"
    },
    {
      "x": 14,
      "y": 22,
      "z": 9,
      "name": "Plant_Leaves_Light"
    },
    {
      "x": 14,
      "y": 12,
      "z": 10,
      "name": "Wood_Beech_Branch_Long",
      "rotation": 5
    },
    {
      "x": 14,
      "y": 18,
      "z": 10,
      "name": "Wood_Beech_Branch_Long",
      "rotation": 5
    },
    {
      "x": 14,
      "y": 22,
      "z": 10,
      "name": "Plant_Leaves_Light"
    },
    {
      "x": 14,
      "y": 23,
      "z": 10,
      "name": "Plant_Leaves_Light"
    },
    {
      "x": 14,
      "y": 24,
      "z": 10,
      "name": "Plant_Leaves_Light"
    },
    {
      "x": 14,
      "y": 22,
      "z": 11,
      "name": "Plant_Leaves_Light"
    },
    {
      "x": 14,
      "y": 23,
      "z": 11,
      "name": "Plant_Leaves_Light"
    },
    {
      "x": 14,
      "y": 14,
      "z": 12,
      "name": "Wood_Beech_Branch_Long",
      "rotation": 5
    },
    {
      "x": 14,
      "y": 16,
      "z": 12,
      "name": "Plant_Leaves_Light"
    },
    {
      "x": 14,
      "y": 18,
      "z": 12,
      "name": "Plant_Leaves_Light"
    },
    {
      "x": 14,
      "y": 19,
      "z": 12,
      "name": "Plant_Leaves_Light"
    },
    {
      "x": 14,
      "y": 20,
      "z": 12,
      "name": "Plant_Leaves_Light"
    },
    {
      "x": 14,
      "y": 22,
      "z": 12,
      "name": "Plant_Leaves_Light"
    },
    {
      "x": 14,
      "y": 23,
      "z": 12,
      "name": "Plant_Leaves_Light"
    },
    {
      "x": 14,
      "y": 15,
      "z": 13,
      "name": "Plant_Leaves_Light"
    },
    {
      "x": 14,
      "y": 18,
      "z": 13,
      "name": "Plant_Leaves_Light"
    },
    {
      "x": 14,
      "y": 20,
      "z": 13,
      "name": "Plant_Leaves_Light"
    },
    {
      "x": 14,
      "y": 14,
      "z": 14,
      "name": "Plant_Leaves_Light"
    },
    {
      "x": 14,
      "y": 15,
      "z": 14,
      "name": "Plant_Leaves_Light"
    },
    {
      "x": 15,
      "y": 12,
      "z": 8,
      "name": "Plant_Leaves_Light"
    },
    {
      "x": 15,
      "y": 13,
      "z": 8,
      "name": "Plant_Leaves_Light"
    },
    {
      "x": 15,
      "y": 18,
      "z": 8,
      "name": "Plant_Leaves_Light"
    },
    {
      "x": 15,
      "y": 19,
      "z": 8,
      "name": "Plant_Leaves_Light"
    },
    {
      "x": 15,
      "y": 12,
      "z": 9,
      "name": "Plant_Leaves_Light"
    },
    {
      "x": 15,
      "y": 13,
      "z": 9,
      "name": "Plant_Leaves_Light"
    },
    {
      "x": 15,
      "y": 18,
      "z": 9,
      "name": "Plant_Leaves_Light"
    },
    {
      "x": 15,
      "y": 19,
      "z": 9,
      "name": "Plant_Leaves_Light"
    },
    {
      "x": 15,
      "y": 20,
      "z": 9,
      "name": "Plant_Leaves_Light"
    },
    {
      "x": 15,
      "y": 22,
      "z": 9,
      "name": "Plant_Leaves_Light"
    },
    {
      "x": 15,
      "y": 23,
      "z": 9,
      "name": "Plant_Leaves_Light"
    },
    {
      "x": 15,
      "y": 12,
      "z": 10,
      "name": "Wood_Beech_Branch_Long",
      "rotation": 5
    },
    {
      "x": 15,
      "y": 18,
      "z": 10,
      "name": "Wood_Beech_Branch_Long",
      "rotation": 5
    },
    {
      "x": 15,
      "y": 19,
      "z": 10,
      "name": "Plant_Leaves_Light"
    },
    {
      "x": 15,
      "y": 20,
      "z": 10,
      "name": "Plant_Leaves_Light"
    },
    {
      "x": 15,
      "y": 22,
      "z": 10,
      "name": "Plant_Leaves_Light"
    },
    {
      "x": 15,
      "y": 23,
      "z": 10,
      "name": "Plant_Leaves_Light"
    },
    {
      "x": 15,
      "y": 11,
      "z": 11,
      "name": "Plant_Leaves_Light"
    },
    {
      "x": 15,
      "y": 12,
      "z": 11,
      "name": "Plant_Leaves_Light"
    },
    {
      "x": 15,
      "y": 13,
      "z": 11,
      "name": "Plant_Leaves_Light"
    },
    {
      "x": 15,
      "y": 15,
      "z": 11,
      "name": "Plant_Leaves_Light"
    },
    {
      "x": 15,
      "y": 16,
      "z": 11,
      "name": "Plant_Leaves_Light"
    },
    {
      "x": 15,
      "y": 19,
      "z": 11,
      "name": "Plant_Leaves_Light"
    },
    {
      "x": 15,
      "y": 20,
      "z": 11,
      "name": "Plant_Leaves_Light"
    },
    {
      "x": 15,
      "y": 22,
      "z": 11,
      "name": "Plant_Leaves_Light"
    },
    {
      "x": 15,
      "y": 11,
      "z": 12,
      "name": "Plant_Leaves_Light"
    },
    {
      "x": 15,
      "y": 12,
      "z": 12,
      "name": "Plant_Leaves_Light"
    },
    {
      "x": 15,
      "y": 13,
      "z": 12,
      "name": "Plant_Leaves_Light"
    },
    {
      "x": 15,
      "y": 14,
      "z": 12,
      "name": "Wood_Beech_Branch_Corner",
      "rotation": 1
    },
    {
      "x": 15,
      "y": 15,
      "z": 12,
      "name": "Plant_Leaves_Light"
    },
    {
      "x": 15,
      "y": 16,
      "z": 12,
      "name": "Plant_Leaves_Light"
    },
    {
      "x": 15,
      "y": 18,
      "z": 12,
      "name": "Plant_Leaves_Light"
    },
    {
      "x": 15,
      "y": 19,
      "z": 12,
      "name": "Plant_Leaves_Light"
    },
    {
      "x": 15,
      "y": 12,
      "z": 13,
      "name": "Plant_Leaves_Light"
    },
    {
      "x": 15,
      "y": 14,
      "z": 13,
      "name": "Plant_Leaves_Light"
    },
    {
      "x": 15,
      "y": 15,
      "z": 13,
      "name": "Plant_Leaves_Light"
    },
    {
      "x": 15,
      "y": 18,
      "z": 13,
      "name": "Plant_Leaves_Light"
    },
    {
      "x": 16,
      "y": 12,
      "z": 8,
      "name": "Plant_Leaves_Light"
    },
    {
      "x": 16,
      "y": 18,
      "z": 8,
      "name": "Plant_Leaves_Light"
    },
    {
      "x": 16,
      "y": 12,
      "z": 9,
      "name": "Plant_Leaves_Light"
    },
    {
      "x": 16,
      "y": 13,
      "z": 9,
      "name": "Plant_Leaves_Light"
    },
    {
      "x": 16,
      "y": 14,
      "z": 9,
      "name": "Plant_Leaves_Light"
    },
    {
      "x": 16,
      "y": 18,
      "z": 9,
      "name": "Plant_Leaves_Light"
    },
    {
      "x": 16,
      "y": 19,
      "z": 9,
      "name": "Plant_Leaves_Light"
    },
    {
      "x": 16,
      "y": 12,
      "z": 10,
      "name": "Wood_Beech_Branch_Corner",
      "rotation": 1
    },
    {
      "x": 16,
      "y": 13,
      "z": 10,
      "name": "Plant_Leaves_Light"
    },
    {
      "x": 16,
      "y": 14,
      "z": 10,
      "name": "Plant_Leaves_Light"
    },
    {
      "x": 16,
      "y": 18,
      "z": 10,
      "name": "Plant_Leaves_Light"
    },
    {
      "x": 16,
      "y": 19,
      "z": 10,
      "name": "Plant_Leaves_Light"
    },
    {
      "x": 16,
      "y": 20,
      "z": 10,
      "name": "Plant_Leaves_Light"
    },
    {
      "x": 16,
      "y": 11,
      "z": 11,
      "name": "Plant_Leaves_Light"
    },
    {
      "x": 16,
      "y": 12,
      "z": 11,
      "name": "Plant_Leaves_Light"
    },
    {
      "x": 16,
      "y": 13,
      "z": 11,
      "name": "Plant_Leaves_Light"
    },
    {
      "x": 16,
      "y": 14,
      "z": 11,
      "name": "Plant_Leaves_Light"
    },
    {
      "x": 16,
      "y": 15,
      "z": 11,
      "name": "Plant_Leaves_Light"
    },
    {
      "x": 16,
      "y": 18,
      "z": 11,
      "name": "Plant_Leaves_Light"
    },
    {
      "x": 16,
      "y": 19,
      "z": 11,
      "name": "Plant_Leaves_Light"
    },
    {
      "x": 16,
      "y": 20,
      "z": 11,
      "name": "Plant_Leaves_Light"
    },
    {
      "x": 16,
      "y": 12,
      "z": 12,
      "name": "Plant_Leaves_Light"
    },
    {
      "x": 16,
      "y": 13,
      "z": 12,
      "name": "Plant_Leaves_Light"
    },
    {
      "x": 16,
      "y": 14,
      "z": 12,
      "name": "Plant_Leaves_Light"
    },
    {
      "x": 16,
      "y": 15,
      "z": 12,
      "name": "Plant_Leaves_Light"
    },
    {
      "x": 17,
      "y": 12,
      "z": 9,
      "name": "Plant_Leaves_Light"
    },
    {
      "x": 17,
      "y": 12,
      "z": 10,
      "name": "Plant_Leaves_Light"
    },
    {
      "x": 17,
      "y": 13,
      "z": 10,
      "name": "Plant_Leaves_Light"
    },
    {
      "x": 17,
      "y": 12,
      "z": 11,
      "name": "Plant_Leaves_Light"
    }
  ]
}