{
  "version": 8,
  "blockIdVersion": 11,
  "anchorX": 0,
  "anchorY": 0,
  "anchorZ": 0,
  "blocks": [
    {
      "x": -4,
      "y": 0,
      "z": -3,
      "name": "Cloth_Block_Wool_Purple_Light_Half",
      "rotation": 7
    },
    {
      "x": -4,
      "y": 0,
      "z": -2,
      "name": "Cloth_Block_Wool_Purple_Light_Half",
      "rotation": 7
    },
    {
      "x": -4,
      "y": 0,
      "z": -1,
      "name": "Soil_Clay_Smooth_Purple_Stairs",
      "rotation": 3
    },
    {
      "x": -4,
      "y": 0,
      "z": 0,
      "name": "Soil_Clay_Smooth_Purple_Stairs",
      "rotation": 3
    },
    {
      "x": -4,
      "y": 0,
      "z": 1,
      "name": "Soil_Clay_Smooth_Purple_Stairs",
      "rotation": 3
    },
    {
      "x": -4,
      "y": 0,
      "z": 2,
      "name": "Cloth_Block_Wool_Purple_Light_Half",
      "rotation": 7
    },
    {
      "x": -4,
      "y": 0,
      "z": 3,
      "name": "Cloth_Block_Wool_Purple_Light_Half",
      "rotation": 7
    },
    {
      "x": -3,
      "y": 0,
      "z": -4,
      "name": "Cloth_Block_Wool_Purple_Light_Half",
      "rotation": 6
    },
    {
      "x": -3,
      "y": 0,
      "z": -3,
      "name": "Soil_Grass"
    },
    {
      "x": -3,
      "y": 1,
      "z": -3,
      "name": "Plant_Leaves_Fir_Lightpink",
      "support": 15
    },
    {
      "x": -3,
      "y": 0,
      "z": -2,
      "name": "Soil_Grass"
    },
    {
      "x": -3,
      "y": 1,
      "z": -2,
      "name": "Plant_Leaves_Fir_Lightpink",
      "support": 15
    },
    {
      "x": -3,
      "y": 0,
      "z": -1,
      "name": "Soil_Grass"
    },
    {
      "x": -3,
      "y": 1,
      "z": -1,
      "name": "Soil_Clay_Smooth_Purple_Stairs",
      "rotation": 3
    },
    {
      "x": -3,
      "y": 0,
      "z": 0,
      "name": "Soil_Grass"
    },
    {
      "x": -3,
      "y": 1,
      "z": 0,
      "name": "Soil_Clay_Smooth_Purple_Stairs",
      "rotation": 3
    },
    {
      "x": -3,
      "y": 0,
      "z": 1,
      "name": "Soil_Grass"
    },
    {
      "x": -3,
      "y": 1,
      "z": 1,
      "name": "Soil_Clay_Smooth_Purple_Stairs",
      "rotation": 3
    },
    {
      "x": -3,
      "y": 0,
      "z": 2,
      "name": "Soil_Grass"
    },
    {
      "x": -3,
      "y": 1,
      "z": 2,
      "name": "Plant_Leaves_Fir_Lightpink",
      "support": 15
    },
    {
      "x": -3,
      "y": 0,
      "z": 3,
      "name": "Soil_Grass"
    },
    {
      "x": -3,
      "y": 1,
      "z": 3,
      "name": "Plant_Leaves_Fir_Lightpink",
      "support": 15
    },
    {
      "x": -3,
      "y": 0,
      "z": 4,
      "name": "Cloth_Block_Wool_Purple_Light_Half",
      "rotation": 4
    },
    {
      "x": -2,
      "y": 0,
      "z": -4,
      "name": "Cloth_Block_Wool_Purple_Light_Half",
      "rotation": 6
    },
    {
      "x": -2,
      "y": 0,
      "z": -3,
      "name": "Soil_Grass"
    },
    {
      "x": -2,
      "y": 1,
      "z": -3,
      "name": "Plant_Leaves_Fir_Lightpink",
      "support": 15
    },
    {
      "x": -2,
      "y": 0,
      "z": -2,
      "name": "Soil_Grass"
    },
    {
      "x": -2,
      "y": 1,
      "z": -2,
      "name": "Cloth_Block_Wool_Purple_Light"
    },
    {
      "x": -2,
      "y": 2,
      "z": -2,
      "name": "Plant_Crop_Mushroom_Block_Brown_Branch",
      "support": 15
    },
    {
      "x": -2,
      "y": 3,
      "z": -2,
      "name": "Plant_Crop_Mushroom_Block_Brown_Branch",
      "support": 15
    },
    {
      "x": -2,
      "y": 4,
      "z": -2,
      "name": "Cloth_Block_Wool_Purple_Light"
    },
    {
      "x": -2,
      "y": 5,
      "z": -2,
      "name": "Deco_Lantern"
    },
    {
      "x": -2,
      "y": 6,
      "z": -2,
      "name": "Cloth_Block_Wool_Purple_Light"
    },
    {
      "x": -2,
      "y": 0,
      "z": -1,
      "name": "Soil_Grass"
    },
    {
      "x": -2,
      "y": 1,
      "z": -1,
      "name": "Soil_Clay_Smooth_Purple_Stairs",
      "rotation": 1
    },
    {
      "x": -2,
      "y": 4,
      "z": -1,
      "name": "Cloth_Block_Wool_Purple_Light_Stairs",
      "rotation": 9
    },
    {
      "x": -2,
      "y": 5,
      "z": -1,
      "name": "Cloth_Block_Wool_Purple_Light_Half",
      "rotation": 6
    },
    {
      "x": -2,
      "y": 6,
      "z": -1,
      "name": "Cloth_Block_Wool_Purple_Light_Half"
    },
    {
      "x": -2,
      "y": 0,
      "z": 0,
      "name": "Soil_Grass"
    },
    {
      "x": -2,
      "y": 1,
      "z": 0,
      "name": "Soil_Clay_Smooth_Purple_Stairs",
      "rotation": 3
    },
    {
      "x": -2,
      "y": 0,
      "z": 1,
      "name": "Soil_Grass"
    },
    {
      "x": -2,
      "y": 1,
      "z": 1,
      "name": "Soil_Clay_Smooth_Purple_Stairs",
      "rotation": 1
    },
    {
      "x": -2,
      "y": 4,
      "z": 1,
      "name": "Cloth_Block_Wool_Purple_Light_Stairs",
      "rotation": 9
    },
    {
      "x": -2,
      "y": 5,
      "z": 1,
      "name": "Cloth_Block_Wool_Purple_Light_Half",
      "rotation": 4
    },
    {
      "x": -2,
      "y": 6,
      "z": 1,
      "name": "Cloth_Block_Wool_Purple_Light_Half"
    },
    {
      "x": -2,
      "y": 0,
      "z": 2,
      "name": "Soil_Dirt"
    },
    {
      "x": -2,
      "y": 1,
      "z": 2,
      "name": "Cloth_Block_Wool_Purple_Light"
    },
    {
      "x": -2,
      "y": 2,
      "z": 2,
      "name": "Plant_Crop_Mushroom_Block_Brown_Branch",
      "support": 15
    },
    {
      "x": -2,
      "y": 3,
      "z": 2,
      "name": "Plant_Crop_Mushroom_Block_Brown_Branch",
      "support": 15
    },
    {
      "x": -2,
      "y": 4,
      "z": 2,
      "name": "Cloth_Block_Wool_Purple_Light"
    },
    {
      "x": -2,
      "y": 5,
      "z": 2,
      "name": "Deco_Lantern"
    },
    {
      "x": -2,
      "y": 6,
      "z": 2,
      "name": "Cloth_Block_Wool_Purple_Light"
    },
    {
      "x": -2,
      "y": 0,
      "z": 3,
      "name": "Soil_Grass"
    },
    {
      "x": -2,
      "y": 1,
      "z": 3,
      "name": "Plant_Leaves_Fir_Lightpink",
      "support": 15
    },
    {
      "x": -2,
      "y": 0,
      "z": 4,
      "name": "Cloth_Block_Wool_Purple_Light_Half",
      "rotation": 4
    },
    {
      "x": -1,
      "y": 0,
      "z": -4,
      "name": "Soil_Clay_Smooth_Purple_Stairs",
      "rotation": 2
    },
    {
      "x": -1,
      "y": 0,
      "z": -3,
      "name": "Soil_Grass"
    },
    {
      "x": -1,
      "y": 1,
      "z": -3,
      "name": "Soil_Clay_Smooth_Purple_Stairs",
      "rotation": 2
    },
    {
      "x": -1,
      "y": 0,
      "z": -2,
      "name": "Soil_Grass"
    },
    {
      "x": -1,
      "y": 1,
      "z": -2,
      "name": "Soil_Clay_Smooth_Purple_Stairs"
    },
    {
      "x": -1,
      "y": 4,
      "z": -2,
      "name": "Cloth_Block_Wool_Purple_Light_Stairs",
      "rotation": 8
    },
    {
      "x": -1,
      "y": 5,
      "z": -2,
      "name": "Cloth_Block_Wool_Purple_Light_Half",
      "rotation": 7
    },
    {
      "x": -1,
      "y": 6,
      "z": -2,
      "name": "Cloth_Block_Wool_Purple_Light_Half"
    },
    {
      "x": -1,
      "y": 0,
      "z": -1,
      "name": "Cloth_Block_Wool_Purple_Light"
    },
    {
      "x": -1,
      "y": 1,
      "z": -1,
      "name": "Empty"
    },
    {
      "x": -1,
      "y": 5,
      "z": -1,
      "name": "Cloth_Block_Wool_Purple_Light"
    },
    {
      "x": -1,
      "y": 0,
      "z": 0,
      "name": "Cloth_Block_Wool_Purple_Light"
    },
    {
      "x": -1,
      "y": 1,
      "z": 0,
      "name": "Empty"
    },
    {
      "x": -1,
      "y": 5,
      "z": 0,
      "name": "Cloth_Block_Wool_Purple_Light"
    },
    {
      "x": -1,
      "y": 0,
      "z": 1,
      "name": "Cloth_Block_Wool_Purple_Light"
    },
    {
      "x": -1,
      "y": 1,
      "z": 1,
      "name": "Empty"
    },
    {
      "x": -1,
      "y": 5,
      "z": 1,
      "name": "Cloth_Block_Wool_Purple_Light"
    },
    {
      "x": -1,
      "y": 0,
      "z": 2,
      "name": "Soil_Grass"
    },
    {
      "x": -1,
      "y": 1,
      "z": 2,
      "name": "Soil_Clay_Smooth_Purple_Stairs",
      "rotation": 2
    },
    {
      "x": -1,
      "y": 4,
      "z": 2,
      "name": "Cloth_Block_Wool_Purple_Light_Stairs",
      "rotation": 10
    },
    {
      "x": -1,
      "y": 5,
      "z": 2,
      "name": "Cloth_Block_Wool_Purple_Light_Half",
      "rotation": 7
    },
    {
      "x": -1,
      "y": 6,
      "z": 2,
      "name": "Cloth_Block_Wool_Purple_Light_Half"
    },
    {
      "x": -1,
      "y": 0,
      "z": 3,
      "name": "Soil_Grass"
    },
    {
      "x": -1,
      "y": 1,
      "z": 3,
      "name": "Soil_Clay_Smooth_Purple_Stairs"
    },
    {
      "x": -1,
      "y": 0,
      "z": 4,
      "name": "Soil_Clay_Smooth_Purple_Stairs"
    },
    {
      "x": 0,
      "y": 0,
      "z": -4,
      "name": "Soil_Clay_Smooth_Purple_Stairs",
      "rotation": 2
    },
    {
      "x": 0,
      "y": 0,
      "z": -3,
      "name": "Soil_Grass"
    },
    {
      "x": 0,
      "y": 1,
      "z": -3,
      "name": "Soil_Clay_Smooth_Purple_Stairs",
      "rotation": 2
    },
    {
      "x": 0,
      "y": 0,
      "z": -2,
      "name": "Soil_Grass"
    },
    {
      "x": 0,
      "y": 1,
      "z": -2,
      "name": "Soil_Clay_Smooth_Purple_Stairs",
      "rotation": 2
    },
    {
      "x": 0,
      "y": 0,
      "z": -1,
      "name": "Cloth_Block_Wool_Purple_Light"
    },
    {
      "x": 0,
      "y": 1,
      "z": -1,
      "name": "Empty"
    },
    {
      "x": 0,
      "y": 5,
      "z": -1,
      "name": "Cloth_Block_Wool_Purple_Light"
    },
    {
      "x": 0,
      "y": 0,
      "z": 0,
      "name": "Rock_Crystal_Pink_Block"
    },
    {
      "x": 0,
      "y": 1,
      "z": 0,
      "name": "Empty"
    },
    {
      "x": 0,
      "y": 2,
      "z": 0,
      "name": "Plant_Flower_Water_Purple"
    },
    {
      "x": 0,
      "y": 0,
      "z": 1,
      "name": "Cloth_Block_Wool_Purple_Light"
    },
    {
      "x": 0,
      "y": 1,
      "z": 1,
      "name": "Empty"
    },
    {
      "x": 0,
      "y": 5,
      "z": 1,
      "name": "Cloth_Block_Wool_Purple_Light"
    },
    {
      "x": 0,
      "y": 0,
      "z": 2,
      "name": "Soil_Grass"
    },
    {
      "x": 0,
      "y": 1,
      "z": 2,
      "name": "Soil_Clay_Smooth_Purple_Stairs"
    },
    {
      "x": 0,
      "y": 0,
      "z": 3,
      "name": "Soil_Grass"
    },
    {
      "x": 0,
      "y": 1,
      "z": 3,
      "name": "Soil_Clay_Smooth_Purple_Stairs"
    },
    {
      "x": 0,
      "y": 0,
      "z": 4,
      "name": "Soil_Clay_Smooth_Purple_Stairs"
    },
    {
      "x": 1,
      "y": 0,
      "z": -4,
      "name": "Soil_Clay_Smooth_Purple_Stairs",
      "rotation": 2
    },
    {
      "x": 1,
      "y": 0,
      "z": -3,
      "name": "Soil_Grass"
    },
    {
      "x": 1,
      "y": 1,
      "z": -3,
      "name": "Soil_Clay_Smooth_Purple_Stairs",
      "rotation": 2
    },
    {
      "x": 1,
      "y": 0,
      "z": -2,
      "name": "Soil_Grass"
    },
    {
      "x": 1,
      "y": 1,
      "z": -2,
      "name": "Soil_Clay_Smooth_Purple_Stairs"
    },
    {
      "x": 1,
      "y": 4,
      "z": -2,
      "name": "Cloth_Block_Wool_Purple_Light_Stairs",
      "rotation": 8
    },
    {
      "x": 1,
      "y": 5,
      "z": -2,
      "name": "Cloth_Block_Wool_Purple_Light_Half",
      "rotation": 5
    },
    {
      "x": 1,
      "y": 6,
      "z": -2,
      "name": "Cloth_Block_Wool_Purple_Light_Half"
    },
    {
      "x": 1,
      "y": 0,
      "z": -1,
      "name": "Cloth_Block_Wool_Purple_Light"
    },
    {
      "x": 1,
      "y": 1,
      "z": -1,
      "name": "Empty"
    },
    {
      "x": 1,
      "y": 5,
      "z": -1,
      "name": "Cloth_Block_Wool_Purple_Light"
    },
    {
      "x": 1,
      "y": 0,
      "z": 0,
      "name": "Cloth_Block_Wool_Purple_Light"
    },
    {
      "x": 1,
      "y": 1,
      "z": 0,
      "name": "Empty"
    },
    {
      "x": 1,
      "y": 5,
      "z": 0,
      "name": "Cloth_Block_Wool_Purple_Light"
    },
    {
      "x": 1,
      "y": 0,
      "z": 1,
      "name": "Cloth_Block_Wool_Purple_Light"
    },
    {
      "x": 1,
      "y": 1,
      "z": 1,
      "name": "Empty"
    },
    {
      "x": 1,
      "y": 5,
      "z": 1,
      "name": "Cloth_Block_Wool_Purple_Light"
    },
    {
      "x": 1,
      "y": 0,
      "z": 2,
      "name": "Soil_Grass"
    },
    {
      "x": 1,
      "y": 1,
      "z": 2,
      "name": "Soil_Clay_Smooth_Purple_Stairs",
      "rotation": 2
    },
    {
      "x": 1,
      "y": 4,
      "z": 2,
      "name": "Cloth_Block_Wool_Purple_Light_Stairs",
      "rotation": 10
    },
    {
      "x": 1,
      "y": 5,
      "z": 2,
      "name": "Cloth_Block_Wool_Purple_Light_Half",
      "rotation": 5
    },
    {
      "x": 1,
      "y": 6,
      "z": 2,
      "name": "Cloth_Block_Wool_Purple_Light_Half"
    },
    {
      "x": 1,
      "y": 0,
      "z": 3,
      "name": "Soil_Grass"
    },
    {
      "x": 1,
      "y": 1,
      "z": 3,
      "name": "Soil_Clay_Smooth_Purple_Stairs"
    },
    {
      "x": 1,
      "y": 0,
      "z": 4,
      "name": "Soil_Clay_Smooth_Purple_Stairs"
    },
    {
      "x": 2,
      "y": 0,
      "z": -4,
      "name": "Cloth_Block_Wool_Purple_Light_Half",
      "rotation": 6
    },
    {
      "x": 2,
      "y": 0,
      "z": -3,
      "name": "Soil_Grass"
    },
    {
      "x": 2,
      "y": 1,
      "z": -3,
      "name": "Plant_Leaves_Fir_Lightpink",
      "support": 15
    },
    {
      "x": 2,
      "y": 0,
      "z": -2,
      "name": "Soil_Dirt"
    },
    {
      "x": 2,
      "y": 1,
      "z": -2,
      "name": "Cloth_Block_Wool_Purple_Light"
    },
    {
      "x": 2,
      "y": 2,
      "z": -2,
      "name": "Plant_Crop_Mushroom_Block_Brown_Branch",
      "support": 15
    },
    {
      "x": 2,
      "y": 3,
      "z": -2,
      "name": "Plant_Crop_Mushroom_Block_Brown_Branch",
      "support": 15
    },
    {
      "x": 2,
      "y": 4,
      "z": -2,
      "name": "Cloth_Block_Wool_Purple_Light"
    },
    {
      "x": 2,
      "y": 5,
      "z": -2,
      "name": "Deco_Lantern"
    },
    {
      "x": 2,
      "y": 6,
      "z": -2,
      "name": "Cloth_Block_Wool_Purple_Light"
    },
    {
      "x": 2,
      "y": 0,
      "z": -1,
      "name": "Soil_Grass"
    },
    {
      "x": 2,
      "y": 1,
      "z": -1,
      "name": "Soil_Clay_Smooth_Purple_Stairs",
      "rotation": 3
    },
    {
      "x": 2,
      "y": 4,
      "z": -1,
      "name": "Cloth_Block_Wool_Purple_Light_Stairs",
      "rotation": 11
    },
    {
      "x": 2,
      "y": 5,
      "z": -1,
      "name": "Cloth_Block_Wool_Purple_Light_Half",
      "rotation": 6
    },
    {
      "x": 2,
      "y": 6,
      "z": -1,
      "name": "Cloth_Block_Wool_Purple_Light_Half"
    },
    {
      "x": 2,
      "y": 0,
      "z": 0,
      "name": "Soil_Grass"
    },
    {
      "x": 2,
      "y": 1,
      "z": 0,
      "name": "Soil_Clay_Smooth_Purple_Stairs",
      "rotation": 1
    },
    {
      "x": 2,
      "y": 0,
      "z": 1,
      "name": "Soil_Grass"
    },
    {
      "x": 2,
      "y": 1,
      "z": 1,
      "name": "Soil_Clay_Smooth_Purple_Stairs",
      "rotation": 3
    },
    {
      "x": 2,
      "y": 4,
      "z": 1,
      "name": "Cloth_Block_Wool_Purple_Light_Stairs",
      "rotation": 11
    },
    {
      "x": 2,
      "y": 5,
      "z": 1,
      "name": "Cloth_Block_Wool_Purple_Light_Half",
      "rotation": 4
    },
    {
      "x": 2,
      "y": 6,
      "z": 1,
      "name": "Cloth_Block_Wool_Purple_Light_Half"
    },
    {
      "x": 2,
      "y": 0,
      "z": 2,
      "name": "Soil_Dirt"
    },
    {
      "x": 2,
      "y": 1,
      "z": 2,
      "name": "Cloth_Block_Wool_Purple_Light"
    },
    {
      "x": 2,
      "y": 2,
      "z": 2,
      "name": "Plant_Crop_Mushroom_Block_Brown_Branch",
      "support": 15
    },
    {
      "x": 2,
      "y": 3,
      "z": 2,
      "name": "Plant_Crop_Mushroom_Block_Brown_Branch",
      "support": 15
    },
    {
      "x": 2,
      "y": 4,
      "z": 2,
      "name": "Cloth_Block_Wool_Purple_Light"
    },
    {
      "x": 2,
      "y": 5,
      "z": 2,
      "name": "Deco_Lantern"
    },
    {
      "x": 2,
      "y": 6,
      "z": 2,
      "name": "Cloth_Block_Wool_Purple_Light"
    },
    {
      "x": 2,
      "y": 0,
      "z": 3,
      "name": "Soil_Grass"
    },
    {
      "x": 2,
      "y": 1,
      "z": 3,
      "name": "Plant_Leaves_Fir_Lightpink",
      "support": 15
    },
    {
      "x": 2,
      "y": 0,
      "z": 4,
      "name": "Cloth_Block_Wool_Purple_Light_Half",
      "rotation": 4
    },
    {
      "x": 3,
      "y": 0,
      "z": -4,
      "name": "Cloth_Block_Wool_Purple_Light_Half",
      "rotation": 6
    },
    {
      "x": 3,
      "y": 0,
      "z": -3,
      "name": "Soil_Grass"
    },
    {
      "x": 3,
      "y": 1,
      "z": -3,
      "name": "Plant_Leaves_Fir_Lightpink",
      "support": 15
    },
    {
      "x": 3,
      "y": 0,
      "z": -2,
      "name": "Soil_Grass"
    },
    {
      "x": 3,
      "y": 1,
      "z": -2,
      "name": "Plant_Leaves_Fir_Lightpink",
      "support": 15
    },
    {
      "x": 3,
      "y": 0,
      "z": -1,
      "name": "Soil_Grass"
    },
    {
      "x": 3,
      "y": 1,
      "z": -1,
      "name": "Soil_Clay_Smooth_Purple_Stairs",
      "rotation": 1
    },
    {
      "x": 3,
      "y": 0,
      "z": 0,
      "name": "Soil_Grass"
    },
    {
      "x": 3,
      "y": 1,
      "z": 0,
      "name": "Soil_Clay_Smooth_Purple_Stairs",
      "rotation": 1
    },
    {
      "x": 3,
      "y": 0,
      "z": 1,
      "name": "Soil_Grass"
    },
    {
      "x": 3,
      "y": 1,
      "z": 1,
      "name": "Soil_Clay_Smooth_Purple_Stairs",
      "rotation": 1
    },
    {
      "x": 3,
      "y": 0,
      "z": 2,
      "name": "Soil_Grass"
    },
    {
      "x": 3,
      "y": 1,
      "z": 2,
      "name": "Plant_Leaves_Fir_Lightpink",
      "support": 15
    },
    {
      "x": 3,
      "y": 0,
      "z": 3,
      "name": "Soil_Grass"
    },
    {
      "x": 3,
      "y": 1,
      "z": 3,
      "name": "Plant_Leaves_Fir_Lightpink",
      "support": 15
    },
    {
      "x": 3,
      "y": 0,
      "z": 4,
      "name": "Cloth_Block_Wool_Purple_Light_Half",
      "rotation": 4
    },
    {
      "x": 4,
      "y": 0,
      "z": -3,
      "name": "Cloth_Block_Wool_Purple_Light_Half",
      "rotation": 5
    },
    {
      "x": 4,
      "y": 0,
      "z": -2,
      "name": "Cloth_Block_Wool_Purple_Light_Half",
      "rotation": 5
    },
    {
      "x": 4,
      "y": 0,
      "z": -1,
      "name": "Soil_Clay_Smooth_Purple_Stairs",
      "rotation": 1
    },
    {
      "x": 4,
      "y": 0,
      "z": 0,
      "name": "Soil_Clay_Smooth_Purple_Stairs",
      "rotation": 1
    },
    {
      "x": 4,
      "y": 0,
      "z": 1,
      "name": "Soil_Clay_Smooth_Purple_Stairs",
      "rotation": 1
    },
    {
      "x": 4,
      "y": 0,
      "z": 2,
      "name": "Cloth_Block_Wool_Purple_Light_Half",
      "rotation": 5
    },
    {
      "x": 4,
      "y": 0,
      "z": 3,
      "name": "Cloth_Block_Wool_Purple_Light_Half",
      "rotation": 5
    }
  ],
  "fluids": [
    {
      "x": -4,
      "y": 0,
      "z": -3,
      "name": "Empty",
      "level": 0
    },
    {
      "x": -4,
      "y": 0,
      "z": -2,
      "name": "Empty",
      "level": 0
    },
    {
      "x": -4,
      "y": 0,
      "z": -1,
      "name": "Empty",
      "level": 0
    },
    {
      "x": -4,
      "y": 0,
      "z": 0,
      "name": "Empty",
      "level": 0
    },
    {
      "x": -4,
      "y": 0,
      "z": 1,
      "name": "Empty",
      "level": 0
    },
    {
      "x": -4,
      "y": 0,
      "z": 2,
      "name": "Empty",
      "level": 0
    },
    {
      "x": -4,
      "y": 0,
      "z": 3,
      "name": "Empty",
      "level": 0
    },
    {
      "x": -3,
      "y": 0,
      "z": -4,
      "name": "Empty",
      "level": 0
    },
    {
      "x": -3,
      "y": 0,
      "z": -3,
      "name": "Empty",
      "level": 0
    },
    {
      "x": -3,
      "y": 1,
      "z": -3,
      "name": "Empty",
      "level": 0
    },
    {
      "x": -3,
      "y": 0,
      "z": -2,
      "name": "Empty",
      "level": 0
    },
    {
      "x": -3,
      "y": 1,
      "z": -2,
      "name": "Empty",
      "level": 0
    },
    {
      "x": -3,
      "y": 0,
      "z": -1,
      "name": "Empty",
      "level": 0
    },
    {
      "x": -3,
      "y": 1,
      "z": -1,
      "name": "Empty",
      "level": 0
    },
    {
      "x": -3,
      "y": 0,
      "z": 0,
      "name": "Empty",
      "level": 0
    },
    {
      "x": -3,
      "y": 1,
      "z": 0,
      "name": "Empty",
      "level": 0
    },
    {
      "x": -3,
      "y": 0,
      "z": 1,
      "name": "Empty",
      "level": 0
    },
    {
      "x": -3,
      "y": 1,
      "z": 1,
      "name": "Empty",
      "level": 0
    },
    {
      "x": -3,
      "y": 0,
      "z": 2,
      "name": "Empty",
      "level": 0
    },
    {
      "x": -3,
      "y": 1,
      "z": 2,
      "name": "Empty",
      "level": 0
    },
    {
      "x": -3,
      "y": 0,
      "z": 3,
      "name": "Empty",
      "level": 0
    },
    {
      "x": -3,
      "y": 1,
      "z": 3,
      "name": "Empty",
      "level": 0
    },
    {
      "x": -3,
      "y": 0,
      "z": 4,
      "name": "Empty",
      "level": 0
    },
    {
      "x": -2,
      "y": 0,
      "z": -4,
      "name": "Empty",
      "level": 0
    },
    {
      "x": -2,
      "y": 0,
      "z": -3,
      "name": "Empty",
      "level": 0
    },
    {
      "x": -2,
      "y": 1,
      "z": -3,
      "name": "Empty",
      "level": 0
    },
    {
      "x": -2,
      "y": 0,
      "z": -2,
      "name": "Empty",
      "level": 0
    },
    {
      "x": -2,
      "y": 1,
      "z": -2,
      "name": "Empty",
      "level": 0
    },
    {
      "x": -2,
      "y": 2,
      "z": -2,
      "name": "Empty",
      "level": 0
    },
    {
      "x": -2,
      "y": 3,
      "z": -2,
      "name": "Empty",
      "level": 0
    },
    {
      "x": -2,
      "y": 4,
      "z": -2,
      "name": "Empty",
      "level": 0
    },
    {
      "x": -2,
      "y": 5,
      "z": -2,
      "name": "Empty",
      "level": 0
    },
    {
      "x": -2,
      "y": 6,
      "z": -2,
      "name": "Empty",
      "level": 0
    },
    {
      "x": -2,
      "y": 0,
      "z": -1,
      "name": "Empty",
      "level": 0
    },
    {
      "x": -2,
      "y": 1,
      "z": -1,
      "name": "Water_Source",
      "level": 1
    },
    {
      "x": -2,
      "y": 4,
      "z": -1,
      "name": "Empty",
      "level": 0
    },
    {
      "x": -2,
      "y": 5,
      "z": -1,
      "name": "Empty",
      "level": 0
    },
    {
      "x": -2,
      "y": 6,
      "z": -1,
      "name": "Empty",
      "level": 0
    },
    {
      "x": -2,
      "y": 0,
      "z": 0,
      "name": "Empty",
      "level": 0
    },
    {
      "x": -2,
      "y": 1,
      "z": 0,
      "name": "Empty",
      "level": 0
    },
    {
      "x": -2,
      "y": 0,
      "z": 1,
      "name": "Empty",
      "level": 0
    },
    {
      "x": -2,
      "y": 1,
      "z": 1,
      "name": "Water_Source",
      "level": 1
    },
    {
      "x": -2,
      "y": 4,
      "z": 1,
      "name": "Empty",
      "level": 0
    },
    {
      "x": -2,
      "y": 5,
      "z": 1,
      "name": "Empty",
      "level": 0
    },
    {
      "x": -2,
      "y": 6,
      "z": 1,
      "name": "Empty",
      "level": 0
    },
    {
      "x": -2,
      "y": 0,
      "z": 2,
      "name": "Empty",
      "level": 0
    },
    {
      "x": -2,
      "y": 1,
      "z": 2,
      "name": "Empty",
      "level": 0
    },
    {
      "x": -2,
      "y": 2,
      "z": 2,
      "name": "Empty",
      "level": 0
    },
    {
      "x": -2,
      "y": 3,
      "z": 2,
      "name": "Empty",
      "level": 0
    },
    {
      "x": -2,
      "y": 4,
      "z": 2,
      "name": "Empty",
      "level": 0
    },
    {
      "x": -2,
      "y": 5,
      "z": 2,
      "name": "Empty",
      "level": 0
    },
    {
      "x": -2,
      "y": 6,
      "z": 2,
      "name": "Empty",
      "level": 0
    },
    {
      "x": -2,
      "y": 0,
      "z": 3,
      "name": "Empty",
      "level": 0
    },
    {
      "x": -2,
      "y": 1,
      "z": 3,
      "name": "Empty",
      "level": 0
    },
    {
      "x": -2,
      "y": 0,
      "z": 4,
      "name": "Empty",
      "level": 0
    },
    {
      "x": -1,
      "y": 0,
      "z": -4,
      "name": "Empty",
      "level": 0
    },
    {
      "x": -1,
      "y": 0,
      "z": -3,
      "name": "Empty",
      "level": 0
    },
    {
      "x": -1,
      "y": 1,
      "z": -3,
      "name": "Empty",
      "level": 0
    },
    {
      "x": -1,
      "y": 0,
      "z": -2,
      "name": "Empty",
      "level": 0
    },
    {
      "x": -1,
      "y": 1,
      "z": -2,
      "name": "Water",
      "level": 7
    },
    {
      "x": -1,
      "y": 4,
      "z": -2,
      "name": "Empty",
      "level": 0
    },
    {
      "x": -1,
      "y": 5,
      "z": -2,
      "name": "Empty",
      "level": 0
    },
    {
      "x": -1,
      "y": 6,
      "z": -2,
      "name": "Empty",
      "level": 0
    },
    {
      "x": -1,
      "y": 0,
      "z": -1,
      "name": "Empty",
      "level": 0
    },
    {
      "x": -1,
      "y": 1,
      "z": -1,
      "name": "Water_Source",
      "level": 1
    },
    {
      "x": -1,
      "y": 5,
      "z": -1,
      "name": "Empty",
      "level": 0
    },
    {
      "x": -1,
      "y": 0,
      "z": 0,
      "name": "Empty",
      "level": 0
    },
    {
      "x": -1,
      "y": 1,
      "z": 0,
      "name": "Water_Source",
      "level": 1
    },
    {
      "x": -1,
      "y": 5,
      "z": 0,
      "name": "Empty",
      "level": 0
    },
    {
      "x": -1,
      "y": 0,
      "z": 1,
      "name": "Empty",
      "level": 0
    },
    {
      "x": -1,
      "y": 1,
      "z": 1,
      "name": "Water_Source",
      "level": 1
    },
    {
      "x": -1,
      "y": 5,
      "z": 1,
      "name": "Empty",
      "level": 0
    },
    {
      "x": -1,
      "y": 0,
      "z": 2,
      "name": "Empty",
      "level": 0
    },
    {
      "x": -1,
      "y": 1,
      "z": 2,
      "name": "Water_Source",
      "level": 1
    },
    {
      "x": -1,
      "y": 4,
      "z": 2,
      "name": "Empty",
      "level": 0
    },
    {
      "x": -1,
      "y": 5,
      "z": 2,
      "name": "Empty",
      "level": 0
    },
    {
      "x": -1,
      "y": 6,
      "z": 2,
      "name": "Empty",
      "level": 0
    },
    {
      "x": -1,
      "y": 0,
      "z": 3,
      "name": "Empty",
      "level": 0
    },
    {
      "x": -1,
      "y": 1,
      "z": 3,
      "name": "Empty",
      "level": 0
    },
    {
      "x": -1,
      "y": 0,
      "z": 4,
      "name": "Empty",
      "level": 0
    },
    {
      "x": 0,
      "y": 0,
      "z": -4,
      "name": "Empty",
      "level": 0
    },
    {
      "x": 0,
      "y": 0,
      "z": -3,
      "name": "Empty",
      "level": 0
    },
    {
      "x": 0,
      "y": 1,
      "z": -3,
      "name": "Empty",
      "level": 0
    },
    {
      "x": 0,
      "y": 0,
      "z": -2,
      "name": "Empty",
      "level": 0
    },
    {
      "x": 0,
      "y": 1,
      "z": -2,
      "name": "Empty",
      "level": 0
    },
    {
      "x": 0,
      "y": 0,
      "z": -1,
      "name": "Empty",
      "level": 0
    },
    {
      "x": 0,
      "y": 1,
      "z": -1,
      "name": "Water_Source",
      "level": 1
    },
    {
      "x": 0,
      "y": 5,
      "z": -1,
      "name": "Empty",
      "level": 0
    },
    {
      "x": 0,
      "y": 0,
      "z": 0,
      "name": "Empty",
      "level": 0
    },
    {
      "x": 0,
      "y": 1,
      "z": 0,
      "name": "Water_Source",
      "level": 1
    },
    {
      "x": 0,
      "y": 2,
      "z": 0,
      "name": "Empty",
      "level": 0
    },
    {
      "x": 0,
      "y": 0,
      "z": 1,
      "name": "Empty",
      "level": 0
    },
    {
      "x": 0,
      "y": 1,
      "z": 1,
      "name": "Water_Source",
      "level": 1
    },
    {
      "x": 0,
      "y": 5,
      "z": 1,
      "name": "Empty",
      "level": 0
    },
    {
      "x": 0,
      "y": 0,
      "z": 2,
      "name": "Empty",
      "level": 0
    },
    {
      "x": 0,
      "y": 1,
      "z": 2,
      "name": "Empty",
      "level": 0
    },
    {
      "x": 0,
      "y": 0,
      "z": 3,
      "name": "Empty",
      "level": 0
    },
    {
      "x": 0,
      "y": 1,
      "z": 3,
      "name": "Empty",
      "level": 0
    },
    {
      "x": 0,
      "y": 0,
      "z": 4,
      "name": "Empty",
      "level": 0
    },
    {
      "x": 1,
      "y": 0,
      "z": -4,
      "name": "Empty",
      "level": 0
    },
    {
      "x": 1,
      "y": 0,
      "z": -3,
      "name": "Empty",
      "level": 0
    },
    {
      "x": 1,
      "y": 1,
      "z": -3,
      "name": "Empty",
      "level": 0
    },
    {
      "x": 1,
      "y": 0,
      "z": -2,
      "name": "Empty",
      "level": 0
    },
    {
      "x": 1,
      "y": 1,
      "z": -2,
      "name": "Water",
      "level": 7
    },
    {
      "x": 1,
      "y": 4,
      "z": -2,
      "name": "Empty",
      "level": 0
    },
    {
      "x": 1,
      "y": 5,
      "z": -2,
      "name": "Empty",
      "level": 0
    },
    {
      "x": 1,
      "y": 6,
      "z": -2,
      "name": "Empty",
      "level": 0
    },
    {
      "x": 1,
      "y": 0,
      "z": -1,
      "name": "Empty",
      "level": 0
    },
    {
      "x": 1,
      "y": 1,
      "z": -1,
      "name": "Water_Source",
      "level": 1
    },
    {
      "x": 1,
      "y": 5,
      "z": -1,
      "name": "Empty",
      "level": 0
    },
    {
      "x": 1,
      "y": 0,
      "z": 0,
      "name": "Empty",
      "level": 0
    },
    {
      "x": 1,
      "y": 1,
      "z": 0,
      "name": "Water_Source",
      "level": 1
    },
    {
      "x": 1,
      "y": 5,
      "z": 0,
      "name": "Empty",
      "level": 0
    },
    {
      "x": 1,
      "y": 0,
      "z": 1,
      "name": "Empty",
      "level": 0
    },
    {
      "x": 1,
      "y": 1,
      "z": 1,
      "name": "Water_Source",
      "level": 1
    },
    {
      "x": 1,
      "y": 5,
      "z": 1,
      "name": "Empty",
      "level": 0
    },
    {
      "x": 1,
      "y": 0,
      "z": 2,
      "name": "Empty",
      "level": 0
    },
    {
      "x": 1,
      "y": 1,
      "z": 2,
      "name": "Water_Source",
      "level": 1
    },
    {
      "x": 1,
      "y": 4,
      "z": 2,
      "name": "Empty",
      "level": 0
    },
    {
      "x": 1,
      "y": 5,
      "z": 2,
      "name": "Empty",
      "level": 0
    },
    {
      "x": 1,
      "y": 6,
      "z": 2,
      "name": "Empty",
      "level": 0
    },
    {
      "x": 1,
      "y": 0,
      "z": 3,
      "name": "Empty",
      "level": 0
    },
    {
      "x": 1,
      "y": 1,
      "z": 3,
      "name": "Empty",
      "level": 0
    },
    {
      "x": 1,
      "y": 0,
      "z": 4,
      "name": "Empty",
      "level": 0
    },
    {
      "x": 2,
      "y": 0,
      "z": -4,
      "name": "Empty",
      "level": 0
    },
    {
      "x": 2,
      "y": 0,
      "z": -3,
      "name": "Empty",
      "level": 0
    },
    {
      "x": 2,
      "y": 1,
      "z": -3,
      "name": "Empty",
      "level": 0
    },
    {
      "x": 2,
      "y": 0,
      "z": -2,
      "name": "Empty",
      "level": 0
    },
    {
      "x": 2,
      "y": 1,
      "z": -2,
      "name": "Empty",
      "level": 0
    },
    {
      "x": 2,
      "y": 2,
      "z": -2,
      "name": "Empty",
      "level": 0
    },
    {
      "x": 2,
      "y": 3,
      "z": -2,
      "name": "Empty",
      "level": 0
    },
    {
      "x": 2,
      "y": 4,
      "z": -2,
      "name": "Empty",
      "level": 0
    },
    {
      "x": 2,
      "y": 5,
      "z": -2,
      "name": "Empty",
      "level": 0
    },
    {
      "x": 2,
      "y": 6,
      "z": -2,
      "name": "Empty",
      "level": 0
    },
    {
      "x": 2,
      "y": 0,
      "z": -1,
      "name": "Empty",
      "level": 0
    },
    {
      "x": 2,
      "y": 1,
      "z": -1,
      "name": "Water_Source",
      "level": 1
    },
    {
      "x": 2,
      "y": 4,
      "z": -1,
      "name": "Empty",
      "level": 0
    },
    {
      "x": 2,
      "y": 5,
      "z": -1,
      "name": "Empty",
      "level": 0
    },
    {
      "x": 2,
      "y": 6,
      "z": -1,
      "name": "Empty",
      "level": 0
    },
    {
      "x": 2,
      "y": 0,
      "z": 0,
      "name": "Empty",
      "level": 0
    },
    {
      "x": 2,
      "y": 1,
      "z": 0,
      "name": "Empty",
      "level": 0
    },
    {
      "x": 2,
      "y": 0,
      "z": 1,
      "name": "Empty",
      "level": 0
    },
    {
      "x": 2,
      "y": 1,
      "z": 1,
      "name": "Water_Source",
      "level": 1
    },
    {
      "x": 2,
      "y": 4,
      "z": 1,
      "name": "Empty",
      "level": 0
    },
    {
      "x": 2,
      "y": 5,
      "z": 1,
      "name": "Empty",
      "level": 0
    },
    {
      "x": 2,
      "y": 6,
      "z": 1,
      "name": "Empty",
      "level": 0
    },
    {
      "x": 2,
      "y": 0,
      "z": 2,
      "name": "Empty",
      "level": 0
    },
    {
      "x": 2,
      "y": 1,
      "z": 2,
      "name": "Empty",
      "level": 0
    },
    {
      "x": 2,
      "y": 2,
      "z": 2,
      "name": "Empty",
      "level": 0
    },
    {
      "x": 2,
      "y": 3,
      "z": 2,
      "name": "Empty",
      "level": 0
    },
    {
      "x": 2,
      "y": 4,
      "z": 2,
      "name": "Empty",
      "level": 0
    },
    {
      "x": 2,
      "y": 5,
      "z": 2,
      "name": "Empty",
      "level": 0
    },
    {
      "x": 2,
      "y": 6,
      "z": 2,
      "name": "Empty",
      "level": 0
    },
    {
      "x": 2,
      "y": 0,
      "z": 3,
      "name": "Empty",
      "level": 0
    },
    {
      "x": 2,
      "y": 1,
      "z": 3,
      "name": "Empty",
      "level": 0
    },
    {
      "x": 2,
      "y": 0,
      "z": 4,
      "name": "Empty",
      "level": 0
    },
    {
      "x": 3,
      "y": 0,
      "z": -4,
      "name": "Empty",
      "level": 0
    },
    {
      "x": 3,
      "y": 0,
      "z": -3,
      "name": "Empty",
      "level": 0
    },
    {
      "x": 3,
      "y": 1,
      "z": -3,
      "name": "Empty",
      "level": 0
    },
    {
      "x": 3,
      "y": 0,
      "z": -2,
      "name": "Empty",
      "level": 0
    },
    {
      "x": 3,
      "y": 1,
      "z": -2,
      "name": "Empty",
      "level": 0
    },
    {
      "x": 3,
      "y": 0,
      "z": -1,
      "name": "Empty",
      "level": 0
    },
    {
      "x": 3,
      "y": 1,
      "z": -1,
      "name": "Empty",
      "level": 0
    },
    {
      "x": 3,
      "y": 0,
      "z": 0,
      "name": "Empty",
      "level": 0
    },
    {
      "x": 3,
      "y": 1,
      "z": 0,
      "name": "Empty",
      "level": 0
    },
    {
      "x": 3,
      "y": 0,
      "z": 1,
      "name": "Empty",
      "level": 0
    },
    {
      "x": 3,
      "y": 1,
      "z": 1,
      "name": "Empty",
      "level": 0
    },
    {
      "x": 3,
      "y": 0,
      "z": 2,
      "name": "Empty",
      "level": 0
    },
    {
      "x": 3,
      "y": 1,
      "z": 2,
      "name": "Empty",
      "level": 0
    },
    {
      "x": 3,
      "y": 0,
      "z": 3,
      "name": "Empty",
      "level": 0
    },
    {
      "x": 3,
      "y": 1,
      "z": 3,
      "name": "Empty",
      "level": 0
    },
    {
      "x": 3,
      "y": 0,
      "z": 4,
      "name": "Empty",
      "level": 0
    },
    {
      "x": 4,
      "y": 0,
      "z": -3,
      "name": "Empty",
      "level": 0
    },
    {
      "x": 4,
      "y": 0,
      "z": -2,
      "name": "Empty",
      "level": 0
    },
    {
      "x": 4,
      "y": 0,
      "z": -1,
      "name": "Empty",
      "level": 0
    },
    {
      "x": 4,
      "y": 0,
      "z": 0,
      "name": "Empty",
      "level": 0
    },
    {
      "x": 4,
      "y": 0,
      "z": 1,
      "name": "Empty",
      "level": 0
    },
    {
      "x": 4,
      "y": 0,
      "z": 2,
      "name": "Empty",
      "level": 0
    },
    {
      "x": 4,
      "y": 0,
      "z": 3,
      "name": "Empty",
      "level": 0
    }
  ]
}