{
  "version": 8,
  "blockIdVersion": 11,
  "anchorX": 0,
  "anchorY": 0,
  "anchorZ": 0,
  "blocks": [
    {
      "x": -4,
      "y": 0,
      "z": -3,
      "name": "Plant_Crop_Mushroom_Block_Brown_Branch",
      "support": 15
    },
    {
      "x": -4,
      "y": 1,
      "z": -3,
      "name": "Plant_Crop_Mushroom_Block_Brown_Branch",
      "support": 15
    },
    {
      "x": -4,
      "y": 2,
      "z": -3,
      "name": "Cloth_Block_Wool_Purple_Light"
    },
    {
      "x": -4,
      "y": 3,
      "z": -3,
      "name": "Deco_Lantern"
    },
    {
      "x": -4,
      "y": 4,
      "z": -3,
      "name": "Cloth_Block_Wool_Purple_Light_Half"
    },
    {
      "x": -4,
      "y": 2,
      "z": -2,
      "name": "Cloth_Block_Wool_Purple_Light_Stairs",
      "rotation": 9
    },
    {
      "x": -4,
      "y": 3,
      "z": -2,
      "name": "Cloth_Block_Wool_Purple_Light_Half",
      "rotation": 6
    },
    {
      "x": -4,
      "y": 4,
      "z": -2,
      "name": "Cloth_Block_Wool_Purple_Light_Stairs",
      "rotation": 3
    },
    {
      "x": -4,
      "y": 2,
      "z": -1,
      "name": "Cloth_Block_Wool_Purple_Light_Half",
      "rotation": 7
    },
    {
      "x": -4,
      "y": 4,
      "z": -1,
      "name": "Cloth_Block_Wool_Purple_Light_Half",
      "rotation": 7
    },
    {
      "x": -4,
      "y": 2,
      "z": 0,
      "name": "Cloth_Block_Wool_Purple_Light_Half",
      "rotation": 7
    },
    {
      "x": -4,
      "y": 4,
      "z": 0,
      "name": "Cloth_Block_Wool_Purple_Light_Half",
      "rotation": 7
    },
    {
      "x": -4,
      "y": 2,
      "z": 1,
      "name": "Cloth_Block_Wool_Purple_Light_Half",
      "rotation": 7
    },
    {
      "x": -4,
      "y": 4,
      "z": 1,
      "name": "Cloth_Block_Wool_Purple_Light_Half",
      "rotation": 7
    },
    {
      "x": -4,
      "y": 2,
      "z": 2,
      "name": "Cloth_Block_Wool_Purple_Light_Half",
      "rotation": 7
    },
    {
      "x": -4,
      "y": 4,
      "z": 2,
      "name": "Cloth_Block_Wool_Purple_Light_Half",
      "rotation": 7
    },
    {
      "x": -4,
      "y": 2,
      "z": 3,
      "name": "Cloth_Block_Wool_Purple_Light_Stairs",
      "rotation": 9
    },
    {
      "x": -4,
      "y": 3,
      "z": 3,
      "name": "Cloth_Block_Wool_Purple_Light_Half",
      "rotation": 4
    },
    {
      "x": -4,
      "y": 4,
      "z": 3,
      "name": "Cloth_Block_Wool_Purple_Light_Stairs",
      "rotation": 3
    },
    {
      "x": -4,
      "y": 0,
      "z": 4,
      "name": "Plant_Crop_Mushroom_Block_Brown_Branch",
      "support": 15
    },
    {
      "x": -4,
      "y": 1,
      "z": 4,
      "name": "Plant_Crop_Mushroom_Block_Brown_Branch",
      "support": 15
    },
    {
      "x": -4,
      "y": 2,
      "z": 4,
      "name": "Cloth_Block_Wool_Purple_Light"
    },
    {
      "x": -4,
      "y": 3,
      "z": 4,
      "name": "Deco_Lantern"
    },
    {
      "x": -4,
      "y": 4,
      "z": 4,
      "name": "Cloth_Block_Wool_Purple_Light_Half"
    },
    {
      "x": -3,
      "y": 2,
      "z": -3,
      "name": "Cloth_Block_Wool_Purple_Light_Stairs",
      "rotation": 8
    },
    {
      "x": -3,
      "y": 3,
      "z": -3,
      "name": "Cloth_Block_Wool_Purple_Light_Half",
      "rotation": 7
    },
    {
      "x": -3,
      "y": 4,
      "z": -3,
      "name": "Cloth_Block_Wool_Purple_Light_Stairs",
      "rotation": 2
    },
    {
      "x": -3,
      "y": 0,
      "z": -2,
      "name": "Soil_Clay_Smooth_Purple"
    },
    {
      "x": -3,
      "y": 1,
      "z": -2,
      "name": "Soil_Clay_Smooth_Purple"
    },
    {
      "x": -3,
      "y": 2,
      "z": -2,
      "name": "Soil_Clay_Smooth_Purple"
    },
    {
      "x": -3,
      "y": 3,
      "z": -2,
      "name": "*Soil_Clay_Smooth_Purple_Stairs_State_Definitions_Corner_Left",
      "rotation": 2
    },
    {
      "x": -3,
      "y": 4,
      "z": -2,
      "name": "Soil_Clay_Smooth_Purple"
    },
    {
      "x": -3,
      "y": 0,
      "z": -1,
      "name": "Soil_Clay_Smooth_Purple"
    },
    {
      "x": -3,
      "y": 1,
      "z": -1,
      "name": "Soil_Clay_Smooth_Purple"
    },
    {
      "x": -3,
      "y": 2,
      "z": -1,
      "name": "Soil_Clay_Smooth_Purple"
    },
    {
      "x": -3,
      "y": 3,
      "z": -1,
      "name": "Soil_Clay_Smooth_Purple_Stairs",
      "rotation": 3
    },
    {
      "x": -3,
      "y": 4,
      "z": -1,
      "name": "Soil_Clay_Smooth_Purple"
    },
    {
      "x": -3,
      "y": 0,
      "z": 0,
      "name": "Soil_Clay_Smooth_Purple"
    },
    {
      "x": -3,
      "y": 1,
      "z": 0,
      "name": "Soil_Clay_Smooth_Purple"
    },
    {
      "x": -3,
      "y": 2,
      "z": 0,
      "name": "Soil_Clay_Smooth_Purple"
    },
    {
      "x": -3,
      "y": 3,
      "z": 0,
      "name": "Soil_Clay_Smooth_Purple_Stairs",
      "rotation": 3
    },
    {
      "x": -3,
      "y": 4,
      "z": 0,
      "name": "Soil_Clay_Smooth_Purple"
    },
    {
      "x": -3,
      "y": 0,
      "z": 1,
      "name": "Soil_Clay_Smooth_Purple"
    },
    {
      "x": -3,
      "y": 1,
      "z": 1,
      "name": "Soil_Clay_Smooth_Purple"
    },
    {
      "x": -3,
      "y": 2,
      "z": 1,
      "name": "Soil_Clay_Smooth_Purple"
    },
    {
      "x": -3,
      "y": 3,
      "z": 1,
      "name": "Soil_Clay_Smooth_Purple_Stairs",
      "rotation": 3
    },
    {
      "x": -3,
      "y": 4,
      "z": 1,
      "name": "Soil_Clay_Smooth_Purple"
    },
    {
      "x": -3,
      "y": 0,
      "z": 2,
      "name": "Soil_Clay_Smooth_Purple"
    },
    {
      "x": -3,
      "y": 1,
      "z": 2,
      "name": "Soil_Clay_Smooth_Purple"
    },
    {
      "x": -3,
      "y": 2,
      "z": 2,
      "name": "Soil_Clay_Smooth_Purple"
    },
    {
      "x": -3,
      "y": 3,
      "z": 2,
      "name": "Soil_Clay_Smooth_Purple_Stairs",
      "rotation": 3
    },
    {
      "x": -3,
      "y": 4,
      "z": 2,
      "name": "Soil_Clay_Smooth_Purple"
    },
    {
      "x": -3,
      "y": 0,
      "z": 3,
      "name": "Soil_Clay_Smooth_Purple"
    },
    {
      "x": -3,
      "y": 1,
      "z": 3,
      "name": "Soil_Clay_Smooth_Purple"
    },
    {
      "x": -3,
      "y": 2,
      "z": 3,
      "name": "Soil_Clay_Smooth_Purple"
    },
    {
      "x": -3,
      "y": 3,
      "z": 3,
      "name": "Soil_Clay_Smooth_Purple_Stairs",
      "rotation": 3
    },
    {
      "x": -3,
      "y": 4,
      "z": 3,
      "name": "Soil_Clay_Smooth_Purple"
    },
    {
      "x": -3,
      "y": 2,
      "z": 4,
      "name": "Cloth_Block_Wool_Purple_Light_Stairs",
      "rotation": 10
    },
    {
      "x": -3,
      "y": 3,
      "z": 4,
      "name": "Cloth_Block_Wool_Purple_Light_Half",
      "rotation": 7
    },
    {
      "x": -3,
      "y": 4,
      "z": 4,
      "name": "Cloth_Block_Wool_Purple_Light_Stairs"
    },
    {
      "x": -2,
      "y": 2,
      "z": -3,
      "name": "Cloth_Block_Wool_Purple_Light_Half",
      "rotation": 6
    },
    {
      "x": -2,
      "y": 4,
      "z": -3,
      "name": "Cloth_Block_Wool_Purple_Light_Half",
      "rotation": 6
    },
    {
      "x": -2,
      "y": 0,
      "z": -2,
      "name": "*Furniture_Village_Door_State_Definitions_CloseDoorIn",
      "rotation": 2
    },
    {
      "x": -2,
      "y": 1,
      "z": -2,
      "name": "*Furniture_Village_Door_State_Definitions_CloseDoorIn",
      "filler": 1024,
      "rotation": 2
    },
    {
      "x": -2,
      "y": 2,
      "z": -2,
      "name": "Soil_Clay_Smooth_Purple"
    },
    {
      "x": -2,
      "y": 3,
      "z": -2,
      "name": "Soil_Clay_Smooth_Purple_Stairs",
      "rotation": 2
    },
    {
      "x": -2,
      "y": 4,
      "z": -2,
      "name": "Soil_Clay_Smooth_Purple"
    },
    {
      "x": -2,
      "y": 2,
      "z": -1,
      "name": "Plant_Moss_Block_Green_Dark",
      "support": 15
    },
    {
      "x": -2,
      "y": 3,
      "z": -1,
      "name": "Ingredient_Hay"
    },
    {
      "x": -2,
      "y": 4,
      "z": -1,
      "name": "Plant_Crop_Pumpkin_Item"
    },
    {
      "x": -2,
      "y": 5,
      "z": -1,
      "name": "Cloth_Block_Wool_Purple_Light_Half"
    },
    {
      "x": -2,
      "y": 1,
      "z": 0,
      "name": "Lobby_Wall_Poster01",
      "rotation": 1
    },
    {
      "x": -2,
      "y": 2,
      "z": 0,
      "name": "Plant_Moss_Block_Green_Dark",
      "support": 15
    },
    {
      "x": -2,
      "y": 3,
      "z": 0,
      "name": "Plant_Vine",
      "support": 15,
      "rotation": 1
    },
    {
      "x": -2,
      "y": 4,
      "z": 0,
      "name": "Plant_Vine",
      "support": 15,
      "rotation": 1
    },
    {
      "x": -2,
      "y": 5,
      "z": 0,
      "name": "Cloth_Block_Wool_Purple_Light_Half"
    },
    {
      "x": -2,
      "y": 0,
      "z": 1,
      "name": "Cloth_Roof_White_Flat"
    },
    {
      "x": -2,
      "y": 2,
      "z": 1,
      "name": "Cloth_Block_Wool_Purple_Light"
    },
    {
      "x": -2,
      "y": 3,
      "z": 1,
      "name": "Bench_Arcane",
      "components": {
        "Components": {
          "BenchBlock": {
            "TierLevel": 1,
            "UpgradeItems": []
          },
          "PlacedByInteraction": {
            "WhoPlacedUuid": {
              "$binary": "usHuoxbhTZaFKBfBlh8H7w==",
              "$type": "04"
            }
          }
        }
      },
      "rotation": 1
    },
    {
      "x": -2,
      "y": 4,
      "z": 1,
      "name": "Bench_Arcane",
      "filler": 1024,
      "rotation": 1
    },
    {
      "x": -2,
      "y": 5,
      "z": 1,
      "name": "Cloth_Block_Wool_Purple_Light_Half"
    },
    {
      "x": -2,
      "y": 0,
      "z": 2,
      "name": "Furniture_Village_Wardrobe",
      "rotation": 2
    },
    {
      "x": -2,
      "y": 1,
      "z": 2,
      "name": "Furniture_Village_Wardrobe",
      "filler": 1024,
      "rotation": 2
    },
    {
      "x": -2,
      "y": 2,
      "z": 2,
      "name": "Cloth_Block_Wool_Purple_Light"
    },
    {
      "x": -2,
      "y": 3,
      "z": 2,
      "name": "Bench_Arcane",
      "filler": 32,
      "rotation": 1
    },
    {
      "x": -2,
      "y": 4,
      "z": 2,
      "name": "Bench_Arcane",
      "filler": 1056,
      "rotation": 1
    },
    {
      "x": -2,
      "y": 5,
      "z": 2,
      "name": "Cloth_Block_Wool_Purple_Light_Half"
    },
    {
      "x": -2,
      "y": 0,
      "z": 3,
      "name": "Soil_Clay_Smooth_Purple"
    },
    {
      "x": -2,
      "y": 1,
      "z": 3,
      "name": "Soil_Clay_Smooth_Purple"
    },
    {
      "x": -2,
      "y": 2,
      "z": 3,
      "name": "Soil_Clay_Smooth_Purple"
    },
    {
      "x": -2,
      "y": 3,
      "z": 3,
      "name": "Soil_Clay_Smooth_Purple"
    },
    {
      "x": -2,
      "y": 4,
      "z": 3,
      "name": "Soil_Clay_Smooth_Purple"
    },
    {
      "x": -2,
      "y": 2,
      "z": 4,
      "name": "Cloth_Block_Wool_Purple_Light_Half",
      "rotation": 4
    },
    {
      "x": -2,
      "y": 4,
      "z": 4,
      "name": "Cloth_Block_Wool_Purple_Light_Half",
      "rotation": 4
    },
    {
      "x": -1,
      "y": 2,
      "z": -3,
      "name": "Cloth_Block_Wool_Purple_Light_Half",
      "rotation": 6
    },
    {
      "x": -1,
      "y": 4,
      "z": -3,
      "name": "Cloth_Block_Wool_Purple_Light_Half",
      "rotation": 6
    },
    {
      "x": -1,
      "y": 0,
      "z": -2,
      "name": "Soil_Clay_Smooth_Purple"
    },
    {
      "x": -1,
      "y": 1,
      "z": -2,
      "name": "Soil_Clay_Smooth_Purple"
    },
    {
      "x": -1,
      "y": 2,
      "z": -2,
      "name": "Soil_Clay_Smooth_Purple"
    },
    {
      "x": -1,
      "y": 3,
      "z": -2,
      "name": "Soil_Clay_Smooth_Purple_Stairs",
      "rotation": 2
    },
    {
      "x": -1,
      "y": 4,
      "z": -2,
      "name": "Soil_Clay_Smooth_Purple"
    },
    {
      "x": -1,
      "y": 2,
      "z": -1,
      "name": "Plant_Vine",
      "support": 15,
      "rotation": 1
    },
    {
      "x": -1,
      "y": 3,
      "z": -1,
      "name": "Plant_Vine",
      "support": 15,
      "rotation": 1
    },
    {
      "x": -1,
      "y": 5,
      "z": -1,
      "name": "Cloth_Block_Wool_Purple_Light_Half"
    },
    {
      "x": -1,
      "y": 2,
      "z": 0,
      "name": "Plant_Vine",
      "support": 15,
      "rotation": 1
    },
    {
      "x": -1,
      "y": 5,
      "z": 0,
      "name": "Cloth_Block_Wool_Purple_Light_Half"
    },
    {
      "x": -1,
      "y": 0,
      "z": 1,
      "name": "Cloth_Roof_White_Flat"
    },
    {
      "x": -1,
      "y": 2,
      "z": 1,
      "name": "Cloth_Block_Wool_Purple_Light_Half",
      "rotation": 8
    },
    {
      "x": -1,
      "y": 3,
      "z": 1,
      "name": "Deco_Map",
      "rotation": 1
    },
    {
      "x": -1,
      "y": 5,
      "z": 1,
      "name": "Cloth_Block_Wool_Purple_Light_Half"
    },
    {
      "x": -1,
      "y": 0,
      "z": 2,
      "name": "Furniture_Village_Wardrobe",
      "filler": 1,
      "rotation": 2
    },
    {
      "x": -1,
      "y": 1,
      "z": 2,
      "name": "Furniture_Village_Wardrobe",
      "filler": 1025,
      "rotation": 2
    },
    {
      "x": -1,
      "y": 2,
      "z": 2,
      "name": "Cloth_Block_Wool_Purple_Light_Stairs",
      "rotation": 8
    },
    {
      "x": -1,
      "y": 5,
      "z": 2,
      "name": "Cloth_Block_Wool_Purple_Light_Half"
    },
    {
      "x": -1,
      "y": 0,
      "z": 3,
      "name": "Soil_Clay_Smooth_Purple"
    },
    {
      "x": -1,
      "y": 1,
      "z": 3,
      "name": "Soil_Clay_Smooth_Purple"
    },
    {
      "x": -1,
      "y": 2,
      "z": 3,
      "name": "Cloth_Block_Wool_Purple_Light"
    },
    {
      "x": -1,
      "y": 3,
      "z": 3,
      "name": "Deco_Book_Pile_Small",
      "rotation": 1
    },
    {
      "x": -1,
      "y": 5,
      "z": 3,
      "name": "Cloth_Block_Wool_Purple_Light_Half"
    },
    {
      "x": -1,
      "y": 2,
      "z": 4,
      "name": "Cloth_Block_Wool_Purple_Light_Half",
      "rotation": 4
    },
    {
      "x": -1,
      "y": 3,
      "z": 4,
      "name": "Cloth_Block_Wool_Purple_Light_Stairs",
      "rotation": 1
    },
    {
      "x": -1,
      "y": 4,
      "z": 4,
      "name": "Cloth_Block_Wool_Purple_Light_Stairs",
      "rotation": 11
    },
    {
      "x": 0,
      "y": 2,
      "z": -3,
      "name": "Cloth_Block_Wool_Purple_Light_Half",
      "rotation": 6
    },
    {
      "x": 0,
      "y": 4,
      "z": -3,
      "name": "Cloth_Block_Wool_Purple_Light_Half",
      "rotation": 6
    },
    {
      "x": 0,
      "y": 0,
      "z": -2,
      "name": "Furniture_Crude_Window"
    },
    {
      "x": 0,
      "y": 1,
      "z": -2,
      "name": "Furniture_Crude_Window"
    },
    {
      "x": 0,
      "y": 2,
      "z": -2,
      "name": "Soil_Clay_Smooth_Purple"
    },
    {
      "x": 0,
      "y": 3,
      "z": -2,
      "name": "Soil_Clay_Smooth_Purple_Stairs",
      "rotation": 2
    },
    {
      "x": 0,
      "y": 4,
      "z": -2,
      "name": "Soil_Clay_Smooth_Purple"
    },
    {
      "x": 0,
      "y": 5,
      "z": -1,
      "name": "Cloth_Block_Wool_Purple_Light_Half"
    },
    {
      "x": 0,
      "y": 5,
      "z": 0,
      "name": "Cloth_Block_Wool_Purple_Light_Half"
    },
    {
      "x": 0,
      "y": 0,
      "z": 1,
      "name": "Furniture_Tavern_Planter"
    },
    {
      "x": 0,
      "y": 1,
      "z": 1,
      "name": "Plant_Cactus_Flower"
    },
    {
      "x": 0,
      "y": 2,
      "z": 1,
      "name": "Cloth_Block_Wool_Purple_Light_Half",
      "rotation": 8
    },
    {
      "x": 0,
      "y": 5,
      "z": 1,
      "name": "Cloth_Block_Wool_Purple_Light_Half"
    },
    {
      "x": 0,
      "y": 0,
      "z": 2,
      "name": "Cloth_Block_Wool_Purple_Light"
    },
    {
      "x": 0,
      "y": 1,
      "z": 2,
      "name": "Cloth_Block_Wool_Purple_Light"
    },
    {
      "x": 0,
      "y": 2,
      "z": 2,
      "name": "Cloth_Block_Wool_Purple_Light"
    },
    {
      "x": 0,
      "y": 5,
      "z": 2,
      "name": "Cloth_Block_Wool_Purple_Light_Half"
    },
    {
      "x": 0,
      "y": 0,
      "z": 3,
      "name": "Soil_Clay_Smooth_Purple"
    },
    {
      "x": 0,
      "y": 1,
      "z": 3,
      "name": "Soil_Clay_Smooth_Purple"
    },
    {
      "x": 0,
      "y": 2,
      "z": 3,
      "name": "Cloth_Block_Wool_Purple_Light"
    },
    {
      "x": 0,
      "y": 3,
      "z": 3,
      "name": "Furniture_Temple_Wind_Candle"
    },
    {
      "x": 0,
      "y": 5,
      "z": 3,
      "name": "Cloth_Block_Wool_Purple_Light_Half"
    },
    {
      "x": 0,
      "y": 2,
      "z": 4,
      "name": "Cloth_Block_Wool_Purple_Light_Half",
      "rotation": 4
    },
    {
      "x": 0,
      "y": 3,
      "z": 4,
      "name": "Cloth_Block_Wool_Purple_Light_Half"
    },
    {
      "x": 0,
      "y": 4,
      "z": 4,
      "name": "Cloth_Block_Wool_Purple_Light_Half",
      "rotation": 8
    },
    {
      "x": 1,
      "y": 2,
      "z": -3,
      "name": "Cloth_Block_Wool_Purple_Light_Half",
      "rotation": 6
    },
    {
      "x": 1,
      "y": 4,
      "z": -3,
      "name": "Cloth_Block_Wool_Purple_Light_Half",
      "rotation": 6
    },
    {
      "x": 1,
      "y": 0,
      "z": -2,
      "name": "Soil_Clay_Smooth_Purple"
    },
    {
      "x": 1,
      "y": 1,
      "z": -2,
      "name": "Soil_Clay_Smooth_Purple"
    },
    {
      "x": 1,
      "y": 2,
      "z": -2,
      "name": "Soil_Clay_Smooth_Purple"
    },
    {
      "x": 1,
      "y": 3,
      "z": -2,
      "name": "Soil_Clay_Smooth_Purple_Stairs",
      "rotation": 2
    },
    {
      "x": 1,
      "y": 4,
      "z": -2,
      "name": "Soil_Clay_Smooth_Purple"
    },
    {
      "x": 1,
      "y": 0,
      "z": -1,
      "name": "Cloth_Block_Wool_Purple_Light_Stairs",
      "rotation": 3
    },
    {
      "x": 1,
      "y": 5,
      "z": -1,
      "name": "Cloth_Block_Wool_Purple_Light_Half"
    },
    {
      "x": 1,
      "y": 5,
      "z": 0,
      "name": "Cloth_Block_Wool_Purple_Light_Half"
    },
    {
      "x": 1,
      "y": 2,
      "z": 1,
      "name": "Cloth_Block_Wool_Purple_Light_Half",
      "rotation": 8
    },
    {
      "x": 1,
      "y": 5,
      "z": 1,
      "name": "Cloth_Block_Wool_Purple_Light_Half"
    },
    {
      "x": 1,
      "y": 0,
      "z": 2,
      "name": "Furniture_Village_Chair",
      "rotation": 1
    },
    {
      "x": 1,
      "y": 1,
      "z": 2,
      "name": "Furniture_Village_Chair",
      "filler": 1024,
      "rotation": 1
    },
    {
      "x": 1,
      "y": 2,
      "z": 2,
      "name": "Cloth_Block_Wool_Purple_Light_Stairs",
      "rotation": 8
    },
    {
      "x": 1,
      "y": 5,
      "z": 2,
      "name": "Cloth_Block_Wool_Purple_Light_Half"
    },
    {
      "x": 1,
      "y": 0,
      "z": 3,
      "name": "Soil_Clay_Smooth_Purple"
    },
    {
      "x": 1,
      "y": 1,
      "z": 3,
      "name": "Soil_Clay_Smooth_Purple"
    },
    {
      "x": 1,
      "y": 2,
      "z": 3,
      "name": "Cloth_Block_Wool_Purple_Light"
    },
    {
      "x": 1,
      "y": 3,
      "z": 3,
      "name": "Deco_Book_Pile_Large",
      "rotation": 2
    },
    {
      "x": 1,
      "y": 5,
      "z": 3,
      "name": "Cloth_Block_Wool_Purple_Light_Half"
    },
    {
      "x": 1,
      "y": 2,
      "z": 4,
      "name": "Cloth_Block_Wool_Purple_Light_Half",
      "rotation": 4
    },
    {
      "x": 1,
      "y": 3,
      "z": 4,
      "name": "Cloth_Block_Wool_Purple_Light_Stairs",
      "rotation": 3
    },
    {
      "x": 1,
      "y": 4,
      "z": 4,
      "name": "Cloth_Block_Wool_Purple_Light_Stairs",
      "rotation": 9
    },
    {
      "x": 2,
      "y": 2,
      "z": -3,
      "name": "Cloth_Block_Wool_Purple_Light_Half",
      "rotation": 6
    },
    {
      "x": 2,
      "y": 4,
      "z": -3,
      "name": "Cloth_Block_Wool_Purple_Light_Half",
      "rotation": 6
    },
    {
      "x": 2,
      "y": 0,
      "z": -2,
      "name": "Soil_Clay_Smooth_Purple"
    },
    {
      "x": 2,
      "y": 1,
      "z": -2,
      "name": "Soil_Clay_Smooth_Purple"
    },
    {
      "x": 2,
      "y": 2,
      "z": -2,
      "name": "Soil_Clay_Smooth_Purple"
    },
    {
      "x": 2,
      "y": 3,
      "z": -2,
      "name": "Soil_Clay_Smooth_Purple_Stairs",
      "rotation": 2
    },
    {
      "x": 2,
      "y": 4,
      "z": -2,
      "name": "Soil_Clay_Smooth_Purple"
    },
    {
      "x": 2,
      "y": 0,
      "z": -1,
      "name": "Cloth_Block_Wool_Purple_Light"
    },
    {
      "x": 2,
      "y": 5,
      "z": -1,
      "name": "Cloth_Block_Wool_Purple_Light_Half"
    },
    {
      "x": 2,
      "y": 0,
      "z": 0,
      "name": "Furniture_Village_Chest_Small",
      "components": {
        "Components": {
          "PlacedByInteraction": {
            "WhoPlacedUuid": {
              "$binary": "usHuoxbhTZaFKBfBlh8H7w==",
              "$type": "04"
            }
          },
          "ItemContainerBlock": {
            "ItemContainer": {
              "Capacity": 18,
              "Items": {}
            },
            "Capacity": 18
          }
        }
      },
      "rotation": 3
    },
    {
      "x": 2,
      "y": 1,
      "z": 0,
      "name": "Cloth_Block_Wool_Purple_Light_Stairs",
      "rotation": 2
    },
    {
      "x": 2,
      "y": 5,
      "z": 0,
      "name": "Cloth_Block_Wool_Purple_Light_Half"
    },
    {
      "x": 2,
      "y": 0,
      "z": 1,
      "name": "Cloth_Block_Wool_Purple_Light"
    },
    {
      "x": 2,
      "y": 1,
      "z": 1,
      "name": "Deco_Lantern"
    },
    {
      "x": 2,
      "y": 2,
      "z": 1,
      "name": "Cloth_Block_Wool_Purple_Light_Stairs",
      "rotation": 2
    },
    {
      "x": 2,
      "y": 5,
      "z": 1,
      "name": "Cloth_Block_Wool_Purple_Light_Half"
    },
    {
      "x": 2,
      "y": 0,
      "z": 2,
      "name": "Cloth_Block_Wool_Purple_Light_Stairs",
      "rotation": 9
    },
    {
      "x": 2,
      "y": 1,
      "z": 2,
      "name": "Deco_Book_Pile_Small",
      "rotation": 2
    },
    {
      "x": 2,
      "y": 2,
      "z": 2,
      "name": "Cloth_Block_Wool_Purple_Light"
    },
    {
      "x": 2,
      "y": 3,
      "z": 2,
      "name": "Plant_Moss_Rug_Pink",
      "support": 15
    },
    {
      "x": 2,
      "y": 5,
      "z": 2,
      "name": "Cloth_Block_Wool_Purple_Light_Half"
    },
    {
      "x": 2,
      "y": 0,
      "z": 3,
      "name": "Soil_Clay_Smooth_Purple"
    },
    {
      "x": 2,
      "y": 1,
      "z": 3,
      "name": "Soil_Clay_Smooth_Purple"
    },
    {
      "x": 2,
      "y": 2,
      "z": 3,
      "name": "Soil_Clay_Smooth_Purple"
    },
    {
      "x": 2,
      "y": 3,
      "z": 3,
      "name": "Soil_Clay_Smooth_Purple"
    },
    {
      "x": 2,
      "y": 4,
      "z": 3,
      "name": "Soil_Clay_Smooth_Purple"
    },
    {
      "x": 2,
      "y": 2,
      "z": 4,
      "name": "Cloth_Block_Wool_Purple_Light_Half",
      "rotation": 4
    },
    {
      "x": 2,
      "y": 4,
      "z": 4,
      "name": "Cloth_Block_Wool_Purple_Light_Half",
      "rotation": 4
    },
    {
      "x": 3,
      "y": 2,
      "z": -3,
      "name": "Cloth_Block_Wool_Purple_Light_Stairs",
      "rotation": 8
    },
    {
      "x": 3,
      "y": 3,
      "z": -3,
      "name": "Cloth_Block_Wool_Purple_Light_Half",
      "rotation": 5
    },
    {
      "x": 3,
      "y": 4,
      "z": -3,
      "name": "Cloth_Block_Wool_Purple_Light_Stairs",
      "rotation": 2
    },
    {
      "x": 3,
      "y": 0,
      "z": -2,
      "name": "Soil_Clay_Smooth_Purple"
    },
    {
      "x": 3,
      "y": 1,
      "z": -2,
      "name": "Soil_Clay_Smooth_Purple"
    },
    {
      "x": 3,
      "y": 2,
      "z": -2,
      "name": "Soil_Clay_Smooth_Purple"
    },
    {
      "x": 3,
      "y": 3,
      "z": -2,
      "name": "*Soil_Clay_Smooth_Purple_Stairs_State_Definitions_Corner_Left",
      "rotation": 1
    },
    {
      "x": 3,
      "y": 4,
      "z": -2,
      "name": "Soil_Clay_Smooth_Purple"
    },
    {
      "x": 3,
      "y": 0,
      "z": -1,
      "name": "Soil_Clay_Smooth_Purple"
    },
    {
      "x": 3,
      "y": 1,
      "z": -1,
      "name": "Soil_Clay_Smooth_Purple"
    },
    {
      "x": 3,
      "y": 2,
      "z": -1,
      "name": "Soil_Clay_Smooth_Purple"
    },
    {
      "x": 3,
      "y": 3,
      "z": -1,
      "name": "Soil_Clay_Smooth_Purple_Stairs",
      "rotation": 1
    },
    {
      "x": 3,
      "y": 4,
      "z": -1,
      "name": "Soil_Clay_Smooth_Purple"
    },
    {
      "x": 3,
      "y": 0,
      "z": 0,
      "name": "Soil_Clay_Smooth_Purple"
    },
    {
      "x": 3,
      "y": 1,
      "z": 0,
      "name": "Soil_Clay_Smooth_Purple"
    },
    {
      "x": 3,
      "y": 2,
      "z": 0,
      "name": "Soil_Clay_Smooth_Purple"
    },
    {
      "x": 3,
      "y": 3,
      "z": 0,
      "name": "Soil_Clay_Smooth_Purple_Stairs",
      "rotation": 1
    },
    {
      "x": 3,
      "y": 4,
      "z": 0,
      "name": "Soil_Clay_Smooth_Purple"
    },
    {
      "x": 3,
      "y": 0,
      "z": 1,
      "name": "Soil_Clay_Smooth_Purple"
    },
    {
      "x": 3,
      "y": 1,
      "z": 1,
      "name": "Soil_Clay_Smooth_Purple"
    },
    {
      "x": 3,
      "y": 2,
      "z": 1,
      "name": "Soil_Clay_Smooth_Purple"
    },
    {
      "x": 3,
      "y": 3,
      "z": 1,
      "name": "Soil_Clay_Smooth_Purple_Stairs",
      "rotation": 1
    },
    {
      "x": 3,
      "y": 4,
      "z": 1,
      "name": "Soil_Clay_Smooth_Purple"
    },
    {
      "x": 3,
      "y": 0,
      "z": 2,
      "name": "Soil_Clay_Smooth_Purple"
    },
    {
      "x": 3,
      "y": 1,
      "z": 2,
      "name": "Furniture_Crude_Window",
      "rotation": 1
    },
    {
      "x": 3,
      "y": 2,
      "z": 2,
      "name": "Soil_Clay_Smooth_Purple"
    },
    {
      "x": 3,
      "y": 3,
      "z": 2,
      "name": "Soil_Clay_Smooth_Purple_Stairs",
      "rotation": 1
    },
    {
      "x": 3,
      "y": 4,
      "z": 2,
      "name": "Soil_Clay_Smooth_Purple"
    },
    {
      "x": 3,
      "y": 0,
      "z": 3,
      "name": "Soil_Clay_Smooth_Purple"
    },
    {
      "x": 3,
      "y": 1,
      "z": 3,
      "name": "Soil_Clay_Smooth_Purple"
    },
    {
      "x": 3,
      "y": 2,
      "z": 3,
      "name": "Soil_Clay_Smooth_Purple"
    },
    {
      "x": 3,
      "y": 3,
      "z": 3,
      "name": "*Soil_Clay_Smooth_Purple_Stairs_State_Definitions_Corner_Left"
    },
    {
      "x": 3,
      "y": 4,
      "z": 3,
      "name": "Soil_Clay_Smooth_Purple"
    },
    {
      "x": 3,
      "y": 2,
      "z": 4,
      "name": "Cloth_Block_Wool_Purple_Light_Stairs",
      "rotation": 10
    },
    {
      "x": 3,
      "y": 3,
      "z": 4,
      "name": "Cloth_Block_Wool_Purple_Light_Half",
      "rotation": 5
    },
    {
      "x": 3,
      "y": 4,
      "z": 4,
      "name": "Cloth_Block_Wool_Purple_Light_Stairs"
    },
    {
      "x": 4,
      "y": 0,
      "z": -3,
      "name": "Plant_Crop_Mushroom_Block_Brown_Branch",
      "support": 15
    },
    {
      "x": 4,
      "y": 1,
      "z": -3,
      "name": "Plant_Crop_Mushroom_Block_Brown_Branch",
      "support": 15
    },
    {
      "x": 4,
      "y": 2,
      "z": -3,
      "name": "Cloth_Block_Wool_Purple_Light"
    },
    {
      "x": 4,
      "y": 3,
      "z": -3,
      "name": "Deco_Lantern"
    },
    {
      "x": 4,
      "y": 4,
      "z": -3,
      "name": "Cloth_Block_Wool_Purple_Light_Half"
    },
    {
      "x": 4,
      "y": 2,
      "z": -2,
      "name": "Cloth_Block_Wool_Purple_Light_Stairs",
      "rotation": 11
    },
    {
      "x": 4,
      "y": 3,
      "z": -2,
      "name": "Cloth_Block_Wool_Purple_Light_Half",
      "rotation": 6
    },
    {
      "x": 4,
      "y": 4,
      "z": -2,
      "name": "Cloth_Block_Wool_Purple_Light_Stairs",
      "rotation": 1
    },
    {
      "x": 4,
      "y": 2,
      "z": -1,
      "name": "Cloth_Block_Wool_Purple_Light_Half",
      "rotation": 5
    },
    {
      "x": 4,
      "y": 4,
      "z": -1,
      "name": "Cloth_Block_Wool_Purple_Light_Half",
      "rotation": 5
    },
    {
      "x": 4,
      "y": 2,
      "z": 0,
      "name": "Cloth_Block_Wool_Purple_Light_Half",
      "rotation": 5
    },
    {
      "x": 4,
      "y": 4,
      "z": 0,
      "name": "Cloth_Block_Wool_Purple_Light_Half",
      "rotation": 5
    },
    {
      "x": 4,
      "y": 2,
      "z": 1,
      "name": "Cloth_Block_Wool_Purple_Light_Half",
      "rotation": 5
    },
    {
      "x": 4,
      "y": 4,
      "z": 1,
      "name": "Cloth_Block_Wool_Purple_Light_Half",
      "rotation": 5
    },
    {
      "x": 4,
      "y": 2,
      "z": 2,
      "name": "Cloth_Block_Wool_Purple_Light_Half",
      "rotation": 5
    },
    {
      "x": 4,
      "y": 4,
      "z": 2,
      "name": "Cloth_Block_Wool_Purple_Light_Half",
      "rotation": 5
    },
    {
      "x": 4,
      "y": 2,
      "z": 3,
      "name": "Cloth_Block_Wool_Purple_Light_Stairs",
      "rotation": 11
    },
    {
      "x": 4,
      "y": 3,
      "z": 3,
      "name": "Cloth_Block_Wool_Purple_Light_Half",
      "rotation": 4
    },
    {
      "x": 4,
      "y": 4,
      "z": 3,
      "name": "Cloth_Block_Wool_Purple_Light_Stairs",
      "rotation": 1
    },
    {
      "x": 4,
      "y": 0,
      "z": 4,
      "name": "Plant_Crop_Mushroom_Block_Brown_Branch",
      "support": 15
    },
    {
      "x": 4,
      "y": 1,
      "z": 4,
      "name": "Plant_Crop_Mushroom_Block_Brown_Branch",
      "support": 15
    },
    {
      "x": 4,
      "y": 2,
      "z": 4,
      "name": "Cloth_Block_Wool_Purple_Light"
    },
    {
      "x": 4,
      "y": 3,
      "z": 4,
      "name": "Deco_Lantern"
    },
    {
      "x": 4,
      "y": 4,
      "z": 4,
      "name": "Cloth_Block_Wool_Purple_Light_Half"
    }
  ],
  "fluids": [
    {
      "x": -4,
      "y": 0,
      "z": -3,
      "name": "Empty",
      "level": 0
    },
    {
      "x": -4,
      "y": 1,
      "z": -3,
      "name": "Empty",
      "level": 0
    },
    {
      "x": -4,
      "y": 2,
      "z": -3,
      "name": "Empty",
      "level": 0
    },
    {
      "x": -4,
      "y": 3,
      "z": -3,
      "name": "Empty",
      "level": 0
    },
    {
      "x": -4,
      "y": 4,
      "z": -3,
      "name": "Empty",
      "level": 0
    },
    {
      "x": -4,
      "y": 2,
      "z": -2,
      "name": "Empty",
      "level": 0
    },
    {
      "x": -4,
      "y": 3,
      "z": -2,
      "name": "Empty",
      "level": 0
    },
    {
      "x": -4,
      "y": 4,
      "z": -2,
      "name": "Empty",
      "level": 0
    },
    {
      "x": -4,
      "y": 2,
      "z": -1,
      "name": "Empty",
      "level": 0
    },
    {
      "x": -4,
      "y": 4,
      "z": -1,
      "name": "Empty",
      "level": 0
    },
    {
      "x": -4,
      "y": 2,
      "z": 0,
      "name": "Empty",
      "level": 0
    },
    {
      "x": -4,
      "y": 4,
      "z": 0,
      "name": "Empty",
      "level": 0
    },
    {
      "x": -4,
      "y": 2,
      "z": 1,
      "name": "Empty",
      "level": 0
    },
    {
      "x": -4,
      "y": 4,
      "z": 1,
      "name": "Empty",
      "level": 0
    },
    {
      "x": -4,
      "y": 2,
      "z": 2,
      "name": "Empty",
      "level": 0
    },
    {
      "x": -4,
      "y": 4,
      "z": 2,
      "name": "Empty",
      "level": 0
    },
    {
      "x": -4,
      "y": 2,
      "z": 3,
      "name": "Empty",
      "level": 0
    },
    {
      "x": -4,
      "y": 3,
      "z": 3,
      "name": "Empty",
      "level": 0
    },
    {
      "x": -4,
      "y": 4,
      "z": 3,
      "name": "Empty",
      "level": 0
    },
    {
      "x": -4,
      "y": 0,
      "z": 4,
      "name": "Empty",
      "level": 0
    },
    {
      "x": -4,
      "y": 1,
      "z": 4,
      "name": "Empty",
      "level": 0
    },
    {
      "x": -4,
      "y": 2,
      "z": 4,
      "name": "Empty",
      "level": 0
    },
    {
      "x": -4,
      "y": 3,
      "z": 4,
      "name": "Empty",
      "level": 0
    },
    {
      "x": -4,
      "y": 4,
      "z": 4,
      "name": "Empty",
      "level": 0
    },
    {
      "x": -3,
      "y": 2,
      "z": -3,
      "name": "Empty",
      "level": 0
    },
    {
      "x": -3,
      "y": 3,
      "z": -3,
      "name": "Empty",
      "level": 0
    },
    {
      "x": -3,
      "y": 4,
      "z": -3,
      "name": "Empty",
      "level": 0
    },
    {
      "x": -3,
      "y": 0,
      "z": -2,
      "name": "Empty",
      "level": 0
    },
    {
      "x": -3,
      "y": 1,
      "z": -2,
      "name": "Empty",
      "level": 0
    },
    {
      "x": -3,
      "y": 2,
      "z": -2,
      "name": "Empty",
      "level": 0
    },
    {
      "x": -3,
      "y": 3,
      "z": -2,
      "name": "Empty",
      "level": 0
    },
    {
      "x": -3,
      "y": 4,
      "z": -2,
      "name": "Empty",
      "level": 0
    },
    {
      "x": -3,
      "y": 0,
      "z": -1,
      "name": "Empty",
      "level": 0
    },
    {
      "x": -3,
      "y": 1,
      "z": -1,
      "name": "Empty",
      "level": 0
    },
    {
      "x": -3,
      "y": 2,
      "z": -1,
      "name": "Empty",
      "level": 0
    },
    {
      "x": -3,
      "y": 3,
      "z": -1,
      "name": "Empty",
      "level": 0
    },
    {
      "x": -3,
      "y": 4,
      "z": -1,
      "name": "Empty",
      "level": 0
    },
    {
      "x": -3,
      "y": 0,
      "z": 0,
      "name": "Empty",
      "level": 0
    },
    {
      "x": -3,
      "y": 1,
      "z": 0,
      "name": "Empty",
      "level": 0
    },
    {
      "x": -3,
      "y": 2,
      "z": 0,
      "name": "Empty",
      "level": 0
    },
    {
      "x": -3,
      "y": 3,
      "z": 0,
      "name": "Empty",
      "level": 0
    },
    {
      "x": -3,
      "y": 4,
      "z": 0,
      "name": "Empty",
      "level": 0
    },
    {
      "x": -3,
      "y": 0,
      "z": 1,
      "name": "Empty",
      "level": 0
    },
    {
      "x": -3,
      "y": 1,
      "z": 1,
      "name": "Empty",
      "level": 0
    },
    {
      "x": -3,
      "y": 2,
      "z": 1,
      "name": "Empty",
      "level": 0
    },
    {
      "x": -3,
      "y": 3,
      "z": 1,
      "name": "Empty",
      "level": 0
    },
    {
      "x": -3,
      "y": 4,
      "z": 1,
      "name": "Empty",
      "level": 0
    },
    {
      "x": -3,
      "y": 0,
      "z": 2,
      "name": "Empty",
      "level": 0
    },
    {
      "x": -3,
      "y": 1,
      "z": 2,
      "name": "Empty",
      "level": 0
    },
    {
      "x": -3,
      "y": 2,
      "z": 2,
      "name": "Empty",
      "level": 0
    },
    {
      "x": -3,
      "y": 3,
      "z": 2,
      "name": "Empty",
      "level": 0
    },
    {
      "x": -3,
      "y": 4,
      "z": 2,
      "name": "Empty",
      "level": 0
    },
    {
      "x": -3,
      "y": 0,
      "z": 3,
      "name": "Empty",
      "level": 0
    },
    {
      "x": -3,
      "y": 1,
      "z": 3,
      "name": "Empty",
      "level": 0
    },
    {
      "x": -3,
      "y": 2,
      "z": 3,
      "name": "Empty",
      "level": 0
    },
    {
      "x": -3,
      "y": 3,
      "z": 3,
      "name": "Empty",
      "level": 0
    },
    {
      "x": -3,
      "y": 4,
      "z": 3,
      "name": "Empty",
      "level": 0
    },
    {
      "x": -3,
      "y": 2,
      "z": 4,
      "name": "Empty",
      "level": 0
    },
    {
      "x": -3,
      "y": 3,
      "z": 4,
      "name": "Empty",
      "level": 0
    },
    {
      "x": -3,
      "y": 4,
      "z": 4,
      "name": "Empty",
      "level": 0
    },
    {
      "x": -2,
      "y": 2,
      "z": -3,
      "name": "Empty",
      "level": 0
    },
    {
      "x": -2,
      "y": 4,
      "z": -3,
      "name": "Empty",
      "level": 0
    },
    {
      "x": -2,
      "y": 0,
      "z": -2,
      "name": "Empty",
      "level": 0
    },
    {
      "x": -2,
      "y": 1,
      "z": -2,
      "name": "Empty",
      "level": 0
    },
    {
      "x": -2,
      "y": 2,
      "z": -2,
      "name": "Empty",
      "level": 0
    },
    {
      "x": -2,
      "y": 3,
      "z": -2,
      "name": "Empty",
      "level": 0
    },
    {
      "x": -2,
      "y": 4,
      "z": -2,
      "name": "Empty",
      "level": 0
    },
    {
      "x": -2,
      "y": 2,
      "z": -1,
      "name": "Empty",
      "level": 0
    },
    {
      "x": -2,
      "y": 3,
      "z": -1,
      "name": "Empty",
      "level": 0
    },
    {
      "x": -2,
      "y": 4,
      "z": -1,
      "name": "Empty",
      "level": 0
    },
    {
      "x": -2,
      "y": 5,
      "z": -1,
      "name": "Empty",
      "level": 0
    },
    {
      "x": -2,
      "y": 1,
      "z": 0,
      "name": "Empty",
      "level": 0
    },
    {
      "x": -2,
      "y": 2,
      "z": 0,
      "name": "Empty",
      "level": 0
    },
    {
      "x": -2,
      "y": 3,
      "z": 0,
      "name": "Empty",
      "level": 0
    },
    {
      "x": -2,
      "y": 4,
      "z": 0,
      "name": "Empty",
      "level": 0
    },
    {
      "x": -2,
      "y": 5,
      "z": 0,
      "name": "Empty",
      "level": 0
    },
    {
      "x": -2,
      "y": 0,
      "z": 1,
      "name": "Empty",
      "level": 0
    },
    {
      "x": -2,
      "y": 2,
      "z": 1,
      "name": "Empty",
      "level": 0
    },
    {
      "x": -2,
      "y": 3,
      "z": 1,
      "name": "Empty",
      "level": 0
    },
    {
      "x": -2,
      "y": 4,
      "z": 1,
      "name": "Empty",
      "level": 0
    },
    {
      "x": -2,
      "y": 5,
      "z": 1,
      "name": "Empty",
      "level": 0
    },
    {
      "x": -2,
      "y": 0,
      "z": 2,
      "name": "Empty",
      "level": 0
    },
    {
      "x": -2,
      "y": 1,
      "z": 2,
      "name": "Empty",
      "level": 0
    },
    {
      "x": -2,
      "y": 2,
      "z": 2,
      "name": "Empty",
      "level": 0
    },
    {
      "x": -2,
      "y": 3,
      "z": 2,
      "name": "Empty",
      "level": 0
    },
    {
      "x": -2,
      "y": 4,
      "z": 2,
      "name": "Empty",
      "level": 0
    },
    {
      "x": -2,
      "y": 5,
      "z": 2,
      "name": "Empty",
      "level": 0
    },
    {
      "x": -2,
      "y": 0,
      "z": 3,
      "name": "Empty",
      "level": 0
    },
    {
      "x": -2,
      "y": 1,
      "z": 3,
      "name": "Empty",
      "level": 0
    },
    {
      "x": -2,
      "y": 2,
      "z": 3,
      "name": "Empty",
      "level": 0
    },
    {
      "x": -2,
      "y": 3,
      "z": 3,
      "name": "Empty",
      "level": 0
    },
    {
      "x": -2,
      "y": 4,
      "z": 3,
      "name": "Empty",
      "level": 0
    },
    {
      "x": -2,
      "y": 2,
      "z": 4,
      "name": "Empty",
      "level": 0
    },
    {
      "x": -2,
      "y": 4,
      "z": 4,
      "name": "Empty",
      "level": 0
    },
    {
      "x": -1,
      "y": 2,
      "z": -3,
      "name": "Empty",
      "level": 0
    },
    {
      "x": -1,
      "y": 4,
      "z": -3,
      "name": "Empty",
      "level": 0
    },
    {
      "x": -1,
      "y": 0,
      "z": -2,
      "name": "Empty",
      "level": 0
    },
    {
      "x": -1,
      "y": 1,
      "z": -2,
      "name": "Empty",
      "level": 0
    },
    {
      "x": -1,
      "y": 2,
      "z": -2,
      "name": "Empty",
      "level": 0
    },
    {
      "x": -1,
      "y": 3,
      "z": -2,
      "name": "Empty",
      "level": 0
    },
    {
      "x": -1,
      "y": 4,
      "z": -2,
      "name": "Empty",
      "level": 0
    },
    {
      "x": -1,
      "y": 2,
      "z": -1,
      "name": "Empty",
      "level": 0
    },
    {
      "x": -1,
      "y": 3,
      "z": -1,
      "name": "Empty",
      "level": 0
    },
    {
      "x": -1,
      "y": 5,
      "z": -1,
      "name": "Empty",
      "level": 0
    },
    {
      "x": -1,
      "y": 2,
      "z": 0,
      "name": "Empty",
      "level": 0
    },
    {
      "x": -1,
      "y": 5,
      "z": 0,
      "name": "Empty",
      "level": 0
    },
    {
      "x": -1,
      "y": 0,
      "z": 1,
      "name": "Empty",
      "level": 0
    },
    {
      "x": -1,
      "y": 2,
      "z": 1,
      "name": "Empty",
      "level": 0
    },
    {
      "x": -1,
      "y": 3,
      "z": 1,
      "name": "Empty",
      "level": 0
    },
    {
      "x": -1,
      "y": 5,
      "z": 1,
      "name": "Empty",
      "level": 0
    },
    {
      "x": -1,
      "y": 0,
      "z": 2,
      "name": "Empty",
      "level": 0
    },
    {
      "x": -1,
      "y": 1,
      "z": 2,
      "name": "Empty",
      "level": 0
    },
    {
      "x": -1,
      "y": 2,
      "z": 2,
      "name": "Empty",
      "level": 0
    },
    {
      "x": -1,
      "y": 5,
      "z": 2,
      "name": "Empty",
      "level": 0
    },
    {
      "x": -1,
      "y": 0,
      "z": 3,
      "name": "Empty",
      "level": 0
    },
    {
      "x": -1,
      "y": 1,
      "z": 3,
      "name": "Empty",
      "level": 0
    },
    {
      "x": -1,
      "y": 2,
      "z": 3,
      "name": "Empty",
      "level": 0
    },
    {
      "x": -1,
      "y": 3,
      "z": 3,
      "name": "Empty",
      "level": 0
    },
    {
      "x": -1,
      "y": 5,
      "z": 3,
      "name": "Empty",
      "level": 0
    },
    {
      "x": -1,
      "y": 2,
      "z": 4,
      "name": "Empty",
      "level": 0
    },
    {
      "x": -1,
      "y": 3,
      "z": 4,
      "name": "Empty",
      "level": 0
    },
    {
      "x": -1,
      "y": 4,
      "z": 4,
      "name": "Empty",
      "level": 0
    },
    {
      "x": 0,
      "y": 2,
      "z": -3,
      "name": "Empty",
      "level": 0
    },
    {
      "x": 0,
      "y": 4,
      "z": -3,
      "name": "Empty",
      "level": 0
    },
    {
      "x": 0,
      "y": 0,
      "z": -2,
      "name": "Empty",
      "level": 0
    },
    {
      "x": 0,
      "y": 1,
      "z": -2,
      "name": "Empty",
      "level": 0
    },
    {
      "x": 0,
      "y": 2,
      "z": -2,
      "name": "Empty",
      "level": 0
    },
    {
      "x": 0,
      "y": 3,
      "z": -2,
      "name": "Empty",
      "level": 0
    },
    {
      "x": 0,
      "y": 4,
      "z": -2,
      "name": "Empty",
      "level": 0
    },
    {
      "x": 0,
      "y": 5,
      "z": -1,
      "name": "Empty",
      "level": 0
    },
    {
      "x": 0,
      "y": 5,
      "z": 0,
      "name": "Empty",
      "level": 0
    },
    {
      "x": 0,
      "y": 0,
      "z": 1,
      "name": "Empty",
      "level": 0
    },
    {
      "x": 0,
      "y": 1,
      "z": 1,
      "name": "Empty",
      "level": 0
    },
    {
      "x": 0,
      "y": 2,
      "z": 1,
      "name": "Empty",
      "level": 0
    },
    {
      "x": 0,
      "y": 5,
      "z": 1,
      "name": "Empty",
      "level": 0
    },
    {
      "x": 0,
      "y": 0,
      "z": 2,
      "name": "Empty",
      "level": 0
    },
    {
      "x": 0,
      "y": 1,
      "z": 2,
      "name": "Empty",
      "level": 0
    },
    {
      "x": 0,
      "y": 2,
      "z": 2,
      "name": "Empty",
      "level": 0
    },
    {
      "x": 0,
      "y": 5,
      "z": 2,
      "name": "Empty",
      "level": 0
    },
    {
      "x": 0,
      "y": 0,
      "z": 3,
      "name": "Empty",
      "level": 0
    },
    {
      "x": 0,
      "y": 1,
      "z": 3,
      "name": "Empty",
      "level": 0
    },
    {
      "x": 0,
      "y": 2,
      "z": 3,
      "name": "Empty",
      "level": 0
    },
    {
      "x": 0,
      "y": 3,
      "z": 3,
      "name": "Empty",
      "level": 0
    },
    {
      "x": 0,
      "y": 5,
      "z": 3,
      "name": "Empty",
      "level": 0
    },
    {
      "x": 0,
      "y": 2,
      "z": 4,
      "name": "Empty",
      "level": 0
    },
    {
      "x": 0,
      "y": 3,
      "z": 4,
      "name": "Empty",
      "level": 0
    },
    {
      "x": 0,
      "y": 4,
      "z": 4,
      "name": "Empty",
      "level": 0
    },
    {
      "x": 1,
      "y": 2,
      "z": -3,
      "name": "Empty",
      "level": 0
    },
    {
      "x": 1,
      "y": 4,
      "z": -3,
      "name": "Empty",
      "level": 0
    },
    {
      "x": 1,
      "y": 0,
      "z": -2,
      "name": "Empty",
      "level": 0
    },
    {
      "x": 1,
      "y": 1,
      "z": -2,
      "name": "Empty",
      "level": 0
    },
    {
      "x": 1,
      "y": 2,
      "z": -2,
      "name": "Empty",
      "level": 0
    },
    {
      "x": 1,
      "y": 3,
      "z": -2,
      "name": "Empty",
      "level": 0
    },
    {
      "x": 1,
      "y": 4,
      "z": -2,
      "name": "Empty",
      "level": 0
    },
    {
      "x": 1,
      "y": 0,
      "z": -1,
      "name": "Empty",
      "level": 0
    },
    {
      "x": 1,
      "y": 5,
      "z": -1,
      "name": "Empty",
      "level": 0
    },
    {
      "x": 1,
      "y": 5,
      "z": 0,
      "name": "Empty",
      "level": 0
    },
    {
      "x": 1,
      "y": 2,
      "z": 1,
      "name": "Empty",
      "level": 0
    },
    {
      "x": 1,
      "y": 5,
      "z": 1,
      "name": "Empty",
      "level": 0
    },
    {
      "x": 1,
      "y": 0,
      "z": 2,
      "name": "Empty",
      "level": 0
    },
    {
      "x": 1,
      "y": 1,
      "z": 2,
      "name": "Empty",
      "level": 0
    },
    {
      "x": 1,
      "y": 2,
      "z": 2,
      "name": "Empty",
      "level": 0
    },
    {
      "x": 1,
      "y": 5,
      "z": 2,
      "name": "Empty",
      "level": 0
    },
    {
      "x": 1,
      "y": 0,
      "z": 3,
      "name": "Empty",
      "level": 0
    },
    {
      "x": 1,
      "y": 1,
      "z": 3,
      "name": "Empty",
      "level": 0
    },
    {
      "x": 1,
      "y": 2,
      "z": 3,
      "name": "Empty",
      "level": 0
    },
    {
      "x": 1,
      "y": 3,
      "z": 3,
      "name": "Empty",
      "level": 0
    },
    {
      "x": 1,
      "y": 5,
      "z": 3,
      "name": "Empty",
      "level": 0
    },
    {
      "x": 1,
      "y": 2,
      "z": 4,
      "name": "Empty",
      "level": 0
    },
    {
      "x": 1,
      "y": 3,
      "z": 4,
      "name": "Empty",
      "level": 0
    },
    {
      "x": 1,
      "y": 4,
      "z": 4,
      "name": "Empty",
      "level": 0
    },
    {
      "x": 2,
      "y": 2,
      "z": -3,
      "name": "Empty",
      "level": 0
    },
    {
      "x": 2,
      "y": 4,
      "z": -3,
      "name": "Empty",
      "level": 0
    },
    {
      "x": 2,
      "y": 0,
      "z": -2,
      "name": "Empty",
      "level": 0
    },
    {
      "x": 2,
      "y": 1,
      "z": -2,
      "name": "Empty",
      "level": 0
    },
    {
      "x": 2,
      "y": 2,
      "z": -2,
      "name": "Empty",
      "level": 0
    },
    {
      "x": 2,
      "y": 3,
      "z": -2,
      "name": "Empty",
      "level": 0
    },
    {
      "x": 2,
      "y": 4,
      "z": -2,
      "name": "Empty",
      "level": 0
    },
    {
      "x": 2,
      "y": 0,
      "z": -1,
      "name": "Empty",
      "level": 0
    },
    {
      "x": 2,
      "y": 5,
      "z": -1,
      "name": "Empty",
      "level": 0
    },
    {
      "x": 2,
      "y": 0,
      "z": 0,
      "name": "Empty",
      "level": 0
    },
    {
      "x": 2,
      "y": 1,
      "z": 0,
      "name": "Empty",
      "level": 0
    },
    {
      "x": 2,
      "y": 5,
      "z": 0,
      "name": "Empty",
      "level": 0
    },
    {
      "x": 2,
      "y": 0,
      "z": 1,
      "name": "Empty",
      "level": 0
    },
    {
      "x": 2,
      "y": 1,
      "z": 1,
      "name": "Empty",
      "level": 0
    },
    {
      "x": 2,
      "y": 2,
      "z": 1,
      "name": "Empty",
      "level": 0
    },
    {
      "x": 2,
      "y": 5,
      "z": 1,
      "name": "Empty",
      "level": 0
    },
    {
      "x": 2,
      "y": 0,
      "z": 2,
      "name": "Empty",
      "level": 0
    },
    {
      "x": 2,
      "y": 1,
      "z": 2,
      "name": "Empty",
      "level": 0
    },
    {
      "x": 2,
      "y": 2,
      "z": 2,
      "name": "Empty",
      "level": 0
    },
    {
      "x": 2,
      "y": 3,
      "z": 2,
      "name": "Empty",
      "level": 0
    },
    {
      "x": 2,
      "y": 5,
      "z": 2,
      "name": "Empty",
      "level": 0
    },
    {
      "x": 2,
      "y": 0,
      "z": 3,
      "name": "Empty",
      "level": 0
    },
    {
      "x": 2,
      "y": 1,
      "z": 3,
      "name": "Empty",
      "level": 0
    },
    {
      "x": 2,
      "y": 2,
      "z": 3,
      "name": "Empty",
      "level": 0
    },
    {
      "x": 2,
      "y": 3,
      "z": 3,
      "name": "Empty",
      "level": 0
    },
    {
      "x": 2,
      "y": 4,
      "z": 3,
      "name": "Empty",
      "level": 0
    },
    {
      "x": 2,
      "y": 2,
      "z": 4,
      "name": "Empty",
      "level": 0
    },
    {
      "x": 2,
      "y": 4,
      "z": 4,
      "name": "Empty",
      "level": 0
    },
    {
      "x": 3,
      "y": 2,
      "z": -3,
      "name": "Empty",
      "level": 0
    },
    {
      "x": 3,
      "y": 3,
      "z": -3,
      "name": "Empty",
      "level": 0
    },
    {
      "x": 3,
      "y": 4,
      "z": -3,
      "name": "Empty",
      "level": 0
    },
    {
      "x": 3,
      "y": 0,
      "z": -2,
      "name": "Empty",
      "level": 0
    },
    {
      "x": 3,
      "y": 1,
      "z": -2,
      "name": "Empty",
      "level": 0
    },
    {
      "x": 3,
      "y": 2,
      "z": -2,
      "name": "Empty",
      "level": 0
    },
    {
      "x": 3,
      "y": 3,
      "z": -2,
      "name": "Empty",
      "level": 0
    },
    {
      "x": 3,
      "y": 4,
      "z": -2,
      "name": "Empty",
      "level": 0
    },
    {
      "x": 3,
      "y": 0,
      "z": -1,
      "name": "Empty",
      "level": 0
    },
    {
      "x": 3,
      "y": 1,
      "z": -1,
      "name": "Empty",
      "level": 0
    },
    {
      "x": 3,
      "y": 2,
      "z": -1,
      "name": "Empty",
      "level": 0
    },
    {
      "x": 3,
      "y": 3,
      "z": -1,
      "name": "Empty",
      "level": 0
    },
    {
      "x": 3,
      "y": 4,
      "z": -1,
      "name": "Empty",
      "level": 0
    },
    {
      "x": 3,
      "y": 0,
      "z": 0,
      "name": "Empty",
      "level": 0
    },
    {
      "x": 3,
      "y": 1,
      "z": 0,
      "name": "Empty",
      "level": 0
    },
    {
      "x": 3,
      "y": 2,
      "z": 0,
      "name": "Empty",
      "level": 0
    },
    {
      "x": 3,
      "y": 3,
      "z": 0,
      "name": "Empty",
      "level": 0
    },
    {
      "x": 3,
      "y": 4,
      "z": 0,
      "name": "Empty",
      "level": 0
    },
    {
      "x": 3,
      "y": 0,
      "z": 1,
      "name": "Empty",
      "level": 0
    },
    {
      "x": 3,
      "y": 1,
      "z": 1,
      "name": "Empty",
      "level": 0
    },
    {
      "x": 3,
      "y": 2,
      "z": 1,
      "name": "Empty",
      "level": 0
    },
    {
      "x": 3,
      "y": 3,
      "z": 1,
      "name": "Empty",
      "level": 0
    },
    {
      "x": 3,
      "y": 4,
      "z": 1,
      "name": "Empty",
      "level": 0
    },
    {
      "x": 3,
      "y": 0,
      "z": 2,
      "name": "Empty",
      "level": 0
    },
    {
      "x": 3,
      "y": 1,
      "z": 2,
      "name": "Empty",
      "level": 0
    },
    {
      "x": 3,
      "y": 2,
      "z": 2,
      "name": "Empty",
      "level": 0
    },
    {
      "x": 3,
      "y": 3,
      "z": 2,
      "name": "Empty",
      "level": 0
    },
    {
      "x": 3,
      "y": 4,
      "z": 2,
      "name": "Empty",
      "level": 0
    },
    {
      "x": 3,
      "y": 0,
      "z": 3,
      "name": "Empty",
      "level": 0
    },
    {
      "x": 3,
      "y": 1,
      "z": 3,
      "name": "Empty",
      "level": 0
    },
    {
      "x": 3,
      "y": 2,
      "z": 3,
      "name": "Empty",
      "level": 0
    },
    {
      "x": 3,
      "y": 3,
      "z": 3,
      "name": "Empty",
      "level": 0
    },
    {
      "x": 3,
      "y": 4,
      "z": 3,
      "name": "Empty",
      "level": 0
    },
    {
      "x": 3,
      "y": 2,
      "z": 4,
      "name": "Empty",
      "level": 0
    },
    {
      "x": 3,
      "y": 3,
      "z": 4,
      "name": "Empty",
      "level": 0
    },
    {
      "x": 3,
      "y": 4,
      "z": 4,
      "name": "Empty",
      "level": 0
    },
    {
      "x": 4,
      "y": 0,
      "z": -3,
      "name": "Empty",
      "level": 0
    },
    {
      "x": 4,
      "y": 1,
      "z": -3,
      "name": "Empty",
      "level": 0
    },
    {
      "x": 4,
      "y": 2,
      "z": -3,
      "name": "Empty",
      "level": 0
    },
    {
      "x": 4,
      "y": 3,
      "z": -3,
      "name": "Empty",
      "level": 0
    },
    {
      "x": 4,
      "y": 4,
      "z": -3,
      "name": "Empty",
      "level": 0
    },
    {
      "x": 4,
      "y": 2,
      "z": -2,
      "name": "Empty",
      "level": 0
    },
    {
      "x": 4,
      "y": 3,
      "z": -2,
      "name": "Empty",
      "level": 0
    },
    {
      "x": 4,
      "y": 4,
      "z": -2,
      "name": "Empty",
      "level": 0
    },
    {
      "x": 4,
      "y": 2,
      "z": -1,
      "name": "Empty",
      "level": 0
    },
    {
      "x": 4,
      "y": 4,
      "z": -1,
      "name": "Empty",
      "level": 0
    },
    {
      "x": 4,
      "y": 2,
      "z": 0,
      "name": "Empty",
      "level": 0
    },
    {
      "x": 4,
      "y": 4,
      "z": 0,
      "name": "Empty",
      "level": 0
    },
    {
      "x": 4,
      "y": 2,
      "z": 1,
      "name": "Empty",
      "level": 0
    },
    {
      "x": 4,
      "y": 4,
      "z": 1,
      "name": "Empty",
      "level": 0
    },
    {
      "x": 4,
      "y": 2,
      "z": 2,
      "name": "Empty",
      "level": 0
    },
    {
      "x": 4,
      "y": 4,
      "z": 2,
      "name": "Empty",
      "level": 0
    },
    {
      "x": 4,
      "y": 2,
      "z": 3,
      "name": "Empty",
      "level": 0
    },
    {
      "x": 4,
      "y": 3,
      "z": 3,
      "name": "Empty",
      "level": 0
    },
    {
      "x": 4,
      "y": 4,
      "z": 3,
      "name": "Empty",
      "level": 0
    },
    {
      "x": 4,
      "y": 0,
      "z": 4,
      "name": "Empty",
      "level": 0
    },
    {
      "x": 4,
      "y": 1,
      "z": 4,
      "name": "Empty",
      "level": 0
    },
    {
      "x": 4,
      "y": 2,
      "z": 4,
      "name": "Empty",
      "level": 0
    },
    {
      "x": 4,
      "y": 3,
      "z": 4,
      "name": "Empty",
      "level": 0
    },
    {
      "x": 4,
      "y": 4,
      "z": 4,
      "name": "Empty",
      "level": 0
    }
  ],
  "entities": [
    {
      "Components": {
        "Nameplate": {
          "Text": "Fairy"
        },
        "SpawnMarkerComponent": {
          "SpawnMarker": "Fairy",
          "RespawnTime": 0.0,
          "SpawnCount": 0
        },
        "Transform": {
          "Position": {
            "X": 0.5,
            "Y": 2.5,
            "Z": 0.5
          },
          "Rotation": {
            "Pitch": 0.0,
            "Yaw": 0.0,
            "Roll": 0.0
          }
        },
        "Model": {
          "Model": {
            "Id": "NPC_Spawn_Marker",
            "Scale": 1.0
          }
        },
        "UUID": {
          "UUID": {
            "$binary": "hFNZ72WsRNmcWQg8mPKThw==",
            "$type": "04"
          }
        },
        "HeadRotation": {
          "Rotation": {
            "Pitch": 0.0,
            "Yaw": 0.0,
            "Roll": 0.0
          }
        }
      }
    }
  ]
}