{
  "version": 8,
  "blockIdVersion": 11,
  "anchorX": 0,
  "anchorY": 0,
  "anchorZ": 0,
  "blocks": [
    {
      "x": -10,
      "y": 0,
      "z": -7,
      "name": "Soil_Grass"
    },
    {
      "x": -10,
      "y": 0,
      "z": -6,
      "name": "Soil_Grass"
    },
    {
      "x": -10,
      "y": 1,
      "z": -6,
      "name": "Plant_Grass_Sharp",
      "rotation": 1
    },
    {
      "x": -10,
      "y": 0,
      "z": -5,
      "name": "Soil_Grass"
    },
    {
      "x": -10,
      "y": 1,
      "z": -5,
      "name": "Plant_Grass_Jungle_Tall",
      "rotation": 1
    },
    {
      "x": -10,
      "y": 0,
      "z": -4,
      "name": "Soil_Grass"
    },
    {
      "x": -10,
      "y": 0,
      "z": -3,
      "name": "Soil_Grass"
    },
    {
      "x": -10,
      "y": 1,
      "z": -3,
      "name": "Plant_Grass_Lush",
      "rotation": 2
    },
    {
      "x": -10,
      "y": 0,
      "z": -2,
      "name": "Soil_Grass"
    },
    {
      "x": -10,
      "y": 0,
      "z": -1,
      "name": "Soil_Grass"
    },
    {
      "x": -10,
      "y": 0,
      "z": 0,
      "name": "Soil_Grass"
    },
    {
      "x": -10,
      "y": 0,
      "z": 1,
      "name": "Soil_Grass"
    },
    {
      "x": -10,
      "y": 0,
      "z": 2,
      "name": "Soil_Grass"
    },
    {
      "x": -10,
      "y": 0,
      "z": 3,
      "name": "Soil_Grass"
    },
    {
      "x": -10,
      "y": 0,
      "z": 4,
      "name": "Soil_Grass"
    },
    {
      "x": -10,
      "y": 0,
      "z": 5,
      "name": "Soil_Grass"
    },
    {
      "x": -10,
      "y": 0,
      "z": 6,
      "name": "Soil_Grass"
    },
    {
      "x": -10,
      "y": 0,
      "z": 7,
      "name": "Soil_Grass"
    },
    {
      "x": -9,
      "y": 0,
      "z": -7,
      "name": "Soil_Grass"
    },
    {
      "x": -9,
      "y": 0,
      "z": -6,
      "name": "Soil_Grass"
    },
    {
      "x": -9,
      "y": 0,
      "z": -5,
      "name": "Soil_Grass"
    },
    {
      "x": -9,
      "y": 0,
      "z": -4,
      "name": "Soil_Grass"
    },
    {
      "x": -9,
      "y": 1,
      "z": -4,
      "name": "Plant_Grass_Sharp"
    },
    {
      "x": -9,
      "y": 0,
      "z": -3,
      "name": "Soil_Grass"
    },
    {
      "x": -9,
      "y": 0,
      "z": -2,
      "name": "Soil_Grass"
    },
    {
      "x": -9,
      "y": 0,
      "z": -1,
      "name": "Soil_Grass"
    },
    {
      "x": -9,
      "y": 1,
      "z": -1,
      "name": "Plant_Grass_Jungle",
      "rotation": 2
    },
    {
      "x": -9,
      "y": 0,
      "z": 0,
      "name": "Soil_Grass"
    },
    {
      "x": -9,
      "y": 0,
      "z": 1,
      "name": "Soil_Grass"
    },
    {
      "x": -9,
      "y": 0,
      "z": 2,
      "name": "Soil_Grass"
    },
    {
      "x": -9,
      "y": 1,
      "z": 2,
      "name": "Plant_Grass_Jungle_Tall",
      "support": 15
    },
    {
      "x": -9,
      "y": 0,
      "z": 3,
      "name": "Soil_Grass"
    },
    {
      "x": -9,
      "y": 1,
      "z": 3,
      "name": "Plant_Grass_Jungle_Tall",
      "support": 15
    },
    {
      "x": -9,
      "y": 0,
      "z": 4,
      "name": "Soil_Grass"
    },
    {
      "x": -9,
      "y": 0,
      "z": 5,
      "name": "Soil_Grass"
    },
    {
      "x": -9,
      "y": 1,
      "z": 5,
      "name": "Plant_Grass_Jungle_Tall",
      "support": 15
    },
    {
      "x": -9,
      "y": 0,
      "z": 6,
      "name": "Soil_Grass"
    },
    {
      "x": -9,
      "y": 0,
      "z": 7,
      "name": "Soil_Grass"
    },
    {
      "x": -8,
      "y": 0,
      "z": -7,
      "name": "Soil_Grass"
    },
    {
      "x": -8,
      "y": 0,
      "z": -6,
      "name": "Soil_Grass"
    },
    {
      "x": -8,
      "y": 1,
      "z": -6,
      "name": "Plant_Grass_Jungle_Tall",
      "rotation": 2
    },
    {
      "x": -8,
      "y": 0,
      "z": -5,
      "name": "Soil_Grass"
    },
    {
      "x": -8,
      "y": 0,
      "z": -4,
      "name": "Soil_Grass"
    },
    {
      "x": -8,
      "y": 0,
      "z": -3,
      "name": "Soil_Grass"
    },
    {
      "x": -8,
      "y": 0,
      "z": -2,
      "name": "Soil_Grass"
    },
    {
      "x": -8,
      "y": 0,
      "z": -1,
      "name": "Soil_Grass"
    },
    {
      "x": -8,
      "y": 0,
      "z": 0,
      "name": "Soil_Grass"
    },
    {
      "x": -8,
      "y": 1,
      "z": 0,
      "name": "Plant_Grass_Lush_Tall",
      "rotation": 2
    },
    {
      "x": -8,
      "y": 0,
      "z": 1,
      "name": "Soil_Grass"
    },
    {
      "x": -8,
      "y": 0,
      "z": 2,
      "name": "Soil_Grass"
    },
    {
      "x": -8,
      "y": 1,
      "z": 2,
      "name": "Plant_Grass_Lush",
      "rotation": 3
    },
    {
      "x": -8,
      "y": 0,
      "z": 3,
      "name": "Soil_Grass"
    },
    {
      "x": -8,
      "y": 0,
      "z": 4,
      "name": "Soil_Grass"
    },
    {
      "x": -8,
      "y": 1,
      "z": 4,
      "name": "Plant_Grass_Jungle_Tall",
      "support": 15
    },
    {
      "x": -8,
      "y": 0,
      "z": 5,
      "name": "Soil_Grass"
    },
    {
      "x": -8,
      "y": 0,
      "z": 6,
      "name": "Soil_Grass"
    },
    {
      "x": -8,
      "y": 1,
      "z": 6,
      "name": "Plant_Grass_Jungle_Tall",
      "support": 15
    },
    {
      "x": -8,
      "y": 0,
      "z": 7,
      "name": "Soil_Grass"
    },
    {
      "x": -8,
      "y": 1,
      "z": 7,
      "name": "Plant_Grass_Jungle_Tall",
      "support": 15
    },
    {
      "x": -7,
      "y": 0,
      "z": -7,
      "name": "Soil_Grass"
    },
    {
      "x": -7,
      "y": 1,
      "z": -7,
      "name": "Plant_Grass_Jungle_Tall"
    },
    {
      "x": -7,
      "y": 0,
      "z": -6,
      "name": "Soil_Grass"
    },
    {
      "x": -7,
      "y": 0,
      "z": -5,
      "name": "Soil_Grass"
    },
    {
      "x": -7,
      "y": 0,
      "z": -4,
      "name": "Soil_Grass"
    },
    {
      "x": -7,
      "y": 1,
      "z": -4,
      "name": "Plant_Grass_Lush",
      "rotation": 2
    },
    {
      "x": -7,
      "y": 0,
      "z": -3,
      "name": "Soil_Grass"
    },
    {
      "x": -7,
      "y": 1,
      "z": -3,
      "name": "Plant_Grass_Jungle_Tall",
      "rotation": 3
    },
    {
      "x": -7,
      "y": 0,
      "z": -2,
      "name": "Soil_Grass"
    },
    {
      "x": -7,
      "y": 1,
      "z": -2,
      "name": "Plant_Grass_Lush"
    },
    {
      "x": -7,
      "y": 0,
      "z": -1,
      "name": "Soil_Grass"
    },
    {
      "x": -7,
      "y": 0,
      "z": 0,
      "name": "Soil_Grass"
    },
    {
      "x": -7,
      "y": 0,
      "z": 1,
      "name": "Soil_Grass"
    },
    {
      "x": -7,
      "y": 0,
      "z": 2,
      "name": "Soil_Grass"
    },
    {
      "x": -7,
      "y": 1,
      "z": 2,
      "name": "Plant_Grass_Jungle_Tall",
      "support": 15
    },
    {
      "x": -7,
      "y": 0,
      "z": 3,
      "name": "Soil_Grass"
    },
    {
      "x": -7,
      "y": 0,
      "z": 4,
      "name": "Soil_Grass"
    },
    {
      "x": -7,
      "y": 0,
      "z": 5,
      "name": "Soil_Grass"
    },
    {
      "x": -7,
      "y": 1,
      "z": 5,
      "name": "Plant_Grass_Jungle_Tall",
      "support": 15
    },
    {
      "x": -7,
      "y": 0,
      "z": 6,
      "name": "Soil_Grass"
    },
    {
      "x": -7,
      "y": 0,
      "z": 7,
      "name": "Soil_Grass"
    },
    {
      "x": -6,
      "y": 0,
      "z": -7,
      "name": "Soil_Grass"
    },
    {
      "x": -6,
      "y": 0,
      "z": -6,
      "name": "Soil_Grass"
    },
    {
      "x": -6,
      "y": 1,
      "z": -6,
      "name": "Plant_Grass_Jungle_Tall",
      "rotation": 2
    },
    {
      "x": -6,
      "y": 0,
      "z": -5,
      "name": "Soil_Grass"
    },
    {
      "x": -6,
      "y": 0,
      "z": -4,
      "name": "Soil_Grass"
    },
    {
      "x": -6,
      "y": 0,
      "z": -3,
      "name": "Soil_Grass"
    },
    {
      "x": -6,
      "y": 0,
      "z": -2,
      "name": "Soil_Grass"
    },
    {
      "x": -6,
      "y": 0,
      "z": -1,
      "name": "Soil_Grass"
    },
    {
      "x": -6,
      "y": 1,
      "z": -1,
      "name": "Plant_Grass_Sharp",
      "rotation": 1
    },
    {
      "x": -6,
      "y": 0,
      "z": 0,
      "name": "Soil_Grass"
    },
    {
      "x": -6,
      "y": 0,
      "z": 1,
      "name": "Soil_Grass"
    },
    {
      "x": -6,
      "y": 0,
      "z": 2,
      "name": "Soil_Grass"
    },
    {
      "x": -6,
      "y": 0,
      "z": 3,
      "name": "Soil_Grass"
    },
    {
      "x": -6,
      "y": 0,
      "z": 4,
      "name": "Soil_Grass"
    },
    {
      "x": -6,
      "y": 1,
      "z": 4,
      "name": "Plant_Grass_Jungle_Tall",
      "support": 15
    },
    {
      "x": -6,
      "y": 0,
      "z": 5,
      "name": "Soil_Grass"
    },
    {
      "x": -6,
      "y": 0,
      "z": 6,
      "name": "Soil_Grass"
    },
    {
      "x": -6,
      "y": 0,
      "z": 7,
      "name": "Soil_Grass"
    },
    {
      "x": -5,
      "y": 0,
      "z": -7,
      "name": "Soil_Grass"
    },
    {
      "x": -5,
      "y": 0,
      "z": -6,
      "name": "Soil_Grass"
    },
    {
      "x": -5,
      "y": 0,
      "z": -5,
      "name": "Soil_Dirt"
    },
    {
      "x": -5,
      "y": 1,
      "z": -5,
      "name": "Wood_Crystal_Trunk_Full",
      "support": 15
    },
    {
      "x": -5,
      "y": 0,
      "z": -4,
      "name": "Soil_Grass"
    },
    {
      "x": -5,
      "y": 0,
      "z": -3,
      "name": "Soil_Grass"
    },
    {
      "x": -5,
      "y": 15,
      "z": -3,
      "name": "Plant_Leaves_Crystal",
      "support": 15
    },
    {
      "x": -5,
      "y": 17,
      "z": -3,
      "name": "Plant_Leaves_Crystal",
      "support": 15
    },
    {
      "x": -5,
      "y": 0,
      "z": -2,
      "name": "Soil_Grass"
    },
    {
      "x": -5,
      "y": 16,
      "z": -2,
      "name": "Plant_Leaves_Crystal",
      "support": 15
    },
    {
      "x": -5,
      "y": 17,
      "z": -2,
      "name": "Plant_Leaves_Crystal",
      "support": 15
    },
    {
      "x": -5,
      "y": 0,
      "z": -1,
      "name": "Soil_Grass"
    },
    {
      "x": -5,
      "y": 15,
      "z": -1,
      "name": "Plant_Leaves_Crystal",
      "support": 15
    },
    {
      "x": -5,
      "y": 17,
      "z": -1,
      "name": "Plant_Leaves_Crystal",
      "support": 15
    },
    {
      "x": -5,
      "y": 0,
      "z": 0,
      "name": "Soil_Grass"
    },
    {
      "x": -5,
      "y": 17,
      "z": 0,
      "name": "Plant_Leaves_Crystal",
      "support": 15
    },
    {
      "x": -5,
      "y": 0,
      "z": 1,
      "name": "Soil_Grass"
    },
    {
      "x": -5,
      "y": 1,
      "z": 1,
      "name": "Plant_Grass_Jungle_Tall",
      "rotation": 1
    },
    {
      "x": -5,
      "y": 12,
      "z": 1,
      "name": "Plant_Leaves_Crystal",
      "support": 15
    },
    {
      "x": -5,
      "y": 0,
      "z": 2,
      "name": "Soil_Grass"
    },
    {
      "x": -5,
      "y": 0,
      "z": 3,
      "name": "Soil_Grass"
    },
    {
      "x": -5,
      "y": 0,
      "z": 4,
      "name": "Soil_Grass"
    },
    {
      "x": -5,
      "y": 0,
      "z": 5,
      "name": "Soil_Grass"
    },
    {
      "x": -5,
      "y": 0,
      "z": 6,
      "name": "Soil_Grass"
    },
    {
      "x": -5,
      "y": 1,
      "z": 6,
      "name": "Plant_Grass_Jungle_Tall",
      "support": 15
    },
    {
      "x": -5,
      "y": 0,
      "z": 7,
      "name": "Soil_Grass"
    },
    {
      "x": -4,
      "y": 0,
      "z": -7,
      "name": "Soil_Grass"
    },
    {
      "x": -4,
      "y": 0,
      "z": -6,
      "name": "Soil_Grass"
    },
    {
      "x": -4,
      "y": 0,
      "z": -5,
      "name": "Soil_Grass"
    },
    {
      "x": -4,
      "y": 15,
      "z": -5,
      "name": "Plant_Leaves_Crystal",
      "support": 15
    },
    {
      "x": -4,
      "y": 16,
      "z": -5,
      "name": "Plant_Leaves_Crystal",
      "support": 15
    },
    {
      "x": -4,
      "y": 0,
      "z": -4,
      "name": "Soil_Grass"
    },
    {
      "x": -4,
      "y": 2,
      "z": -4,
      "name": "Wood_Crystal_Trunk_Full",
      "support": 15,
      "rotation": 5
    },
    {
      "x": -4,
      "y": 12,
      "z": -4,
      "name": "Plant_Leaves_Crystal",
      "support": 15
    },
    {
      "x": -4,
      "y": 13,
      "z": -4,
      "name": "Plant_Leaves_Crystal",
      "support": 15
    },
    {
      "x": -4,
      "y": 14,
      "z": -4,
      "name": "Plant_Leaves_Crystal",
      "support": 15
    },
    {
      "x": -4,
      "y": 15,
      "z": -4,
      "name": "Plant_Leaves_Crystal",
      "support": 15
    },
    {
      "x": -4,
      "y": 16,
      "z": -4,
      "name": "Plant_Leaves_Crystal",
      "support": 15
    },
    {
      "x": -4,
      "y": 17,
      "z": -4,
      "name": "Plant_Leaves_Crystal",
      "support": 15
    },
    {
      "x": -4,
      "y": 0,
      "z": -3,
      "name": "Soil_Grass"
    },
    {
      "x": -4,
      "y": 15,
      "z": -3,
      "name": "Plant_Leaves_Crystal",
      "support": 15
    },
    {
      "x": -4,
      "y": 16,
      "z": -3,
      "name": "Plant_Leaves_Crystal",
      "support": 15
    },
    {
      "x": -4,
      "y": 17,
      "z": -3,
      "name": "Soil_Grass"
    },
    {
      "x": -4,
      "y": 0,
      "z": -2,
      "name": "Soil_Grass"
    },
    {
      "x": -4,
      "y": 14,
      "z": -2,
      "name": "Plant_Leaves_Crystal",
      "support": 15
    },
    {
      "x": -4,
      "y": 15,
      "z": -2,
      "name": "Plant_Leaves_Crystal",
      "support": 15
    },
    {
      "x": -4,
      "y": 16,
      "z": -2,
      "name": "Soil_Dirt"
    },
    {
      "x": -4,
      "y": 17,
      "z": -2,
      "name": "Soil_Grass"
    },
    {
      "x": -4,
      "y": 0,
      "z": -1,
      "name": "Soil_Grass"
    },
    {
      "x": -4,
      "y": 1,
      "z": -1,
      "name": "Plant_Grass_Sharp",
      "rotation": 1
    },
    {
      "x": -4,
      "y": 14,
      "z": -1,
      "name": "Plant_Leaves_Crystal",
      "support": 15
    },
    {
      "x": -4,
      "y": 15,
      "z": -1,
      "name": "Plant_Leaves_Crystal",
      "support": 15
    },
    {
      "x": -4,
      "y": 16,
      "z": -1,
      "name": "Plant_Leaves_Crystal",
      "support": 15
    },
    {
      "x": -4,
      "y": 17,
      "z": -1,
      "name": "Soil_Grass"
    },
    {
      "x": -4,
      "y": 0,
      "z": 0,
      "name": "Soil_Grass"
    },
    {
      "x": -4,
      "y": 1,
      "z": 0,
      "name": "Plant_Grass_Lush",
      "rotation": 3
    },
    {
      "x": -4,
      "y": 14,
      "z": 0,
      "name": "Plant_Leaves_Crystal",
      "support": 15
    },
    {
      "x": -4,
      "y": 15,
      "z": 0,
      "name": "Plant_Leaves_Crystal",
      "support": 15
    },
    {
      "x": -4,
      "y": 16,
      "z": 0,
      "name": "Plant_Leaves_Crystal",
      "support": 15
    },
    {
      "x": -4,
      "y": 17,
      "z": 0,
      "name": "Plant_Leaves_Crystal",
      "support": 15
    },
    {
      "x": -4,
      "y": 0,
      "z": 1,
      "name": "Soil_Grass"
    },
    {
      "x": -4,
      "y": 9,
      "z": 1,
      "name": "Plant_Leaves_Crystal",
      "support": 15
    },
    {
      "x": -4,
      "y": 10,
      "z": 1,
      "name": "Plant_Leaves_Crystal",
      "support": 15
    },
    {
      "x": -4,
      "y": 11,
      "z": 1,
      "name": "Plant_Leaves_Crystal",
      "support": 15
    },
    {
      "x": -4,
      "y": 12,
      "z": 1,
      "name": "Plant_Leaves_Crystal",
      "support": 15
    },
    {
      "x": -4,
      "y": 13,
      "z": 1,
      "name": "Plant_Leaves_Crystal",
      "support": 15
    },
    {
      "x": -4,
      "y": 14,
      "z": 1,
      "name": "Plant_Leaves_Crystal",
      "support": 15
    },
    {
      "x": -4,
      "y": 15,
      "z": 1,
      "name": "Plant_Leaves_Crystal",
      "support": 15
    },
    {
      "x": -4,
      "y": 16,
      "z": 1,
      "name": "Plant_Leaves_Crystal",
      "support": 15
    },
    {
      "x": -4,
      "y": 17,
      "z": 1,
      "name": "Plant_Leaves_Crystal",
      "support": 15
    },
    {
      "x": -4,
      "y": 0,
      "z": 2,
      "name": "Soil_Grass"
    },
    {
      "x": -4,
      "y": 0,
      "z": 3,
      "name": "Soil_Dirt"
    },
    {
      "x": -4,
      "y": 1,
      "z": 3,
      "name": "Wood_Crystal_Trunk_Full",
      "support": 15
    },
    {
      "x": -4,
      "y": 0,
      "z": 4,
      "name": "Soil_Grass"
    },
    {
      "x": -4,
      "y": 0,
      "z": 5,
      "name": "Soil_Grass"
    },
    {
      "x": -4,
      "y": 0,
      "z": 6,
      "name": "Soil_Grass"
    },
    {
      "x": -4,
      "y": 0,
      "z": 7,
      "name": "Soil_Grass"
    },
    {
      "x": -3,
      "y": 0,
      "z": -7,
      "name": "Soil_Grass"
    },
    {
      "x": -3,
      "y": 0,
      "z": -6,
      "name": "Soil_Grass"
    },
    {
      "x": -3,
      "y": 0,
      "z": -5,
      "name": "Soil_Grass"
    },
    {
      "x": -3,
      "y": 1,
      "z": -5,
      "name": "Plant_Grass_Jungle",
      "rotation": 3
    },
    {
      "x": -3,
      "y": 14,
      "z": -5,
      "name": "Plant_Leaves_Crystal",
      "support": 15
    },
    {
      "x": -3,
      "y": 16,
      "z": -5,
      "name": "Plant_Leaves_Crystal",
      "support": 15
    },
    {
      "x": -3,
      "y": 0,
      "z": -4,
      "name": "Soil_Grass"
    },
    {
      "x": -3,
      "y": 1,
      "z": -4,
      "name": "Plant_Grass_Jungle",
      "rotation": 2
    },
    {
      "x": -3,
      "y": 13,
      "z": -4,
      "name": "Plant_Leaves_Crystal",
      "support": 15
    },
    {
      "x": -3,
      "y": 14,
      "z": -4,
      "name": "Plant_Leaves_Crystal",
      "support": 15
    },
    {
      "x": -3,
      "y": 15,
      "z": -4,
      "name": "Plant_Leaves_Crystal",
      "support": 15
    },
    {
      "x": -3,
      "y": 16,
      "z": -4,
      "name": "Soil_Dirt"
    },
    {
      "x": -3,
      "y": 17,
      "z": -4,
      "name": "Soil_Grass"
    },
    {
      "x": -3,
      "y": 0,
      "z": -3,
      "name": "Soil_Dirt"
    },
    {
      "x": -3,
      "y": 1,
      "z": -3,
      "name": "Wood_Crystal_Trunk_Full",
      "support": 15
    },
    {
      "x": -3,
      "y": 2,
      "z": -3,
      "name": "Wood_Crystal_Trunk_Full",
      "support": 15
    },
    {
      "x": -3,
      "y": 14,
      "z": -3,
      "name": "Plant_Leaves_Crystal",
      "support": 15
    },
    {
      "x": -3,
      "y": 15,
      "z": -3,
      "name": "Ore_Iron_Stone"
    },
    {
      "x": -3,
      "y": 16,
      "z": -3,
      "name": "Soil_Dirt"
    },
    {
      "x": -3,
      "y": 17,
      "z": -3,
      "name": "Soil_Grass"
    },
    {
      "x": -3,
      "y": 0,
      "z": -2,
      "name": "Soil_Grass"
    },
    {
      "x": -3,
      "y": 14,
      "z": -2,
      "name": "Plant_Leaves_Crystal",
      "support": 15
    },
    {
      "x": -3,
      "y": 15,
      "z": -2,
      "name": "Ore_Iron_Stone"
    },
    {
      "x": -3,
      "y": 16,
      "z": -2,
      "name": "Soil_Dirt"
    },
    {
      "x": -3,
      "y": 17,
      "z": -2,
      "name": "Soil_Grass"
    },
    {
      "x": -3,
      "y": 0,
      "z": -1,
      "name": "Soil_Grass"
    },
    {
      "x": -3,
      "y": 13,
      "z": -1,
      "name": "Plant_Leaves_Crystal",
      "support": 15
    },
    {
      "x": -3,
      "y": 15,
      "z": -1,
      "name": "Rock_Stone"
    },
    {
      "x": -3,
      "y": 16,
      "z": -1,
      "name": "Soil_Dirt"
    },
    {
      "x": -3,
      "y": 17,
      "z": -1,
      "name": "Soil_Grass"
    },
    {
      "x": -3,
      "y": 0,
      "z": 0,
      "name": "Soil_Grass"
    },
    {
      "x": -3,
      "y": 14,
      "z": 0,
      "name": "Plant_Leaves_Crystal",
      "support": 15
    },
    {
      "x": -3,
      "y": 15,
      "z": 0,
      "name": "Plant_Leaves_Crystal",
      "support": 15
    },
    {
      "x": -3,
      "y": 16,
      "z": 0,
      "name": "Soil_Dirt"
    },
    {
      "x": -3,
      "y": 17,
      "z": 0,
      "name": "Soil_Grass"
    },
    {
      "x": -3,
      "y": 0,
      "z": 1,
      "name": "Soil_Grass"
    },
    {
      "x": -3,
      "y": 13,
      "z": 1,
      "name": "Plant_Leaves_Crystal",
      "support": 15
    },
    {
      "x": -3,
      "y": 14,
      "z": 1,
      "name": "Plant_Leaves_Crystal",
      "support": 15
    },
    {
      "x": -3,
      "y": 15,
      "z": 1,
      "name": "Plant_Leaves_Crystal",
      "support": 15
    },
    {
      "x": -3,
      "y": 16,
      "z": 1,
      "name": "Plant_Leaves_Crystal",
      "support": 15
    },
    {
      "x": -3,
      "y": 17,
      "z": 1,
      "name": "Soil_Grass"
    },
    {
      "x": -3,
      "y": 0,
      "z": 2,
      "name": "Soil_Dirt"
    },
    {
      "x": -3,
      "y": 1,
      "z": 2,
      "name": "Wood_Crystal_Trunk_Full",
      "support": 15
    },
    {
      "x": -3,
      "y": 16,
      "z": 2,
      "name": "Plant_Leaves_Crystal",
      "support": 15
    },
    {
      "x": -3,
      "y": 17,
      "z": 2,
      "name": "Plant_Leaves_Crystal",
      "support": 15
    },
    {
      "x": -3,
      "y": 0,
      "z": 3,
      "name": "Soil_Grass"
    },
    {
      "x": -3,
      "y": 1,
      "z": 3,
      "name": "Plant_Grass_Jungle",
      "rotation": 1
    },
    {
      "x": -3,
      "y": 0,
      "z": 4,
      "name": "Soil_Grass"
    },
    {
      "x": -3,
      "y": 0,
      "z": 5,
      "name": "Soil_Grass"
    },
    {
      "x": -3,
      "y": 0,
      "z": 6,
      "name": "Soil_Grass"
    },
    {
      "x": -3,
      "y": 1,
      "z": 6,
      "name": "Plant_Grass_Jungle_Tall",
      "support": 15
    },
    {
      "x": -3,
      "y": 0,
      "z": 7,
      "name": "Soil_Grass"
    },
    {
      "x": -2,
      "y": 0,
      "z": -7,
      "name": "Soil_Grass"
    },
    {
      "x": -2,
      "y": 1,
      "z": -7,
      "name": "Plant_Grass_Jungle",
      "rotation": 1
    },
    {
      "x": -2,
      "y": 0,
      "z": -6,
      "name": "Soil_Grass"
    },
    {
      "x": -2,
      "y": 15,
      "z": -6,
      "name": "Plant_Leaves_Crystal",
      "support": 15
    },
    {
      "x": -2,
      "y": 0,
      "z": -5,
      "name": "Soil_Grass"
    },
    {
      "x": -2,
      "y": 15,
      "z": -5,
      "name": "Plant_Leaves_Crystal",
      "support": 15
    },
    {
      "x": -2,
      "y": 17,
      "z": -5,
      "name": "Plant_Leaves_Crystal",
      "support": 15
    },
    {
      "x": -2,
      "y": 0,
      "z": -4,
      "name": "Soil_Grass"
    },
    {
      "x": -2,
      "y": 14,
      "z": -4,
      "name": "Plant_Leaves_Crystal",
      "support": 15
    },
    {
      "x": -2,
      "y": 15,
      "z": -4,
      "name": "Rock_Stone"
    },
    {
      "x": -2,
      "y": 16,
      "z": -4,
      "name": "Soil_Dirt"
    },
    {
      "x": -2,
      "y": 17,
      "z": -4,
      "name": "Soil_Grass"
    },
    {
      "x": -2,
      "y": 0,
      "z": -3,
      "name": "Soil_Grass"
    },
    {
      "x": -2,
      "y": 1,
      "z": -3,
      "name": "Plant_Grass_Sharp"
    },
    {
      "x": -2,
      "y": 14,
      "z": -3,
      "name": "Plant_Leaves_Crystal",
      "support": 15
    },
    {
      "x": -2,
      "y": 15,
      "z": -3,
      "name": "Rock_Stone"
    },
    {
      "x": -2,
      "y": 16,
      "z": -3,
      "name": "Soil_Dirt"
    },
    {
      "x": -2,
      "y": 17,
      "z": -3,
      "name": "Soil_Grass"
    },
    {
      "x": -2,
      "y": 0,
      "z": -2,
      "name": "Soil_Grass"
    },
    {
      "x": -2,
      "y": 14,
      "z": -2,
      "name": "Plant_Leaves_Crystal",
      "support": 15
    },
    {
      "x": -2,
      "y": 15,
      "z": -2,
      "name": "Ore_Gold_Stone"
    },
    {
      "x": -2,
      "y": 16,
      "z": -2,
      "name": "Soil_Dirt"
    },
    {
      "x": -2,
      "y": 17,
      "z": -2,
      "name": "Soil_Grass"
    },
    {
      "x": -2,
      "y": 18,
      "z": -2,
      "name": "Furniture_Village_Bench",
      "filler": 992,
      "rotation": 3
    },
    {
      "x": -2,
      "y": 19,
      "z": -2,
      "name": "Furniture_Village_Bench",
      "filler": 2016,
      "rotation": 3
    },
    {
      "x": -2,
      "y": 0,
      "z": -1,
      "name": "Soil_Dirt"
    },
    {
      "x": -2,
      "y": 1,
      "z": -1,
      "name": "Wood_Crystal_Trunk_Full",
      "support": 15,
      "rotation": 5
    },
    {
      "x": -2,
      "y": 13,
      "z": -1,
      "name": "Plant_Leaves_Crystal",
      "support": 15
    },
    {
      "x": -2,
      "y": 14,
      "z": -1,
      "name": "Plant_Leaves_Crystal",
      "support": 15
    },
    {
      "x": -2,
      "y": 15,
      "z": -1,
      "name": "Rock_Stone"
    },
    {
      "x": -2,
      "y": 16,
      "z": -1,
      "name": "Soil_Dirt"
    },
    {
      "x": -2,
      "y": 17,
      "z": -1,
      "name": "Soil_Grass"
    },
    {
      "x": -2,
      "y": 18,
      "z": -1,
      "name": "Furniture_Village_Bench",
      "rotation": 3
    },
    {
      "x": -2,
      "y": 19,
      "z": -1,
      "name": "Furniture_Village_Bench",
      "filler": 1024,
      "rotation": 3
    },
    {
      "x": -2,
      "y": 0,
      "z": 0,
      "name": "Soil_Dirt"
    },
    {
      "x": -2,
      "y": 1,
      "z": 0,
      "name": "Wood_Crystal_Trunk_Full",
      "support": 15,
      "rotation": 5
    },
    {
      "x": -2,
      "y": 2,
      "z": 0,
      "name": "Wood_Crystal_Trunk_Full",
      "support": 15,
      "rotation": 5
    },
    {
      "x": -2,
      "y": 3,
      "z": 0,
      "name": "Wood_Crystal_Trunk_Full",
      "support": 15,
      "rotation": 5
    },
    {
      "x": -2,
      "y": 4,
      "z": 0,
      "name": "Wood_Crystal_Trunk_Full",
      "support": 15,
      "rotation": 5
    },
    {
      "x": -2,
      "y": 14,
      "z": 0,
      "name": "Plant_Leaves_Crystal",
      "support": 15
    },
    {
      "x": -2,
      "y": 15,
      "z": 0,
      "name": "Rock_Stone"
    },
    {
      "x": -2,
      "y": 16,
      "z": 0,
      "name": "Soil_Dirt"
    },
    {
      "x": -2,
      "y": 17,
      "z": 0,
      "name": "Rock_Crystal_Pink_Block",
      "rotation": 4
    },
    {
      "x": -2,
      "y": 18,
      "z": 0,
      "name": "Rock_Crystal_Pink_Small"
    },
    {
      "x": -2,
      "y": 0,
      "z": 1,
      "name": "Soil_Grass"
    },
    {
      "x": -2,
      "y": 14,
      "z": 1,
      "name": "Plant_Leaves_Crystal",
      "support": 15
    },
    {
      "x": -2,
      "y": 15,
      "z": 1,
      "name": "Rock_Crystal_Purple_Medium",
      "rotation": 8
    },
    {
      "x": -2,
      "y": 16,
      "z": 1,
      "name": "Soil_Dirt"
    },
    {
      "x": -2,
      "y": 17,
      "z": 1,
      "name": "Soil_Grass"
    },
    {
      "x": -2,
      "y": 0,
      "z": 2,
      "name": "Soil_Grass"
    },
    {
      "x": -2,
      "y": 1,
      "z": 2,
      "name": "Plant_Grass_Jungle",
      "rotation": 3
    },
    {
      "x": -2,
      "y": 14,
      "z": 2,
      "name": "Plant_Leaves_Crystal",
      "support": 15
    },
    {
      "x": -2,
      "y": 15,
      "z": 2,
      "name": "Plant_Leaves_Crystal",
      "support": 15
    },
    {
      "x": -2,
      "y": 16,
      "z": 2,
      "name": "Soil_Dirt"
    },
    {
      "x": -2,
      "y": 17,
      "z": 2,
      "name": "Soil_Grass"
    },
    {
      "x": -2,
      "y": 18,
      "z": 2,
      "name": "Plant_Grass_Lush",
      "support": 15
    },
    {
      "x": -2,
      "y": 0,
      "z": 3,
      "name": "Soil_Grass"
    },
    {
      "x": -2,
      "y": 15,
      "z": 3,
      "name": "Plant_Leaves_Crystal",
      "support": 15
    },
    {
      "x": -2,
      "y": 16,
      "z": 3,
      "name": "Plant_Leaves_Crystal",
      "support": 15
    },
    {
      "x": -2,
      "y": 17,
      "z": 3,
      "name": "Plant_Leaves_Crystal",
      "support": 15
    },
    {
      "x": -2,
      "y": 0,
      "z": 4,
      "name": "Soil_Grass"
    },
    {
      "x": -2,
      "y": 1,
      "z": 4,
      "name": "Plant_Grass_Jungle"
    },
    {
      "x": -2,
      "y": 16,
      "z": 4,
      "name": "Plant_Leaves_Crystal",
      "support": 15
    },
    {
      "x": -2,
      "y": 0,
      "z": 5,
      "name": "Soil_Grass"
    },
    {
      "x": -2,
      "y": 1,
      "z": 5,
      "name": "Plant_Grass_Jungle"
    },
    {
      "x": -2,
      "y": 0,
      "z": 6,
      "name": "Soil_Grass"
    },
    {
      "x": -2,
      "y": 1,
      "z": 6,
      "name": "Plant_Grass_Jungle_Tall",
      "support": 15
    },
    {
      "x": -2,
      "y": 0,
      "z": 7,
      "name": "Soil_Grass"
    },
    {
      "x": -1,
      "y": 0,
      "z": -7,
      "name": "Soil_Grass"
    },
    {
      "x": -1,
      "y": 0,
      "z": -6,
      "name": "Soil_Grass"
    },
    {
      "x": -1,
      "y": 1,
      "z": -6,
      "name": "Plant_Grass_Sharp",
      "rotation": 2
    },
    {
      "x": -1,
      "y": 0,
      "z": -5,
      "name": "Soil_Grass"
    },
    {
      "x": -1,
      "y": 14,
      "z": -5,
      "name": "Plant_Leaves_Crystal",
      "support": 15
    },
    {
      "x": -1,
      "y": 16,
      "z": -5,
      "name": "Plant_Leaves_Crystal",
      "support": 15
    },
    {
      "x": -1,
      "y": 17,
      "z": -5,
      "name": "Plant_Leaves_Crystal",
      "support": 15
    },
    {
      "x": -1,
      "y": 0,
      "z": -4,
      "name": "Soil_Grass"
    },
    {
      "x": -1,
      "y": 1,
      "z": -4,
      "name": "Plant_Grass_Jungle",
      "support": 15
    },
    {
      "x": -1,
      "y": 14,
      "z": -4,
      "name": "Plant_Leaves_Crystal",
      "support": 15
    },
    {
      "x": -1,
      "y": 15,
      "z": -4,
      "name": "Plant_Leaves_Crystal",
      "support": 15
    },
    {
      "x": -1,
      "y": 16,
      "z": -4,
      "name": "Soil_Dirt"
    },
    {
      "x": -1,
      "y": 17,
      "z": -4,
      "name": "Soil_Grass"
    },
    {
      "x": -1,
      "y": 0,
      "z": -3,
      "name": "Soil_Grass"
    },
    {
      "x": -1,
      "y": 14,
      "z": -3,
      "name": "Plant_Leaves_Crystal",
      "support": 15
    },
    {
      "x": -1,
      "y": 15,
      "z": -3,
      "name": "Rock_Stone"
    },
    {
      "x": -1,
      "y": 16,
      "z": -3,
      "name": "Soil_Dirt"
    },
    {
      "x": -1,
      "y": 17,
      "z": -3,
      "name": "Soil_Grass"
    },
    {
      "x": -1,
      "y": 0,
      "z": -2,
      "name": "Soil_Dirt"
    },
    {
      "x": -1,
      "y": 1,
      "z": -2,
      "name": "Wood_Crystal_Trunk_Full",
      "support": 15,
      "rotation": 4
    },
    {
      "x": -1,
      "y": 14,
      "z": -2,
      "name": "Plant_Leaves_Crystal",
      "support": 15
    },
    {
      "x": -1,
      "y": 15,
      "z": -2,
      "name": "Rock_Stone"
    },
    {
      "x": -1,
      "y": 16,
      "z": -2,
      "name": "Soil_Dirt"
    },
    {
      "x": -1,
      "y": 17,
      "z": -2,
      "name": "Soil_Grass"
    },
    {
      "x": -1,
      "y": 0,
      "z": -1,
      "name": "Soil_Dirt"
    },
    {
      "x": -1,
      "y": 1,
      "z": -1,
      "name": "Wood_Crystal_Trunk_Full",
      "support": 15,
      "rotation": 5
    },
    {
      "x": -1,
      "y": 2,
      "z": -1,
      "name": "Wood_Crystal_Trunk_Full",
      "support": 15,
      "rotation": 5
    },
    {
      "x": -1,
      "y": 3,
      "z": -1,
      "name": "Wood_Crystal_Trunk_Full",
      "support": 15,
      "rotation": 5
    },
    {
      "x": -1,
      "y": 13,
      "z": -1,
      "name": "Plant_Leaves_Crystal",
      "support": 15
    },
    {
      "x": -1,
      "y": 14,
      "z": -1,
      "name": "Wood_Crystal_Trunk_Full",
      "support": 15,
      "rotation": 5
    },
    {
      "x": -1,
      "y": 15,
      "z": -1,
      "name": "Rock_Stone"
    },
    {
      "x": -1,
      "y": 16,
      "z": -1,
      "name": "Soil_Dirt"
    },
    {
      "x": -1,
      "y": 17,
      "z": -1,
      "name": "Soil_Grass"
    },
    {
      "x": -1,
      "y": 0,
      "z": 0,
      "name": "Soil_Dirt"
    },
    {
      "x": -1,
      "y": 1,
      "z": 0,
      "name": "Wood_Crystal_Trunk_Full",
      "support": 15
    },
    {
      "x": -1,
      "y": 2,
      "z": 0,
      "name": "Wood_Crystal_Trunk_Full",
      "support": 15,
      "rotation": 5
    },
    {
      "x": -1,
      "y": 3,
      "z": 0,
      "name": "Wood_Crystal_Trunk_Full",
      "support": 15,
      "rotation": 5
    },
    {
      "x": -1,
      "y": 4,
      "z": 0,
      "name": "Wood_Crystal_Trunk_Full",
      "support": 15,
      "rotation": 5
    },
    {
      "x": -1,
      "y": 5,
      "z": 0,
      "name": "Wood_Crystal_Trunk_Full",
      "support": 15,
      "rotation": 5
    },
    {
      "x": -1,
      "y": 6,
      "z": 0,
      "name": "Wood_Crystal_Trunk_Full",
      "support": 15,
      "rotation": 4
    },
    {
      "x": -1,
      "y": 7,
      "z": 0,
      "name": "Wood_Crystal_Trunk_Full",
      "support": 15,
      "rotation": 4
    },
    {
      "x": -1,
      "y": 8,
      "z": 0,
      "name": "Wood_Crystal_Trunk_Full",
      "support": 15
    },
    {
      "x": -1,
      "y": 9,
      "z": 0,
      "name": "Wood_Crystal_Trunk_Full",
      "support": 15
    },
    {
      "x": -1,
      "y": 10,
      "z": 0,
      "name": "Wood_Crystal_Trunk_Full",
      "support": 15
    },
    {
      "x": -1,
      "y": 13,
      "z": 0,
      "name": "Plant_Leaves_Crystal",
      "support": 15
    },
    {
      "x": -1,
      "y": 14,
      "z": 0,
      "name": "Wood_Crystal_Trunk_Full",
      "support": 15,
      "rotation": 4
    },
    {
      "x": -1,
      "y": 15,
      "z": 0,
      "name": "Rock_Stone"
    },
    {
      "x": -1,
      "y": 16,
      "z": 0,
      "name": "Soil_Dirt"
    },
    {
      "x": -1,
      "y": 17,
      "z": 0,
      "name": "Soil_Grass"
    },
    {
      "x": -1,
      "y": 0,
      "z": 1,
      "name": "Soil_Grass"
    },
    {
      "x": -1,
      "y": 1,
      "z": 1,
      "name": "Wood_Crystal_Trunk_Full",
      "support": 15,
      "rotation": 5
    },
    {
      "x": -1,
      "y": 2,
      "z": 1,
      "name": "Wood_Crystal_Trunk_Full",
      "support": 15,
      "rotation": 5
    },
    {
      "x": -1,
      "y": 3,
      "z": 1,
      "name": "Wood_Crystal_Trunk_Full",
      "support": 15,
      "rotation": 4
    },
    {
      "x": -1,
      "y": 6,
      "z": 1,
      "name": "Wood_Crystal_Trunk_Full",
      "support": 15,
      "rotation": 5
    },
    {
      "x": -1,
      "y": 7,
      "z": 1,
      "name": "Wood_Crystal_Trunk_Full",
      "support": 15
    },
    {
      "x": -1,
      "y": 8,
      "z": 1,
      "name": "Wood_Crystal_Trunk_Full",
      "support": 15
    },
    {
      "x": -1,
      "y": 14,
      "z": 1,
      "name": "Plant_Leaves_Crystal",
      "support": 15
    },
    {
      "x": -1,
      "y": 15,
      "z": 1,
      "name": "Soil_Dirt"
    },
    {
      "x": -1,
      "y": 16,
      "z": 1,
      "name": "Soil_Dirt"
    },
    {
      "x": -1,
      "y": 17,
      "z": 1,
      "name": "Soil_Grass"
    },
    {
      "x": -1,
      "y": 0,
      "z": 2,
      "name": "Soil_Grass"
    },
    {
      "x": -1,
      "y": 1,
      "z": 2,
      "name": "Plant_Grass_Jungle_Tall"
    },
    {
      "x": -1,
      "y": 14,
      "z": 2,
      "name": "Plant_Leaves_Crystal",
      "support": 15
    },
    {
      "x": -1,
      "y": 15,
      "z": 2,
      "name": "Soil_Dirt"
    },
    {
      "x": -1,
      "y": 16,
      "z": 2,
      "name": "Soil_Dirt"
    },
    {
      "x": -1,
      "y": 17,
      "z": 2,
      "name": "Soil_Grass"
    },
    {
      "x": -1,
      "y": 0,
      "z": 3,
      "name": "Soil_Grass"
    },
    {
      "x": -1,
      "y": 14,
      "z": 3,
      "name": "Plant_Leaves_Crystal",
      "support": 15
    },
    {
      "x": -1,
      "y": 15,
      "z": 3,
      "name": "Plant_Leaves_Crystal",
      "support": 15
    },
    {
      "x": -1,
      "y": 16,
      "z": 3,
      "name": "Soil_Dirt"
    },
    {
      "x": -1,
      "y": 17,
      "z": 3,
      "name": "Soil_Grass"
    },
    {
      "x": -1,
      "y": 0,
      "z": 4,
      "name": "Soil_Grass"
    },
    {
      "x": -1,
      "y": 15,
      "z": 4,
      "name": "Plant_Leaves_Crystal",
      "support": 15
    },
    {
      "x": -1,
      "y": 16,
      "z": 4,
      "name": "Plant_Leaves_Crystal",
      "support": 15
    },
    {
      "x": -1,
      "y": 17,
      "z": 4,
      "name": "Plant_Leaves_Crystal",
      "support": 15
    },
    {
      "x": -1,
      "y": 0,
      "z": 5,
      "name": "Soil_Grass"
    },
    {
      "x": -1,
      "y": 0,
      "z": 6,
      "name": "Soil_Grass"
    },
    {
      "x": -1,
      "y": 0,
      "z": 7,
      "name": "Soil_Grass"
    },
    {
      "x": 0,
      "y": 0,
      "z": -7,
      "name": "Soil_Grass"
    },
    {
      "x": 0,
      "y": 0,
      "z": -6,
      "name": "Soil_Grass"
    },
    {
      "x": 0,
      "y": 13,
      "z": -6,
      "name": "Plant_Leaves_Crystal",
      "support": 15
    },
    {
      "x": 0,
      "y": 0,
      "z": -5,
      "name": "Soil_Grass"
    },
    {
      "x": 0,
      "y": 11,
      "z": -5,
      "name": "Plant_Leaves_Crystal",
      "support": 15
    },
    {
      "x": 0,
      "y": 12,
      "z": -5,
      "name": "Plant_Leaves_Crystal",
      "support": 15
    },
    {
      "x": 0,
      "y": 13,
      "z": -5,
      "name": "Plant_Leaves_Crystal",
      "support": 15
    },
    {
      "x": 0,
      "y": 14,
      "z": -5,
      "name": "Plant_Leaves_Crystal",
      "support": 15
    },
    {
      "x": 0,
      "y": 15,
      "z": -5,
      "name": "Plant_Leaves_Crystal",
      "support": 15
    },
    {
      "x": 0,
      "y": 16,
      "z": -5,
      "name": "Plant_Leaves_Crystal",
      "support": 15
    },
    {
      "x": 0,
      "y": 17,
      "z": -5,
      "name": "Plant_Leaves_Crystal",
      "support": 15
    },
    {
      "x": 0,
      "y": 0,
      "z": -4,
      "name": "Soil_Grass"
    },
    {
      "x": 0,
      "y": 15,
      "z": -4,
      "name": "Plant_Leaves_Crystal",
      "support": 15
    },
    {
      "x": 0,
      "y": 16,
      "z": -4,
      "name": "Soil_Grass"
    },
    {
      "x": 0,
      "y": 17,
      "z": -4,
      "name": "Plant_Leaves_Crystal",
      "support": 15
    },
    {
      "x": 0,
      "y": 0,
      "z": -3,
      "name": "Soil_Dirt"
    },
    {
      "x": 0,
      "y": 1,
      "z": -3,
      "name": "Wood_Crystal_Trunk_Full",
      "support": 15
    },
    {
      "x": 0,
      "y": 15,
      "z": -3,
      "name": "Ore_Iron_Stone"
    },
    {
      "x": 0,
      "y": 16,
      "z": -3,
      "name": "Soil_Dirt"
    },
    {
      "x": 0,
      "y": 17,
      "z": -3,
      "name": "Soil_Grass"
    },
    {
      "x": 0,
      "y": 0,
      "z": -2,
      "name": "Soil_Dirt"
    },
    {
      "x": 0,
      "y": 1,
      "z": -2,
      "name": "Wood_Crystal_Trunk_Full",
      "support": 15
    },
    {
      "x": 0,
      "y": 2,
      "z": -2,
      "name": "Wood_Crystal_Trunk_Full",
      "support": 15,
      "rotation": 4
    },
    {
      "x": 0,
      "y": 12,
      "z": -2,
      "name": "Plant_Leaves_Crystal",
      "support": 15
    },
    {
      "x": 0,
      "y": 13,
      "z": -2,
      "name": "Plant_Leaves_Crystal",
      "support": 15
    },
    {
      "x": 0,
      "y": 14,
      "z": -2,
      "name": "Plant_Leaves_Crystal",
      "support": 15
    },
    {
      "x": 0,
      "y": 15,
      "z": -2,
      "name": "Rock_Stone"
    },
    {
      "x": 0,
      "y": 16,
      "z": -2,
      "name": "Soil_Dirt"
    },
    {
      "x": 0,
      "y": 17,
      "z": -2,
      "name": "Soil_Grass"
    },
    {
      "x": 0,
      "y": 0,
      "z": -1,
      "name": "Soil_Dirt"
    },
    {
      "x": 0,
      "y": 1,
      "z": -1,
      "name": "Wood_Crystal_Trunk_Full",
      "support": 15,
      "rotation": 4
    },
    {
      "x": 0,
      "y": 2,
      "z": -1,
      "name": "Wood_Crystal_Trunk_Full",
      "support": 15,
      "rotation": 4
    },
    {
      "x": 0,
      "y": 3,
      "z": -1,
      "name": "Wood_Crystal_Trunk_Full",
      "support": 15
    },
    {
      "x": 0,
      "y": 8,
      "z": -1,
      "name": "Wood_Crystal_Trunk_Full",
      "support": 15,
      "rotation": 4
    },
    {
      "x": 0,
      "y": 9,
      "z": -1,
      "name": "Wood_Crystal_Trunk_Full",
      "support": 15,
      "rotation": 4
    },
    {
      "x": 0,
      "y": 10,
      "z": -1,
      "name": "Wood_Crystal_Trunk_Full",
      "support": 15,
      "rotation": 4
    },
    {
      "x": 0,
      "y": 11,
      "z": -1,
      "name": "Wood_Crystal_Trunk_Full",
      "support": 15,
      "rotation": 4
    },
    {
      "x": 0,
      "y": 12,
      "z": -1,
      "name": "Wood_Crystal_Trunk_Full",
      "support": 15,
      "rotation": 4
    },
    {
      "x": 0,
      "y": 13,
      "z": -1,
      "name": "Plant_Leaves_Crystal",
      "support": 15
    },
    {
      "x": 0,
      "y": 14,
      "z": -1,
      "name": "Wood_Crystal_Trunk_Full",
      "support": 15,
      "rotation": 5
    },
    {
      "x": 0,
      "y": 15,
      "z": -1,
      "name": "Rock_Stone"
    },
    {
      "x": 0,
      "y": 16,
      "z": -1,
      "name": "Soil_Dirt"
    },
    {
      "x": 0,
      "y": 17,
      "z": -1,
      "name": "Soil_Grass"
    },
    {
      "x": 0,
      "y": 0,
      "z": 0,
      "name": "Soil_Dirt"
    },
    {
      "x": 0,
      "y": 1,
      "z": 0,
      "name": "Wood_Crystal_Trunk_Full",
      "support": 15
    },
    {
      "x": 0,
      "y": 2,
      "z": 0,
      "name": "Wood_Crystal_Trunk_Full",
      "support": 15
    },
    {
      "x": 0,
      "y": 3,
      "z": 0,
      "name": "Wood_Crystal_Trunk_Full",
      "support": 15,
      "rotation": 4
    },
    {
      "x": 0,
      "y": 6,
      "z": 0,
      "name": "Wood_Crystal_Trunk_Full",
      "support": 15
    },
    {
      "x": 0,
      "y": 7,
      "z": 0,
      "name": "Wood_Crystal_Trunk_Full",
      "support": 15,
      "rotation": 4
    },
    {
      "x": 0,
      "y": 8,
      "z": 0,
      "name": "Wood_Crystal_Trunk_Full",
      "support": 15,
      "rotation": 5
    },
    {
      "x": 0,
      "y": 9,
      "z": 0,
      "name": "Wood_Crystal_Trunk_Full",
      "support": 15,
      "rotation": 5
    },
    {
      "x": 0,
      "y": 10,
      "z": 0,
      "name": "Wood_Crystal_Trunk_Full",
      "support": 15,
      "rotation": 4
    },
    {
      "x": 0,
      "y": 11,
      "z": 0,
      "name": "Wood_Crystal_Trunk_Full",
      "support": 15
    },
    {
      "x": 0,
      "y": 12,
      "z": 0,
      "name": "Wood_Crystal_Trunk_Full",
      "support": 15
    },
    {
      "x": 0,
      "y": 13,
      "z": 0,
      "name": "Wood_Crystal_Trunk_Full",
      "support": 15
    },
    {
      "x": 0,
      "y": 14,
      "z": 0,
      "name": "Rock_Stone"
    },
    {
      "x": 0,
      "y": 15,
      "z": 0,
      "name": "Soil_Dirt"
    },
    {
      "x": 0,
      "y": 16,
      "z": 0,
      "name": "Soil_Dirt"
    },
    {
      "x": 0,
      "y": 17,
      "z": 0,
      "name": "Soil_Grass"
    },
    {
      "x": 0,
      "y": 0,
      "z": 1,
      "name": "Soil_Dirt"
    },
    {
      "x": 0,
      "y": 1,
      "z": 1,
      "name": "Wood_Crystal_Trunk_Full",
      "support": 15
    },
    {
      "x": 0,
      "y": 2,
      "z": 1,
      "name": "Wood_Crystal_Trunk_Full",
      "support": 15
    },
    {
      "x": 0,
      "y": 3,
      "z": 1,
      "name": "Wood_Crystal_Trunk_Full",
      "support": 15
    },
    {
      "x": 0,
      "y": 4,
      "z": 1,
      "name": "Wood_Crystal_Trunk_Full",
      "support": 15
    },
    {
      "x": 0,
      "y": 5,
      "z": 1,
      "name": "Wood_Crystal_Trunk_Full",
      "support": 15
    },
    {
      "x": 0,
      "y": 6,
      "z": 1,
      "name": "Wood_Crystal_Trunk_Full",
      "support": 15,
      "rotation": 4
    },
    {
      "x": 0,
      "y": 8,
      "z": 1,
      "name": "Wood_Crystal_Trunk_Full",
      "support": 15
    },
    {
      "x": 0,
      "y": 9,
      "z": 1,
      "name": "Wood_Crystal_Trunk_Full",
      "support": 15
    },
    {
      "x": 0,
      "y": 10,
      "z": 1,
      "name": "Wood_Crystal_Trunk_Full",
      "support": 15
    },
    {
      "x": 0,
      "y": 11,
      "z": 1,
      "name": "Wood_Crystal_Trunk_Full",
      "support": 15,
      "rotation": 4
    },
    {
      "x": 0,
      "y": 12,
      "z": 1,
      "name": "Wood_Crystal_Trunk_Full",
      "support": 15,
      "rotation": 4
    },
    {
      "x": 0,
      "y": 13,
      "z": 1,
      "name": "Wood_Crystal_Trunk_Full",
      "support": 15,
      "rotation": 4
    },
    {
      "x": 0,
      "y": 14,
      "z": 1,
      "name": "Rock_Stone"
    },
    {
      "x": 0,
      "y": 15,
      "z": 1,
      "name": "Soil_Dirt"
    },
    {
      "x": 0,
      "y": 16,
      "z": 1,
      "name": "Soil_Dirt"
    },
    {
      "x": 0,
      "y": 17,
      "z": 1,
      "name": "Soil_Grass"
    },
    {
      "x": 0,
      "y": 18,
      "z": 1,
      "name": "Plant_Grass_Lush",
      "support": 15
    },
    {
      "x": 0,
      "y": 0,
      "z": 2,
      "name": "Soil_Grass"
    },
    {
      "x": 0,
      "y": 1,
      "z": 2,
      "name": "Plant_Grass_Lush_Tall",
      "support": 15
    },
    {
      "x": 0,
      "y": 13,
      "z": 2,
      "name": "Plant_Leaves_Crystal",
      "support": 15
    },
    {
      "x": 0,
      "y": 14,
      "z": 2,
      "name": "Plant_Leaves_Crystal",
      "support": 15
    },
    {
      "x": 0,
      "y": 15,
      "z": 2,
      "name": "Soil_Dirt"
    },
    {
      "x": 0,
      "y": 16,
      "z": 2,
      "name": "Soil_Dirt"
    },
    {
      "x": 0,
      "y": 17,
      "z": 2,
      "name": "Soil_Grass"
    },
    {
      "x": 0,
      "y": 0,
      "z": 3,
      "name": "Soil_Grass"
    },
    {
      "x": 0,
      "y": 13,
      "z": 3,
      "name": "Plant_Leaves_Crystal",
      "support": 15
    },
    {
      "x": 0,
      "y": 14,
      "z": 3,
      "name": "Plant_Leaves_Crystal",
      "support": 15
    },
    {
      "x": 0,
      "y": 15,
      "z": 3,
      "name": "Plant_Leaves_Crystal",
      "support": 15
    },
    {
      "x": 0,
      "y": 16,
      "z": 3,
      "name": "Soil_Dirt"
    },
    {
      "x": 0,
      "y": 17,
      "z": 3,
      "name": "Soil_Grass"
    },
    {
      "x": 0,
      "y": 18,
      "z": 3,
      "name": "Plant_Grass_Lush",
      "support": 15
    },
    {
      "x": 0,
      "y": 0,
      "z": 4,
      "name": "Soil_Grass"
    },
    {
      "x": 0,
      "y": 1,
      "z": 4,
      "name": "Plant_Grass_Sharp",
      "rotation": 3
    },
    {
      "x": 0,
      "y": 14,
      "z": 4,
      "name": "Plant_Leaves_Crystal",
      "support": 15
    },
    {
      "x": 0,
      "y": 15,
      "z": 4,
      "name": "Plant_Leaves_Crystal",
      "support": 15
    },
    {
      "x": 0,
      "y": 16,
      "z": 4,
      "name": "Soil_Grass"
    },
    {
      "x": 0,
      "y": 17,
      "z": 4,
      "name": "Plant_Leaves_Crystal",
      "support": 15
    },
    {
      "x": 0,
      "y": 0,
      "z": 5,
      "name": "Soil_Grass"
    },
    {
      "x": 0,
      "y": 11,
      "z": 5,
      "name": "Plant_Leaves_Crystal",
      "support": 15
    },
    {
      "x": 0,
      "y": 12,
      "z": 5,
      "name": "Plant_Leaves_Crystal",
      "support": 15
    },
    {
      "x": 0,
      "y": 13,
      "z": 5,
      "name": "Plant_Leaves_Crystal",
      "support": 15
    },
    {
      "x": 0,
      "y": 14,
      "z": 5,
      "name": "Plant_Leaves_Crystal",
      "support": 15
    },
    {
      "x": 0,
      "y": 16,
      "z": 5,
      "name": "Plant_Leaves_Crystal",
      "support": 15
    },
    {
      "x": 0,
      "y": 0,
      "z": 6,
      "name": "Soil_Grass"
    },
    {
      "x": 0,
      "y": 0,
      "z": 7,
      "name": "Soil_Grass"
    },
    {
      "x": 1,
      "y": 0,
      "z": -7,
      "name": "Soil_Grass"
    },
    {
      "x": 1,
      "y": 1,
      "z": -7,
      "name": "Plant_Grass_Lush"
    },
    {
      "x": 1,
      "y": 0,
      "z": -6,
      "name": "Soil_Grass"
    },
    {
      "x": 1,
      "y": 1,
      "z": -6,
      "name": "Plant_Grass_Jungle",
      "support": 15
    },
    {
      "x": 1,
      "y": 0,
      "z": -5,
      "name": "Soil_Grass"
    },
    {
      "x": 1,
      "y": 0,
      "z": -4,
      "name": "Soil_Grass"
    },
    {
      "x": 1,
      "y": 15,
      "z": -4,
      "name": "Plant_Leaves_Crystal",
      "support": 15
    },
    {
      "x": 1,
      "y": 17,
      "z": -4,
      "name": "Plant_Leaves_Crystal",
      "support": 15
    },
    {
      "x": 1,
      "y": 0,
      "z": -3,
      "name": "Soil_Grass"
    },
    {
      "x": 1,
      "y": 13,
      "z": -3,
      "name": "Plant_Leaves_Crystal",
      "support": 15
    },
    {
      "x": 1,
      "y": 14,
      "z": -3,
      "name": "Plant_Leaves_Crystal",
      "support": 15
    },
    {
      "x": 1,
      "y": 15,
      "z": -3,
      "name": "Rock_Stone"
    },
    {
      "x": 1,
      "y": 16,
      "z": -3,
      "name": "Soil_Dirt"
    },
    {
      "x": 1,
      "y": 17,
      "z": -3,
      "name": "Soil_Grass"
    },
    {
      "x": 1,
      "y": 0,
      "z": -2,
      "name": "Soil_Dirt"
    },
    {
      "x": 1,
      "y": 1,
      "z": -2,
      "name": "Wood_Crystal_Trunk_Full",
      "support": 15,
      "rotation": 4
    },
    {
      "x": 1,
      "y": 13,
      "z": -2,
      "name": "Plant_Leaves_Crystal",
      "support": 15
    },
    {
      "x": 1,
      "y": 14,
      "z": -2,
      "name": "Plant_Leaves_Crystal",
      "support": 15
    },
    {
      "x": 1,
      "y": 15,
      "z": -2,
      "name": "Rock_Stone"
    },
    {
      "x": 1,
      "y": 16,
      "z": -2,
      "name": "Soil_Clay_Smooth_Purple"
    },
    {
      "x": 1,
      "y": 17,
      "z": -2,
      "name": "Soil_Grass"
    },
    {
      "x": 1,
      "y": 18,
      "z": -2,
      "name": "Plant_Grass_Lush",
      "support": 15
    },
    {
      "x": 1,
      "y": 0,
      "z": -1,
      "name": "Soil_Grass"
    },
    {
      "x": 1,
      "y": 1,
      "z": -1,
      "name": "Wood_Crystal_Trunk_Full",
      "support": 15
    },
    {
      "x": 1,
      "y": 13,
      "z": -1,
      "name": "Wood_Crystal_Trunk_Full",
      "support": 15,
      "rotation": 4
    },
    {
      "x": 1,
      "y": 14,
      "z": -1,
      "name": "Wood_Crystal_Trunk_Full",
      "support": 15,
      "rotation": 4
    },
    {
      "x": 1,
      "y": 15,
      "z": -1,
      "name": "Rock_Stone"
    },
    {
      "x": 1,
      "y": 16,
      "z": -1,
      "name": "Soil_Clay_Smooth_Purple"
    },
    {
      "x": 1,
      "y": 17,
      "z": -1,
      "name": "Soil_Grass"
    },
    {
      "x": 1,
      "y": 18,
      "z": -1,
      "name": "Plant_Grass_Lush",
      "support": 15
    },
    {
      "x": 1,
      "y": 0,
      "z": 0,
      "name": "Soil_Dirt"
    },
    {
      "x": 1,
      "y": 1,
      "z": 0,
      "name": "Wood_Crystal_Trunk_Full",
      "support": 15
    },
    {
      "x": 1,
      "y": 2,
      "z": 0,
      "name": "Wood_Crystal_Trunk_Full",
      "support": 15,
      "rotation": 5
    },
    {
      "x": 1,
      "y": 11,
      "z": 0,
      "name": "Wood_Crystal_Trunk_Full",
      "support": 15,
      "rotation": 5
    },
    {
      "x": 1,
      "y": 12,
      "z": 0,
      "name": "Wood_Crystal_Trunk_Full",
      "support": 15,
      "rotation": 5
    },
    {
      "x": 1,
      "y": 13,
      "z": 0,
      "name": "Wood_Crystal_Trunk_Full",
      "support": 15,
      "rotation": 5
    },
    {
      "x": 1,
      "y": 14,
      "z": 0,
      "name": "Rock_Stone"
    },
    {
      "x": 1,
      "y": 15,
      "z": 0,
      "name": "Soil_Dirt"
    },
    {
      "x": 1,
      "y": 16,
      "z": 0,
      "name": "Soil_Dirt"
    },
    {
      "x": 1,
      "y": 17,
      "z": 0,
      "name": "Soil_Grass"
    },
    {
      "x": 1,
      "y": 0,
      "z": 1,
      "name": "Soil_Dirt"
    },
    {
      "x": 1,
      "y": 1,
      "z": 1,
      "name": "Wood_Crystal_Trunk_Full",
      "support": 15
    },
    {
      "x": 1,
      "y": 13,
      "z": 1,
      "name": "Plant_Leaves_Crystal",
      "support": 15
    },
    {
      "x": 1,
      "y": 14,
      "z": 1,
      "name": "Rock_Stone"
    },
    {
      "x": 1,
      "y": 15,
      "z": 1,
      "name": "Soil_Dirt"
    },
    {
      "x": 1,
      "y": 16,
      "z": 1,
      "name": "Soil_Dirt"
    },
    {
      "x": 1,
      "y": 17,
      "z": 1,
      "name": "Soil_Grass"
    },
    {
      "x": 1,
      "y": 0,
      "z": 2,
      "name": "Soil_Grass"
    },
    {
      "x": 1,
      "y": 13,
      "z": 2,
      "name": "Plant_Leaves_Crystal",
      "support": 15
    },
    {
      "x": 1,
      "y": 14,
      "z": 2,
      "name": "Plant_Leaves_Crystal",
      "support": 15
    },
    {
      "x": 1,
      "y": 15,
      "z": 2,
      "name": "Soil_Dirt"
    },
    {
      "x": 1,
      "y": 16,
      "z": 2,
      "name": "Soil_Dirt"
    },
    {
      "x": 1,
      "y": 17,
      "z": 2,
      "name": "Soil_Grass"
    },
    {
      "x": 1,
      "y": 0,
      "z": 3,
      "name": "Soil_Grass"
    },
    {
      "x": 1,
      "y": 1,
      "z": 3,
      "name": "Plant_Grass_Sharp",
      "rotation": 1
    },
    {
      "x": 1,
      "y": 15,
      "z": 3,
      "name": "Soil_Dirt"
    },
    {
      "x": 1,
      "y": 16,
      "z": 3,
      "name": "Soil_Dirt"
    },
    {
      "x": 1,
      "y": 17,
      "z": 3,
      "name": "Soil_Grass"
    },
    {
      "x": 1,
      "y": 0,
      "z": 4,
      "name": "Soil_Grass"
    },
    {
      "x": 1,
      "y": 13,
      "z": 4,
      "name": "Plant_Leaves_Crystal",
      "support": 15
    },
    {
      "x": 1,
      "y": 15,
      "z": 4,
      "name": "Plant_Leaves_Crystal",
      "support": 15
    },
    {
      "x": 1,
      "y": 16,
      "z": 4,
      "name": "Soil_Grass"
    },
    {
      "x": 1,
      "y": 17,
      "z": 4,
      "name": "Plant_Leaves_Crystal",
      "support": 15
    },
    {
      "x": 1,
      "y": 0,
      "z": 5,
      "name": "Soil_Grass"
    },
    {
      "x": 1,
      "y": 1,
      "z": 5,
      "name": "Plant_Grass_Lush",
      "rotation": 2
    },
    {
      "x": 1,
      "y": 16,
      "z": 5,
      "name": "Plant_Leaves_Crystal",
      "support": 15
    },
    {
      "x": 1,
      "y": 0,
      "z": 6,
      "name": "Soil_Grass"
    },
    {
      "x": 1,
      "y": 1,
      "z": 6,
      "name": "Plant_Grass_Jungle_Tall",
      "support": 15
    },
    {
      "x": 1,
      "y": 0,
      "z": 7,
      "name": "Soil_Grass"
    },
    {
      "x": 2,
      "y": 0,
      "z": -7,
      "name": "Soil_Grass"
    },
    {
      "x": 2,
      "y": 0,
      "z": -6,
      "name": "Soil_Grass"
    },
    {
      "x": 2,
      "y": 0,
      "z": -5,
      "name": "Soil_Grass"
    },
    {
      "x": 2,
      "y": 15,
      "z": -5,
      "name": "Plant_Leaves_Crystal",
      "support": 15
    },
    {
      "x": 2,
      "y": 0,
      "z": -4,
      "name": "Soil_Grass"
    },
    {
      "x": 2,
      "y": 1,
      "z": -4,
      "name": "Plant_Grass_Jungle",
      "support": 15
    },
    {
      "x": 2,
      "y": 14,
      "z": -4,
      "name": "Plant_Leaves_Crystal",
      "support": 15
    },
    {
      "x": 2,
      "y": 15,
      "z": -4,
      "name": "Plant_Leaves_Crystal",
      "support": 15
    },
    {
      "x": 2,
      "y": 16,
      "z": -4,
      "name": "Plant_Leaves_Crystal",
      "support": 15
    },
    {
      "x": 2,
      "y": 17,
      "z": -4,
      "name": "Plant_Leaves_Crystal",
      "support": 15
    },
    {
      "x": 2,
      "y": 0,
      "z": -3,
      "name": "Soil_Grass"
    },
    {
      "x": 2,
      "y": 13,
      "z": -3,
      "name": "Plant_Leaves_Crystal",
      "support": 15
    },
    {
      "x": 2,
      "y": 15,
      "z": -3,
      "name": "Plant_Leaves_Crystal",
      "support": 15
    },
    {
      "x": 2,
      "y": 16,
      "z": -3,
      "name": "Soil_Dirt"
    },
    {
      "x": 2,
      "y": 17,
      "z": -3,
      "name": "Soil_Grass"
    },
    {
      "x": 2,
      "y": 0,
      "z": -2,
      "name": "Soil_Grass"
    },
    {
      "x": 2,
      "y": 13,
      "z": -2,
      "name": "Plant_Leaves_Crystal",
      "support": 15
    },
    {
      "x": 2,
      "y": 14,
      "z": -2,
      "name": "Plant_Leaves_Crystal",
      "support": 15
    },
    {
      "x": 2,
      "y": 15,
      "z": -2,
      "name": "Rock_Stone"
    },
    {
      "x": 2,
      "y": 16,
      "z": -2,
      "name": "Soil_Clay_Smooth_Purple"
    },
    {
      "x": 2,
      "y": 17,
      "z": -2,
      "name": "Soil_Grass"
    },
    {
      "x": 2,
      "y": 0,
      "z": -1,
      "name": "Soil_Dirt"
    },
    {
      "x": 2,
      "y": 1,
      "z": -1,
      "name": "Wood_Crystal_Trunk_Full",
      "support": 15,
      "rotation": 5
    },
    {
      "x": 2,
      "y": 13,
      "z": -1,
      "name": "Plant_Leaves_Crystal",
      "support": 15
    },
    {
      "x": 2,
      "y": 14,
      "z": -1,
      "name": "Plant_Leaves_Crystal",
      "support": 15
    },
    {
      "x": 2,
      "y": 15,
      "z": -1,
      "name": "Rock_Stone"
    },
    {
      "x": 2,
      "y": 16,
      "z": -1,
      "name": "Soil_Clay_Smooth_Purple"
    },
    {
      "x": 2,
      "y": 17,
      "z": -1,
      "name": "Soil_Grass"
    },
    {
      "x": 2,
      "y": 0,
      "z": 0,
      "name": "Soil_Grass"
    },
    {
      "x": 2,
      "y": 12,
      "z": 0,
      "name": "Plant_Leaves_Crystal",
      "support": 15
    },
    {
      "x": 2,
      "y": 13,
      "z": 0,
      "name": "Plant_Leaves_Crystal",
      "support": 15
    },
    {
      "x": 2,
      "y": 14,
      "z": 0,
      "name": "Rock_Stone"
    },
    {
      "x": 2,
      "y": 15,
      "z": 0,
      "name": "Soil_Dirt"
    },
    {
      "x": 2,
      "y": 16,
      "z": 0,
      "name": "Soil_Dirt"
    },
    {
      "x": 2,
      "y": 17,
      "z": 0,
      "name": "Soil_Grass"
    },
    {
      "x": 2,
      "y": 0,
      "z": 1,
      "name": "Soil_Grass"
    },
    {
      "x": 2,
      "y": 13,
      "z": 1,
      "name": "Plant_Leaves_Crystal",
      "support": 15
    },
    {
      "x": 2,
      "y": 14,
      "z": 1,
      "name": "Plant_Leaves_Crystal",
      "support": 15
    },
    {
      "x": 2,
      "y": 15,
      "z": 1,
      "name": "Soil_Dirt"
    },
    {
      "x": 2,
      "y": 16,
      "z": 1,
      "name": "Soil_Dirt"
    },
    {
      "x": 2,
      "y": 17,
      "z": 1,
      "name": "Soil_Grass"
    },
    {
      "x": 2,
      "y": 0,
      "z": 2,
      "name": "Soil_Grass"
    },
    {
      "x": 2,
      "y": 1,
      "z": 2,
      "name": "Plant_Grass_Lush_Tall",
      "support": 15
    },
    {
      "x": 2,
      "y": 13,
      "z": 2,
      "name": "Plant_Leaves_Crystal",
      "support": 15
    },
    {
      "x": 2,
      "y": 14,
      "z": 2,
      "name": "Plant_Leaves_Crystal",
      "support": 15
    },
    {
      "x": 2,
      "y": 15,
      "z": 2,
      "name": "Soil_Dirt"
    },
    {
      "x": 2,
      "y": 16,
      "z": 2,
      "name": "Soil_Dirt"
    },
    {
      "x": 2,
      "y": 17,
      "z": 2,
      "name": "Soil_Grass"
    },
    {
      "x": 2,
      "y": 18,
      "z": 2,
      "name": "Plant_Grass_Lush",
      "support": 15
    },
    {
      "x": 2,
      "y": 0,
      "z": 3,
      "name": "Soil_Grass"
    },
    {
      "x": 2,
      "y": 13,
      "z": 3,
      "name": "Plant_Leaves_Crystal",
      "support": 15
    },
    {
      "x": 2,
      "y": 15,
      "z": 3,
      "name": "Soil_Dirt"
    },
    {
      "x": 2,
      "y": 16,
      "z": 3,
      "name": "Soil_Dirt"
    },
    {
      "x": 2,
      "y": 17,
      "z": 3,
      "name": "Soil_Grass"
    },
    {
      "x": 2,
      "y": 0,
      "z": 4,
      "name": "Soil_Grass"
    },
    {
      "x": 2,
      "y": 1,
      "z": 4,
      "name": "Plant_Grass_Lush",
      "support": 15
    },
    {
      "x": 2,
      "y": 13,
      "z": 4,
      "name": "Plant_Leaves_Crystal",
      "support": 15
    },
    {
      "x": 2,
      "y": 14,
      "z": 4,
      "name": "Plant_Leaves_Crystal",
      "support": 15
    },
    {
      "x": 2,
      "y": 15,
      "z": 4,
      "name": "Plant_Leaves_Crystal",
      "support": 15
    },
    {
      "x": 2,
      "y": 16,
      "z": 4,
      "name": "Plant_Leaves_Crystal",
      "support": 15
    },
    {
      "x": 2,
      "y": 17,
      "z": 4,
      "name": "Plant_Leaves_Crystal",
      "support": 15
    },
    {
      "x": 2,
      "y": 0,
      "z": 5,
      "name": "Soil_Grass"
    },
    {
      "x": 2,
      "y": 14,
      "z": 5,
      "name": "Plant_Leaves_Crystal",
      "support": 15
    },
    {
      "x": 2,
      "y": 15,
      "z": 5,
      "name": "Plant_Leaves_Crystal",
      "support": 15
    },
    {
      "x": 2,
      "y": 16,
      "z": 5,
      "name": "Plant_Leaves_Crystal",
      "support": 15
    },
    {
      "x": 2,
      "y": 0,
      "z": 6,
      "name": "Soil_Grass"
    },
    {
      "x": 2,
      "y": 14,
      "z": 6,
      "name": "Plant_Leaves_Crystal",
      "support": 15
    },
    {
      "x": 2,
      "y": 0,
      "z": 7,
      "name": "Soil_Grass"
    },
    {
      "x": 3,
      "y": 0,
      "z": -7,
      "name": "Soil_Grass"
    },
    {
      "x": 3,
      "y": 0,
      "z": -6,
      "name": "Soil_Grass"
    },
    {
      "x": 3,
      "y": 0,
      "z": -5,
      "name": "Soil_Grass"
    },
    {
      "x": 3,
      "y": 1,
      "z": -5,
      "name": "Plant_Grass_Lush",
      "support": 15
    },
    {
      "x": 3,
      "y": 0,
      "z": -4,
      "name": "Soil_Grass"
    },
    {
      "x": 3,
      "y": 16,
      "z": -4,
      "name": "Plant_Leaves_Crystal",
      "support": 15
    },
    {
      "x": 3,
      "y": 17,
      "z": -4,
      "name": "Plant_Leaves_Crystal",
      "support": 15
    },
    {
      "x": 3,
      "y": 0,
      "z": -3,
      "name": "Soil_Grass"
    },
    {
      "x": 3,
      "y": 1,
      "z": -3,
      "name": "Plant_Grass_Lush_Tall",
      "support": 15
    },
    {
      "x": 3,
      "y": 14,
      "z": -3,
      "name": "Plant_Leaves_Crystal",
      "support": 15
    },
    {
      "x": 3,
      "y": 15,
      "z": -3,
      "name": "Plant_Leaves_Crystal",
      "support": 15
    },
    {
      "x": 3,
      "y": 16,
      "z": -3,
      "name": "Soil_Dirt"
    },
    {
      "x": 3,
      "y": 17,
      "z": -3,
      "name": "Soil_Grass"
    },
    {
      "x": 3,
      "y": 18,
      "z": -3,
      "name": "Plant_Grass_Lush",
      "support": 15
    },
    {
      "x": 3,
      "y": 0,
      "z": -2,
      "name": "Soil_Grass"
    },
    {
      "x": 3,
      "y": 14,
      "z": -2,
      "name": "Plant_Leaves_Crystal",
      "support": 15
    },
    {
      "x": 3,
      "y": 15,
      "z": -2,
      "name": "Rock_Stone"
    },
    {
      "x": 3,
      "y": 16,
      "z": -2,
      "name": "Soil_Clay_Smooth_Purple"
    },
    {
      "x": 3,
      "y": 17,
      "z": -2,
      "name": "Soil_Grass"
    },
    {
      "x": 3,
      "y": 0,
      "z": -1,
      "name": "Soil_Grass"
    },
    {
      "x": 3,
      "y": 1,
      "z": -1,
      "name": "Plant_Grass_Lush_Tall",
      "support": 15
    },
    {
      "x": 3,
      "y": 14,
      "z": -1,
      "name": "Plant_Leaves_Crystal",
      "support": 15
    },
    {
      "x": 3,
      "y": 15,
      "z": -1,
      "name": "Ore_Iron_Stone"
    },
    {
      "x": 3,
      "y": 16,
      "z": -1,
      "name": "Soil_Clay_Smooth_Purple"
    },
    {
      "x": 3,
      "y": 17,
      "z": -1,
      "name": "Soil_Grass"
    },
    {
      "x": 3,
      "y": 18,
      "z": -1,
      "name": "Plant_Grass_Lush",
      "support": 15
    },
    {
      "x": 3,
      "y": 0,
      "z": 0,
      "name": "Soil_Grass"
    },
    {
      "x": 3,
      "y": 13,
      "z": 0,
      "name": "Plant_Leaves_Crystal",
      "support": 15
    },
    {
      "x": 3,
      "y": 14,
      "z": 0,
      "name": "Plant_Leaves_Crystal",
      "support": 15
    },
    {
      "x": 3,
      "y": 15,
      "z": 0,
      "name": "Rock_Stone"
    },
    {
      "x": 3,
      "y": 16,
      "z": 0,
      "name": "Soil_Clay_Smooth_Purple"
    },
    {
      "x": 3,
      "y": 17,
      "z": 0,
      "name": "Soil_Grass"
    },
    {
      "x": 3,
      "y": 0,
      "z": 1,
      "name": "Soil_Grass"
    },
    {
      "x": 3,
      "y": 12,
      "z": 1,
      "name": "Plant_Leaves_Crystal",
      "support": 15
    },
    {
      "x": 3,
      "y": 13,
      "z": 1,
      "name": "Plant_Leaves_Crystal",
      "support": 15
    },
    {
      "x": 3,
      "y": 14,
      "z": 1,
      "name": "Plant_Leaves_Crystal",
      "support": 15
    },
    {
      "x": 3,
      "y": 15,
      "z": 1,
      "name": "Soil_Dirt"
    },
    {
      "x": 3,
      "y": 16,
      "z": 1,
      "name": "Soil_Clay_Smooth_Purple"
    },
    {
      "x": 3,
      "y": 17,
      "z": 1,
      "name": "Soil_Grass"
    },
    {
      "x": 3,
      "y": 0,
      "z": 2,
      "name": "Soil_Grass"
    },
    {
      "x": 3,
      "y": 1,
      "z": 2,
      "name": "Plant_Grass_Lush_Tall",
      "support": 15
    },
    {
      "x": 3,
      "y": 14,
      "z": 2,
      "name": "Plant_Leaves_Crystal",
      "support": 15
    },
    {
      "x": 3,
      "y": 15,
      "z": 2,
      "name": "Soil_Dirt"
    },
    {
      "x": 3,
      "y": 16,
      "z": 2,
      "name": "Soil_Dirt"
    },
    {
      "x": 3,
      "y": 17,
      "z": 2,
      "name": "Soil_Grass"
    },
    {
      "x": 3,
      "y": 0,
      "z": 3,
      "name": "Soil_Dirt"
    },
    {
      "x": 3,
      "y": 1,
      "z": 3,
      "name": "Wood_Crystal_Trunk_Full",
      "support": 15
    },
    {
      "x": 3,
      "y": 14,
      "z": 3,
      "name": "Plant_Leaves_Crystal",
      "support": 15
    },
    {
      "x": 3,
      "y": 15,
      "z": 3,
      "name": "Plant_Leaves_Crystal",
      "support": 15
    },
    {
      "x": 3,
      "y": 16,
      "z": 3,
      "name": "Soil_Dirt"
    },
    {
      "x": 3,
      "y": 17,
      "z": 3,
      "name": "Soil_Grass"
    },
    {
      "x": 3,
      "y": 0,
      "z": 4,
      "name": "Soil_Grass"
    },
    {
      "x": 3,
      "y": 1,
      "z": 4,
      "name": "Plant_Grass_Jungle",
      "support": 15
    },
    {
      "x": 3,
      "y": 14,
      "z": 4,
      "name": "Plant_Leaves_Crystal",
      "support": 15
    },
    {
      "x": 3,
      "y": 16,
      "z": 4,
      "name": "Plant_Leaves_Crystal",
      "support": 15
    },
    {
      "x": 3,
      "y": 17,
      "z": 4,
      "name": "Plant_Leaves_Crystal",
      "support": 15
    },
    {
      "x": 3,
      "y": 0,
      "z": 5,
      "name": "Soil_Grass"
    },
    {
      "x": 3,
      "y": 8,
      "z": 5,
      "name": "Plant_Leaves_Crystal",
      "support": 15
    },
    {
      "x": 3,
      "y": 9,
      "z": 5,
      "name": "Plant_Leaves_Crystal",
      "support": 15
    },
    {
      "x": 3,
      "y": 10,
      "z": 5,
      "name": "Plant_Leaves_Crystal",
      "support": 15
    },
    {
      "x": 3,
      "y": 11,
      "z": 5,
      "name": "Plant_Leaves_Crystal",
      "support": 15
    },
    {
      "x": 3,
      "y": 12,
      "z": 5,
      "name": "Plant_Leaves_Crystal",
      "support": 15
    },
    {
      "x": 3,
      "y": 13,
      "z": 5,
      "name": "Plant_Leaves_Crystal",
      "support": 15
    },
    {
      "x": 3,
      "y": 14,
      "z": 5,
      "name": "Plant_Leaves_Crystal",
      "support": 15
    },
    {
      "x": 3,
      "y": 15,
      "z": 5,
      "name": "Plant_Leaves_Crystal",
      "support": 15
    },
    {
      "x": 3,
      "y": 0,
      "z": 6,
      "name": "Soil_Grass"
    },
    {
      "x": 3,
      "y": 1,
      "z": 6,
      "name": "Plant_Grass_Lush",
      "rotation": 1
    },
    {
      "x": 3,
      "y": 0,
      "z": 7,
      "name": "Soil_Grass"
    },
    {
      "x": 4,
      "y": 0,
      "z": -7,
      "name": "Soil_Grass"
    },
    {
      "x": 4,
      "y": 0,
      "z": -6,
      "name": "Soil_Grass"
    },
    {
      "x": 4,
      "y": 0,
      "z": -5,
      "name": "Soil_Grass"
    },
    {
      "x": 4,
      "y": 0,
      "z": -4,
      "name": "Soil_Dirt"
    },
    {
      "x": 4,
      "y": 1,
      "z": -4,
      "name": "Wood_Crystal_Trunk_Full",
      "support": 15
    },
    {
      "x": 4,
      "y": 2,
      "z": -4,
      "name": "Wood_Crystal_Trunk_Full",
      "support": 15
    },
    {
      "x": 4,
      "y": 11,
      "z": -4,
      "name": "Plant_Leaves_Crystal",
      "support": 15
    },
    {
      "x": 4,
      "y": 12,
      "z": -4,
      "name": "Plant_Leaves_Crystal",
      "support": 15
    },
    {
      "x": 4,
      "y": 13,
      "z": -4,
      "name": "Plant_Leaves_Crystal",
      "support": 15
    },
    {
      "x": 4,
      "y": 16,
      "z": -4,
      "name": "Plant_Leaves_Crystal",
      "support": 15
    },
    {
      "x": 4,
      "y": 0,
      "z": -3,
      "name": "Soil_Grass"
    },
    {
      "x": 4,
      "y": 12,
      "z": -3,
      "name": "Plant_Leaves_Crystal",
      "support": 15
    },
    {
      "x": 4,
      "y": 13,
      "z": -3,
      "name": "Plant_Leaves_Crystal",
      "support": 15
    },
    {
      "x": 4,
      "y": 14,
      "z": -3,
      "name": "Plant_Leaves_Crystal",
      "support": 15
    },
    {
      "x": 4,
      "y": 16,
      "z": -3,
      "name": "Plant_Leaves_Crystal",
      "support": 15
    },
    {
      "x": 4,
      "y": 17,
      "z": -3,
      "name": "Soil_Grass"
    },
    {
      "x": 4,
      "y": 0,
      "z": -2,
      "name": "Soil_Grass"
    },
    {
      "x": 4,
      "y": 13,
      "z": -2,
      "name": "Plant_Leaves_Crystal",
      "support": 15
    },
    {
      "x": 4,
      "y": 14,
      "z": -2,
      "name": "Plant_Leaves_Crystal",
      "support": 15
    },
    {
      "x": 4,
      "y": 15,
      "z": -2,
      "name": "Rock_Crystal_Purple_Medium",
      "rotation": 8
    },
    {
      "x": 4,
      "y": 16,
      "z": -2,
      "name": "Soil_Dirt"
    },
    {
      "x": 4,
      "y": 17,
      "z": -2,
      "name": "Soil_Grass"
    },
    {
      "x": 4,
      "y": 0,
      "z": -1,
      "name": "Soil_Grass"
    },
    {
      "x": 4,
      "y": 1,
      "z": -1,
      "name": "Plant_Grass_Lush_Tall",
      "support": 15
    },
    {
      "x": 4,
      "y": 14,
      "z": -1,
      "name": "Plant_Leaves_Crystal",
      "support": 15
    },
    {
      "x": 4,
      "y": 15,
      "z": -1,
      "name": "Rock_Stone"
    },
    {
      "x": 4,
      "y": 16,
      "z": -1,
      "name": "Soil_Clay_Smooth_Purple"
    },
    {
      "x": 4,
      "y": 17,
      "z": -1,
      "name": "Soil_Grass"
    },
    {
      "x": 4,
      "y": 18,
      "z": -1,
      "name": "Plant_Grass_Lush",
      "support": 15
    },
    {
      "x": 4,
      "y": 0,
      "z": 0,
      "name": "Soil_Grass"
    },
    {
      "x": 4,
      "y": 12,
      "z": 0,
      "name": "Plant_Leaves_Crystal",
      "support": 15
    },
    {
      "x": 4,
      "y": 13,
      "z": 0,
      "name": "Plant_Leaves_Crystal",
      "support": 15
    },
    {
      "x": 4,
      "y": 14,
      "z": 0,
      "name": "Plant_Leaves_Crystal",
      "support": 15
    },
    {
      "x": 4,
      "y": 15,
      "z": 0,
      "name": "Soil_Dirt"
    },
    {
      "x": 4,
      "y": 16,
      "z": 0,
      "name": "Soil_Clay_Smooth_Purple"
    },
    {
      "x": 4,
      "y": 17,
      "z": 0,
      "name": "Soil_Grass"
    },
    {
      "x": 4,
      "y": 18,
      "z": 0,
      "name": "Plant_Grass_Lush",
      "support": 15
    },
    {
      "x": 4,
      "y": 0,
      "z": 1,
      "name": "Soil_Grass"
    },
    {
      "x": 4,
      "y": 1,
      "z": 1,
      "name": "Plant_Grass_Lush_Tall",
      "support": 15
    },
    {
      "x": 4,
      "y": 14,
      "z": 1,
      "name": "Plant_Leaves_Crystal",
      "support": 15
    },
    {
      "x": 4,
      "y": 15,
      "z": 1,
      "name": "Soil_Dirt"
    },
    {
      "x": 4,
      "y": 16,
      "z": 1,
      "name": "Soil_Clay_Smooth_Purple"
    },
    {
      "x": 4,
      "y": 17,
      "z": 1,
      "name": "Soil_Grass"
    },
    {
      "x": 4,
      "y": 0,
      "z": 2,
      "name": "Soil_Grass"
    },
    {
      "x": 4,
      "y": 15,
      "z": 2,
      "name": "Plant_Leaves_Crystal",
      "support": 15
    },
    {
      "x": 4,
      "y": 16,
      "z": 2,
      "name": "Soil_Dirt"
    },
    {
      "x": 4,
      "y": 17,
      "z": 2,
      "name": "Soil_Grass"
    },
    {
      "x": 4,
      "y": 0,
      "z": 3,
      "name": "Soil_Grass"
    },
    {
      "x": 4,
      "y": 1,
      "z": 3,
      "name": "Plant_Grass_Jungle",
      "support": 15
    },
    {
      "x": 4,
      "y": 13,
      "z": 3,
      "name": "Plant_Leaves_Crystal",
      "support": 15
    },
    {
      "x": 4,
      "y": 14,
      "z": 3,
      "name": "Plant_Leaves_Crystal",
      "support": 15
    },
    {
      "x": 4,
      "y": 15,
      "z": 3,
      "name": "Plant_Leaves_Crystal",
      "support": 15
    },
    {
      "x": 4,
      "y": 16,
      "z": 3,
      "name": "Soil_Grass"
    },
    {
      "x": 4,
      "y": 17,
      "z": 3,
      "name": "Plant_Leaves_Crystal",
      "support": 15
    },
    {
      "x": 4,
      "y": 0,
      "z": 4,
      "name": "Soil_Dirt"
    },
    {
      "x": 4,
      "y": 1,
      "z": 4,
      "name": "Wood_Crystal_Trunk_Full",
      "support": 15
    },
    {
      "x": 4,
      "y": 14,
      "z": 4,
      "name": "Plant_Leaves_Crystal",
      "support": 15
    },
    {
      "x": 4,
      "y": 15,
      "z": 4,
      "name": "Plant_Leaves_Crystal",
      "support": 15
    },
    {
      "x": 4,
      "y": 16,
      "z": 4,
      "name": "Plant_Leaves_Crystal",
      "support": 15
    },
    {
      "x": 4,
      "y": 0,
      "z": 5,
      "name": "Soil_Grass"
    },
    {
      "x": 4,
      "y": 15,
      "z": 5,
      "name": "Plant_Leaves_Crystal",
      "support": 15
    },
    {
      "x": 4,
      "y": 0,
      "z": 6,
      "name": "Soil_Grass"
    },
    {
      "x": 4,
      "y": 0,
      "z": 7,
      "name": "Soil_Grass"
    },
    {
      "x": 5,
      "y": 0,
      "z": -7,
      "name": "Soil_Grass"
    },
    {
      "x": 5,
      "y": 1,
      "z": -7,
      "name": "Plant_Grass_Lush_Tall",
      "rotation": 1
    },
    {
      "x": 5,
      "y": 0,
      "z": -6,
      "name": "Soil_Grass"
    },
    {
      "x": 5,
      "y": 0,
      "z": -5,
      "name": "Soil_Grass"
    },
    {
      "x": 5,
      "y": 0,
      "z": -4,
      "name": "Soil_Grass"
    },
    {
      "x": 5,
      "y": 1,
      "z": -4,
      "name": "Plant_Grass_Lush",
      "support": 15
    },
    {
      "x": 5,
      "y": 2,
      "z": -4,
      "name": "Wood_Crystal_Trunk_Full",
      "support": 15,
      "rotation": 5
    },
    {
      "x": 5,
      "y": 17,
      "z": -4,
      "name": "Plant_Leaves_Crystal",
      "support": 15
    },
    {
      "x": 5,
      "y": 0,
      "z": -3,
      "name": "Soil_Grass"
    },
    {
      "x": 5,
      "y": 1,
      "z": -3,
      "name": "Plant_Grass_Lush_Tall",
      "support": 15
    },
    {
      "x": 5,
      "y": 15,
      "z": -3,
      "name": "Plant_Leaves_Crystal",
      "support": 15
    },
    {
      "x": 5,
      "y": 16,
      "z": -3,
      "name": "Plant_Leaves_Crystal",
      "support": 15
    },
    {
      "x": 5,
      "y": 17,
      "z": -3,
      "name": "Plant_Leaves_Crystal",
      "support": 15
    },
    {
      "x": 5,
      "y": 0,
      "z": -2,
      "name": "Soil_Grass"
    },
    {
      "x": 5,
      "y": 15,
      "z": -2,
      "name": "Plant_Leaves_Crystal",
      "support": 15
    },
    {
      "x": 5,
      "y": 16,
      "z": -2,
      "name": "Soil_Dirt"
    },
    {
      "x": 5,
      "y": 17,
      "z": -2,
      "name": "Soil_Grass"
    },
    {
      "x": 5,
      "y": 0,
      "z": -1,
      "name": "Soil_Grass"
    },
    {
      "x": 5,
      "y": 14,
      "z": -1,
      "name": "Plant_Leaves_Crystal",
      "support": 15
    },
    {
      "x": 5,
      "y": 15,
      "z": -1,
      "name": "Soil_Dirt"
    },
    {
      "x": 5,
      "y": 16,
      "z": -1,
      "name": "Soil_Clay_Smooth_Purple"
    },
    {
      "x": 5,
      "y": 17,
      "z": -1,
      "name": "Soil_Grass"
    },
    {
      "x": 5,
      "y": 18,
      "z": -1,
      "name": "Plant_Grass_Lush",
      "support": 15
    },
    {
      "x": 5,
      "y": 0,
      "z": 0,
      "name": "Soil_Grass"
    },
    {
      "x": 5,
      "y": 14,
      "z": 0,
      "name": "Plant_Leaves_Crystal",
      "support": 15
    },
    {
      "x": 5,
      "y": 15,
      "z": 0,
      "name": "Soil_Dirt"
    },
    {
      "x": 5,
      "y": 16,
      "z": 0,
      "name": "Soil_Clay_Smooth_Purple"
    },
    {
      "x": 5,
      "y": 17,
      "z": 0,
      "name": "Soil_Grass"
    },
    {
      "x": 5,
      "y": 0,
      "z": 1,
      "name": "Soil_Grass"
    },
    {
      "x": 5,
      "y": 14,
      "z": 1,
      "name": "Plant_Leaves_Crystal",
      "support": 15
    },
    {
      "x": 5,
      "y": 15,
      "z": 1,
      "name": "Soil_Dirt"
    },
    {
      "x": 5,
      "y": 16,
      "z": 1,
      "name": "Soil_Clay_Smooth_Purple"
    },
    {
      "x": 5,
      "y": 17,
      "z": 1,
      "name": "Soil_Grass"
    },
    {
      "x": 5,
      "y": 18,
      "z": 1,
      "name": "Plant_Grass_Lush",
      "support": 15
    },
    {
      "x": 5,
      "y": 0,
      "z": 2,
      "name": "Soil_Grass"
    },
    {
      "x": 5,
      "y": 14,
      "z": 2,
      "name": "Plant_Leaves_Crystal",
      "support": 15
    },
    {
      "x": 5,
      "y": 15,
      "z": 2,
      "name": "Plant_Leaves_Crystal",
      "support": 15
    },
    {
      "x": 5,
      "y": 16,
      "z": 2,
      "name": "Soil_Dirt"
    },
    {
      "x": 5,
      "y": 17,
      "z": 2,
      "name": "Soil_Grass"
    },
    {
      "x": 5,
      "y": 0,
      "z": 3,
      "name": "Soil_Grass"
    },
    {
      "x": 5,
      "y": 13,
      "z": 3,
      "name": "Plant_Leaves_Crystal",
      "support": 15
    },
    {
      "x": 5,
      "y": 14,
      "z": 3,
      "name": "Plant_Leaves_Crystal",
      "support": 15
    },
    {
      "x": 5,
      "y": 15,
      "z": 3,
      "name": "Plant_Leaves_Crystal",
      "support": 15
    },
    {
      "x": 5,
      "y": 16,
      "z": 3,
      "name": "Plant_Leaves_Crystal",
      "support": 15
    },
    {
      "x": 5,
      "y": 17,
      "z": 3,
      "name": "Plant_Leaves_Crystal",
      "support": 15
    },
    {
      "x": 5,
      "y": 0,
      "z": 4,
      "name": "Soil_Dirt"
    },
    {
      "x": 5,
      "y": 1,
      "z": 4,
      "name": "Wood_Crystal_Trunk_Full",
      "support": 15
    },
    {
      "x": 5,
      "y": 14,
      "z": 4,
      "name": "Plant_Leaves_Crystal",
      "support": 15
    },
    {
      "x": 5,
      "y": 15,
      "z": 4,
      "name": "Plant_Leaves_Crystal",
      "support": 15
    },
    {
      "x": 5,
      "y": 0,
      "z": 5,
      "name": "Soil_Grass"
    },
    {
      "x": 5,
      "y": 0,
      "z": 6,
      "name": "Soil_Grass"
    },
    {
      "x": 5,
      "y": 0,
      "z": 7,
      "name": "Soil_Grass"
    },
    {
      "x": 5,
      "y": 1,
      "z": 7,
      "name": "Plant_Grass_Jungle"
    },
    {
      "x": 6,
      "y": 0,
      "z": -7,
      "name": "Soil_Grass"
    },
    {
      "x": 6,
      "y": 0,
      "z": -6,
      "name": "Soil_Grass"
    },
    {
      "x": 6,
      "y": 1,
      "z": -6,
      "name": "Plant_Grass_Sharp",
      "rotation": 3
    },
    {
      "x": 6,
      "y": 0,
      "z": -5,
      "name": "Soil_Grass"
    },
    {
      "x": 6,
      "y": 0,
      "z": -4,
      "name": "Soil_Dirt"
    },
    {
      "x": 6,
      "y": 1,
      "z": -4,
      "name": "Wood_Crystal_Trunk_Full",
      "support": 15
    },
    {
      "x": 6,
      "y": 0,
      "z": -3,
      "name": "Soil_Grass"
    },
    {
      "x": 6,
      "y": 16,
      "z": -3,
      "name": "Plant_Leaves_Crystal",
      "support": 15
    },
    {
      "x": 6,
      "y": 17,
      "z": -3,
      "name": "Plant_Leaves_Crystal",
      "support": 15
    },
    {
      "x": 6,
      "y": 0,
      "z": -2,
      "name": "Soil_Grass"
    },
    {
      "x": 6,
      "y": 14,
      "z": -2,
      "name": "Plant_Leaves_Crystal",
      "support": 15
    },
    {
      "x": 6,
      "y": 15,
      "z": -2,
      "name": "Plant_Leaves_Crystal",
      "support": 15
    },
    {
      "x": 6,
      "y": 16,
      "z": -2,
      "name": "Plant_Leaves_Crystal",
      "support": 15
    },
    {
      "x": 6,
      "y": 17,
      "z": -2,
      "name": "Soil_Grass"
    },
    {
      "x": 6,
      "y": 0,
      "z": -1,
      "name": "Soil_Grass"
    },
    {
      "x": 6,
      "y": 1,
      "z": -1,
      "name": "Rubble_Calcite",
      "support": 15
    },
    {
      "x": 6,
      "y": 14,
      "z": -1,
      "name": "Plant_Leaves_Crystal",
      "support": 15
    },
    {
      "x": 6,
      "y": 15,
      "z": -1,
      "name": "Soil_Dirt"
    },
    {
      "x": 6,
      "y": 16,
      "z": -1,
      "name": "Soil_Dirt"
    },
    {
      "x": 6,
      "y": 17,
      "z": -1,
      "name": "Soil_Grass"
    },
    {
      "x": 6,
      "y": 0,
      "z": 0,
      "name": "Plant_Petals_White"
    },
    {
      "x": 6,
      "y": 14,
      "z": 0,
      "name": "Plant_Leaves_Crystal",
      "support": 15
    },
    {
      "x": 6,
      "y": 15,
      "z": 0,
      "name": "Soil_Dirt"
    },
    {
      "x": 6,
      "y": 16,
      "z": 0,
      "name": "Soil_Clay_Smooth_Purple"
    },
    {
      "x": 6,
      "y": 17,
      "z": 0,
      "name": "Empty"
    },
    {
      "x": 6,
      "y": 0,
      "z": 1,
      "name": "Plant_Petals_White"
    },
    {
      "x": 6,
      "y": 14,
      "z": 1,
      "name": "Plant_Leaves_Crystal",
      "support": 15
    },
    {
      "x": 6,
      "y": 15,
      "z": 1,
      "name": "Plant_Leaves_Crystal",
      "support": 15
    },
    {
      "x": 6,
      "y": 16,
      "z": 1,
      "name": "Soil_Dirt"
    },
    {
      "x": 6,
      "y": 17,
      "z": 1,
      "name": "Soil_Grass"
    },
    {
      "x": 6,
      "y": 0,
      "z": 2,
      "name": "Soil_Grass"
    },
    {
      "x": 6,
      "y": 1,
      "z": 2,
      "name": "Plant_Grass_Lush_Tall",
      "support": 15
    },
    {
      "x": 6,
      "y": 13,
      "z": 2,
      "name": "Plant_Leaves_Crystal",
      "support": 15
    },
    {
      "x": 6,
      "y": 14,
      "z": 2,
      "name": "Plant_Leaves_Crystal",
      "support": 15
    },
    {
      "x": 6,
      "y": 15,
      "z": 2,
      "name": "Plant_Leaves_Crystal",
      "support": 15
    },
    {
      "x": 6,
      "y": 16,
      "z": 2,
      "name": "Plant_Leaves_Crystal",
      "support": 15
    },
    {
      "x": 6,
      "y": 17,
      "z": 2,
      "name": "Soil_Grass"
    },
    {
      "x": 6,
      "y": 0,
      "z": 3,
      "name": "Soil_Grass"
    },
    {
      "x": 6,
      "y": 14,
      "z": 3,
      "name": "Plant_Leaves_Crystal",
      "support": 15
    },
    {
      "x": 6,
      "y": 16,
      "z": 3,
      "name": "Plant_Leaves_Crystal",
      "support": 15
    },
    {
      "x": 6,
      "y": 17,
      "z": 3,
      "name": "Plant_Leaves_Crystal",
      "support": 15
    },
    {
      "x": 6,
      "y": 0,
      "z": 4,
      "name": "Soil_Grass"
    },
    {
      "x": 6,
      "y": 1,
      "z": 4,
      "name": "Plant_Grass_Lush_Tall",
      "support": 15
    },
    {
      "x": 6,
      "y": 0,
      "z": 5,
      "name": "Soil_Grass"
    },
    {
      "x": 6,
      "y": 1,
      "z": 5,
      "name": "Plant_Grass_Jungle_Tall",
      "support": 15
    },
    {
      "x": 6,
      "y": 0,
      "z": 6,
      "name": "Soil_Grass"
    },
    {
      "x": 6,
      "y": 0,
      "z": 7,
      "name": "Soil_Grass"
    },
    {
      "x": 7,
      "y": 0,
      "z": -7,
      "name": "Soil_Grass"
    },
    {
      "x": 7,
      "y": 1,
      "z": -7,
      "name": "Plant_Grass_Lush_Tall",
      "rotation": 3
    },
    {
      "x": 7,
      "y": 0,
      "z": -6,
      "name": "Soil_Grass"
    },
    {
      "x": 7,
      "y": 0,
      "z": -5,
      "name": "Soil_Grass"
    },
    {
      "x": 7,
      "y": 0,
      "z": -4,
      "name": "Soil_Grass"
    },
    {
      "x": 7,
      "y": 1,
      "z": -4,
      "name": "Plant_Grass_Sharp",
      "support": 15
    },
    {
      "x": 7,
      "y": 0,
      "z": -3,
      "name": "Soil_Grass"
    },
    {
      "x": 7,
      "y": 16,
      "z": -3,
      "name": "Plant_Leaves_Crystal",
      "support": 15
    },
    {
      "x": 7,
      "y": 0,
      "z": -2,
      "name": "Soil_Grass"
    },
    {
      "x": 7,
      "y": 1,
      "z": -2,
      "name": "Rubble_Calcite_Medium",
      "support": 15
    },
    {
      "x": 7,
      "y": 12,
      "z": -2,
      "name": "Plant_Leaves_Crystal",
      "support": 15
    },
    {
      "x": 7,
      "y": 13,
      "z": -2,
      "name": "Plant_Leaves_Crystal",
      "support": 15
    },
    {
      "x": 7,
      "y": 14,
      "z": -2,
      "name": "Plant_Leaves_Crystal",
      "support": 15
    },
    {
      "x": 7,
      "y": 15,
      "z": -2,
      "name": "Plant_Leaves_Crystal",
      "support": 15
    },
    {
      "x": 7,
      "y": 16,
      "z": -2,
      "name": "Plant_Leaves_Crystal",
      "support": 15
    },
    {
      "x": 7,
      "y": 17,
      "z": -2,
      "name": "Plant_Leaves_Crystal",
      "support": 15
    },
    {
      "x": 7,
      "y": 0,
      "z": -1,
      "name": "Empty"
    },
    {
      "x": 7,
      "y": 15,
      "z": -1,
      "name": "Plant_Leaves_Crystal",
      "support": 15
    },
    {
      "x": 7,
      "y": 16,
      "z": -1,
      "name": "Soil_Dirt"
    },
    {
      "x": 7,
      "y": 17,
      "z": -1,
      "name": "Soil_Grass"
    },
    {
      "x": 7,
      "y": 0,
      "z": 0,
      "name": "Plant_Coral_Bush_Dead"
    },
    {
      "x": 7,
      "y": 14,
      "z": 0,
      "name": "Plant_Leaves_Crystal",
      "support": 15
    },
    {
      "x": 7,
      "y": 15,
      "z": 0,
      "name": "Soil_Dirt"
    },
    {
      "x": 7,
      "y": 16,
      "z": 0,
      "name": "Soil_Clay_Smooth_Purple"
    },
    {
      "x": 7,
      "y": 17,
      "z": 0,
      "name": "Empty"
    },
    {
      "x": 7,
      "y": 0,
      "z": 1,
      "name": "Plant_Petals_White"
    },
    {
      "x": 7,
      "y": 14,
      "z": 1,
      "name": "Plant_Leaves_Crystal",
      "support": 15
    },
    {
      "x": 7,
      "y": 15,
      "z": 1,
      "name": "Plant_Leaves_Crystal",
      "support": 15
    },
    {
      "x": 7,
      "y": 16,
      "z": 1,
      "name": "Soil_Dirt"
    },
    {
      "x": 7,
      "y": 17,
      "z": 1,
      "name": "Soil_Grass"
    },
    {
      "x": 7,
      "y": 0,
      "z": 2,
      "name": "Plant_Petals_White"
    },
    {
      "x": 7,
      "y": 11,
      "z": 2,
      "name": "Plant_Leaves_Crystal",
      "support": 15
    },
    {
      "x": 7,
      "y": 12,
      "z": 2,
      "name": "Plant_Leaves_Crystal",
      "support": 15
    },
    {
      "x": 7,
      "y": 13,
      "z": 2,
      "name": "Plant_Leaves_Crystal",
      "support": 15
    },
    {
      "x": 7,
      "y": 14,
      "z": 2,
      "name": "Plant_Leaves_Crystal",
      "support": 15
    },
    {
      "x": 7,
      "y": 15,
      "z": 2,
      "name": "Plant_Leaves_Crystal",
      "support": 15
    },
    {
      "x": 7,
      "y": 16,
      "z": 2,
      "name": "Plant_Leaves_Crystal",
      "support": 15
    },
    {
      "x": 7,
      "y": 17,
      "z": 2,
      "name": "Plant_Leaves_Crystal",
      "support": 15
    },
    {
      "x": 7,
      "y": 0,
      "z": 3,
      "name": "Soil_Grass"
    },
    {
      "x": 7,
      "y": 16,
      "z": 3,
      "name": "Plant_Leaves_Crystal",
      "support": 15
    },
    {
      "x": 7,
      "y": 0,
      "z": 4,
      "name": "Soil_Grass"
    },
    {
      "x": 7,
      "y": 0,
      "z": 5,
      "name": "Soil_Grass"
    },
    {
      "x": 7,
      "y": 1,
      "z": 5,
      "name": "Plant_Grass_Lush",
      "support": 15
    },
    {
      "x": 7,
      "y": 0,
      "z": 6,
      "name": "Soil_Grass"
    },
    {
      "x": 7,
      "y": 1,
      "z": 6,
      "name": "Plant_Grass_Lush",
      "support": 15
    },
    {
      "x": 7,
      "y": 0,
      "z": 7,
      "name": "Soil_Grass"
    },
    {
      "x": 8,
      "y": 0,
      "z": -7,
      "name": "Soil_Grass"
    },
    {
      "x": 8,
      "y": 0,
      "z": -6,
      "name": "Soil_Grass"
    },
    {
      "x": 8,
      "y": 1,
      "z": -6,
      "name": "Plant_Grass_Lush",
      "rotation": 3
    },
    {
      "x": 8,
      "y": 0,
      "z": -5,
      "name": "Soil_Grass"
    },
    {
      "x": 8,
      "y": 1,
      "z": -5,
      "name": "Plant_Grass_Lush",
      "support": 15
    },
    {
      "x": 8,
      "y": 0,
      "z": -4,
      "name": "Soil_Grass"
    },
    {
      "x": 8,
      "y": 0,
      "z": -3,
      "name": "Soil_Grass"
    },
    {
      "x": 8,
      "y": 0,
      "z": -2,
      "name": "Plant_Petals_White"
    },
    {
      "x": 8,
      "y": 16,
      "z": -2,
      "name": "Plant_Leaves_Crystal",
      "support": 15
    },
    {
      "x": 8,
      "y": 17,
      "z": -2,
      "name": "Plant_Leaves_Crystal",
      "support": 15
    },
    {
      "x": 8,
      "y": 0,
      "z": -1,
      "name": "Plant_Coral_Bush_Dead"
    },
    {
      "x": 8,
      "y": 16,
      "z": -1,
      "name": "Plant_Leaves_Crystal",
      "support": 15
    },
    {
      "x": 8,
      "y": 17,
      "z": -1,
      "name": "Plant_Leaves_Crystal",
      "support": 15
    },
    {
      "x": 8,
      "y": 0,
      "z": 0,
      "name": "Plant_Coral_Bush_Dead"
    },
    {
      "x": 8,
      "y": 1,
      "z": 0,
      "name": "Empty"
    },
    {
      "x": 8,
      "y": 2,
      "z": 0,
      "name": "Empty"
    },
    {
      "x": 8,
      "y": 3,
      "z": 0,
      "name": "Empty"
    },
    {
      "x": 8,
      "y": 4,
      "z": 0,
      "name": "Empty"
    },
    {
      "x": 8,
      "y": 5,
      "z": 0,
      "name": "Empty"
    },
    {
      "x": 8,
      "y": 6,
      "z": 0,
      "name": "Empty"
    },
    {
      "x": 8,
      "y": 7,
      "z": 0,
      "name": "Empty"
    },
    {
      "x": 8,
      "y": 8,
      "z": 0,
      "name": "Empty"
    },
    {
      "x": 8,
      "y": 9,
      "z": 0,
      "name": "Empty"
    },
    {
      "x": 8,
      "y": 10,
      "z": 0,
      "name": "Empty"
    },
    {
      "x": 8,
      "y": 11,
      "z": 0,
      "name": "Empty"
    },
    {
      "x": 8,
      "y": 12,
      "z": 0,
      "name": "Empty"
    },
    {
      "x": 8,
      "y": 13,
      "z": 0,
      "name": "Empty"
    },
    {
      "x": 8,
      "y": 14,
      "z": 0,
      "name": "Empty"
    },
    {
      "x": 8,
      "y": 15,
      "z": 0,
      "name": "Empty"
    },
    {
      "x": 8,
      "y": 16,
      "z": 0,
      "name": "Empty"
    },
    {
      "x": 8,
      "y": 17,
      "z": 0,
      "name": "Empty"
    },
    {
      "x": 8,
      "y": 0,
      "z": 1,
      "name": "Plant_Petals_White"
    },
    {
      "x": 8,
      "y": 16,
      "z": 1,
      "name": "Plant_Leaves_Crystal",
      "support": 15
    },
    {
      "x": 8,
      "y": 17,
      "z": 1,
      "name": "Plant_Leaves_Crystal",
      "support": 15
    },
    {
      "x": 8,
      "y": 0,
      "z": 2,
      "name": "Soil_Grass"
    },
    {
      "x": 8,
      "y": 1,
      "z": 2,
      "name": "Rubble_Calcite_Medium",
      "support": 15
    },
    {
      "x": 8,
      "y": 0,
      "z": 3,
      "name": "Soil_Grass"
    },
    {
      "x": 8,
      "y": 0,
      "z": 4,
      "name": "Soil_Grass"
    },
    {
      "x": 8,
      "y": 0,
      "z": 5,
      "name": "Soil_Grass"
    },
    {
      "x": 8,
      "y": 1,
      "z": 5,
      "name": "Plant_Grass_Lush",
      "support": 15
    },
    {
      "x": 8,
      "y": 0,
      "z": 6,
      "name": "Soil_Grass"
    },
    {
      "x": 8,
      "y": 1,
      "z": 6,
      "name": "Plant_Grass_Lush",
      "support": 15
    },
    {
      "x": 8,
      "y": 0,
      "z": 7,
      "name": "Soil_Grass"
    },
    {
      "x": 9,
      "y": 0,
      "z": -7,
      "name": "Soil_Grass"
    },
    {
      "x": 9,
      "y": 0,
      "z": -6,
      "name": "Soil_Grass"
    },
    {
      "x": 9,
      "y": 0,
      "z": -5,
      "name": "Soil_Grass"
    },
    {
      "x": 9,
      "y": 0,
      "z": -4,
      "name": "Soil_Grass"
    },
    {
      "x": 9,
      "y": 0,
      "z": -3,
      "name": "Soil_Grass"
    },
    {
      "x": 9,
      "y": 1,
      "z": -3,
      "name": "Plant_Grass_Lush",
      "support": 15
    },
    {
      "x": 9,
      "y": 0,
      "z": -2,
      "name": "Plant_Petals_White"
    },
    {
      "x": 9,
      "y": 0,
      "z": -1,
      "name": "Plant_Petals_White"
    },
    {
      "x": 9,
      "y": 0,
      "z": 0,
      "name": "Plant_Coral_Bush_Dead"
    },
    {
      "x": 9,
      "y": 0,
      "z": 1,
      "name": "Plant_Petals_White"
    },
    {
      "x": 9,
      "y": 0,
      "z": 2,
      "name": "Soil_Grass"
    },
    {
      "x": 9,
      "y": 1,
      "z": 2,
      "name": "Rubble_Calcite",
      "support": 15
    },
    {
      "x": 9,
      "y": 0,
      "z": 3,
      "name": "Soil_Grass"
    },
    {
      "x": 9,
      "y": 0,
      "z": 4,
      "name": "Soil_Grass"
    },
    {
      "x": 9,
      "y": 1,
      "z": 4,
      "name": "Plant_Grass_Lush",
      "support": 15
    },
    {
      "x": 9,
      "y": 0,
      "z": 5,
      "name": "Soil_Grass"
    },
    {
      "x": 9,
      "y": 1,
      "z": 5,
      "name": "Plant_Grass_Lush",
      "support": 15
    },
    {
      "x": 9,
      "y": 0,
      "z": 6,
      "name": "Soil_Grass"
    },
    {
      "x": 9,
      "y": 0,
      "z": 7,
      "name": "Soil_Grass"
    },
    {
      "x": 10,
      "y": 0,
      "z": -7,
      "name": "Soil_Grass"
    },
    {
      "x": 10,
      "y": 0,
      "z": -6,
      "name": "Soil_Grass"
    },
    {
      "x": 10,
      "y": 1,
      "z": -6,
      "name": "Plant_Grass_Sharp",
      "rotation": 2
    },
    {
      "x": 10,
      "y": 0,
      "z": -5,
      "name": "Soil_Grass"
    },
    {
      "x": 10,
      "y": 0,
      "z": -4,
      "name": "Soil_Grass"
    },
    {
      "x": 10,
      "y": 0,
      "z": -3,
      "name": "Soil_Grass"
    },
    {
      "x": 10,
      "y": 0,
      "z": -2,
      "name": "Soil_Grass"
    },
    {
      "x": 10,
      "y": 1,
      "z": -2,
      "name": "Rubble_Calcite_Medium",
      "support": 15
    },
    {
      "x": 10,
      "y": 0,
      "z": -1,
      "name": "Plant_Petals_White"
    },
    {
      "x": 10,
      "y": 0,
      "z": 0,
      "name": "Plant_Petals_White"
    },
    {
      "x": 10,
      "y": 0,
      "z": 1,
      "name": "Soil_Grass"
    },
    {
      "x": 10,
      "y": 1,
      "z": 1,
      "name": "Rubble_Calcite_Medium",
      "support": 15
    },
    {
      "x": 10,
      "y": 0,
      "z": 2,
      "name": "Soil_Grass"
    },
    {
      "x": 10,
      "y": 0,
      "z": 3,
      "name": "Soil_Grass"
    },
    {
      "x": 10,
      "y": 0,
      "z": 4,
      "name": "Soil_Grass"
    },
    {
      "x": 10,
      "y": 0,
      "z": 5,
      "name": "Soil_Grass"
    },
    {
      "x": 10,
      "y": 0,
      "z": 6,
      "name": "Soil_Grass"
    },
    {
      "x": 10,
      "y": 0,
      "z": 7,
      "name": "Soil_Grass"
    },
    {
      "x": 10,
      "y": 1,
      "z": 7,
      "name": "Plant_Grass_Sharp",
      "rotation": 2
    },
    {
      "x": 11,
      "y": 0,
      "z": -7,
      "name": "Soil_Grass"
    },
    {
      "x": 11,
      "y": 0,
      "z": -6,
      "name": "Soil_Grass"
    },
    {
      "x": 11,
      "y": 1,
      "z": -6,
      "name": "Plant_Grass_Lush",
      "support": 15
    },
    {
      "x": 11,
      "y": 0,
      "z": -5,
      "name": "Soil_Grass"
    },
    {
      "x": 11,
      "y": 1,
      "z": -5,
      "name": "Plant_Grass_Lush",
      "support": 15
    },
    {
      "x": 11,
      "y": 0,
      "z": -4,
      "name": "Soil_Grass"
    },
    {
      "x": 11,
      "y": 0,
      "z": -3,
      "name": "Soil_Grass"
    },
    {
      "x": 11,
      "y": 1,
      "z": -3,
      "name": "Plant_Grass_Lush",
      "support": 15
    },
    {
      "x": 11,
      "y": 0,
      "z": -2,
      "name": "Soil_Grass"
    },
    {
      "x": 11,
      "y": 0,
      "z": -1,
      "name": "Soil_Grass"
    },
    {
      "x": 11,
      "y": 1,
      "z": -1,
      "name": "Plant_Grass_Lush",
      "support": 15
    },
    {
      "x": 11,
      "y": 0,
      "z": 0,
      "name": "Soil_Grass"
    },
    {
      "x": 11,
      "y": 1,
      "z": 0,
      "name": "Plant_Grass_Lush",
      "support": 15
    },
    {
      "x": 11,
      "y": 0,
      "z": 1,
      "name": "Soil_Grass"
    },
    {
      "x": 11,
      "y": 0,
      "z": 2,
      "name": "Soil_Grass"
    },
    {
      "x": 11,
      "y": 0,
      "z": 3,
      "name": "Soil_Grass"
    },
    {
      "x": 11,
      "y": 1,
      "z": 3,
      "name": "Plant_Grass_Lush",
      "support": 15
    },
    {
      "x": 11,
      "y": 0,
      "z": 4,
      "name": "Soil_Grass"
    },
    {
      "x": 11,
      "y": 1,
      "z": 4,
      "name": "Plant_Grass_Jungle_Tall",
      "support": 15
    },
    {
      "x": 11,
      "y": 0,
      "z": 5,
      "name": "Soil_Grass"
    },
    {
      "x": 11,
      "y": 0,
      "z": 6,
      "name": "Soil_Grass"
    },
    {
      "x": 11,
      "y": 1,
      "z": 6,
      "name": "Plant_Grass_Lush",
      "support": 15
    },
    {
      "x": 11,
      "y": 0,
      "z": 7,
      "name": "Soil_Grass"
    }
  ],
  "fluids": [
    {
      "x": -10,
      "y": 0,
      "z": -7,
      "name": "Empty",
      "level": 0
    },
    {
      "x": -10,
      "y": 0,
      "z": -6,
      "name": "Empty",
      "level": 0
    },
    {
      "x": -10,
      "y": 1,
      "z": -6,
      "name": "Empty",
      "level": 0
    },
    {
      "x": -10,
      "y": 0,
      "z": -5,
      "name": "Empty",
      "level": 0
    },
    {
      "x": -10,
      "y": 1,
      "z": -5,
      "name": "Empty",
      "level": 0
    },
    {
      "x": -10,
      "y": 0,
      "z": -4,
      "name": "Empty",
      "level": 0
    },
    {
      "x": -10,
      "y": 0,
      "z": -3,
      "name": "Empty",
      "level": 0
    },
    {
      "x": -10,
      "y": 1,
      "z": -3,
      "name": "Empty",
      "level": 0
    },
    {
      "x": -10,
      "y": 0,
      "z": -2,
      "name": "Empty",
      "level": 0
    },
    {
      "x": -10,
      "y": 0,
      "z": -1,
      "name": "Empty",
      "level": 0
    },
    {
      "x": -10,
      "y": 0,
      "z": 0,
      "name": "Empty",
      "level": 0
    },
    {
      "x": -10,
      "y": 0,
      "z": 1,
      "name": "Empty",
      "level": 0
    },
    {
      "x": -10,
      "y": 0,
      "z": 2,
      "name": "Empty",
      "level": 0
    },
    {
      "x": -10,
      "y": 0,
      "z": 3,
      "name": "Empty",
      "level": 0
    },
    {
      "x": -10,
      "y": 0,
      "z": 4,
      "name": "Empty",
