{
  "version": 8,
  "blockIdVersion": 11,
  "anchorX": 0,
  "anchorY": 0,
  "anchorZ": 0,
  "blocks": [
    {
      "x": -2,
      "y": 0,
      "z": 0,
      "name": "Plant_Grass_Lush",
      "rotation": 2
    },
    {
      "x": -2,
      "y": 0,
      "z": 2,
      "name": "Plant_Grass_Jungle",
      "rotation": 1
    },
    {
      "x": -1,
      "y": 0,
      "z": -2,
      "name": "Plant_Grass_Jungle",
      "rotation": 1
    },
    {
      "x": -1,
      "y": 8,
      "z": -1,
      "name": "Wood_Crystal_Trunk_Full",
      "support": 15,
      "rotation": 4
    },
    {
      "x": -1,
      "y": 9,
      "z": -1,
      "name": "PortalKey_Luminara_Red",
      "filler": 1023,
      "rotation": 3
    },
    {
      "x": -1,
      "y": 0,
      "z": 0,
      "name": "Wood_Crystal_Trunk_Stairs",
      "rotation": 3
    },
    {
      "x": -1,
      "y": 1,
      "z": 0,
      "name": "Wood_Crystal_Trunk_Half",
      "rotation": 7
    },
    {
      "x": -1,
      "y": 2,
      "z": 0,
      "name": "Wood_Crystal_Trunk_Half",
      "rotation": 7
    },
    {
      "x": -1,
      "y": 6,
      "z": 0,
      "name": "Wood_Crystal_Trunk_Half",
      "rotation": 7
    },
    {
      "x": -1,
      "y": 7,
      "z": 0,
      "name": "Wood_Crystal_Trunk_Stairs",
      "rotation": 9
    },
    {
      "x": -1,
      "y": 8,
      "z": 0,
      "name": "Wood_Crystal_Trunk_Stairs",
      "rotation": 9
    },
    {
      "x": -1,
      "y": 9,
      "z": 0,
      "name": "PortalKey_Luminara_Red",
      "filler": 31,
      "rotation": 3
    },
    {
      "x": -1,
      "y": 8,
      "z": 1,
      "name": "Wood_Crystal_Trunk_Full",
      "support": 15,
      "rotation": 5
    },
    {
      "x": -1,
      "y": 9,
      "z": 1,
      "name": "PortalKey_Luminara_Red",
      "filler": 63,
      "rotation": 3
    },
    {
      "x": 0,
      "y": 0,
      "z": -2,
      "name": "Plant_Grass_Jungle",
      "rotation": 1
    },
    {
      "x": 0,
      "y": 0,
      "z": -1,
      "name": "Wood_Crystal_Trunk_Stairs",
      "rotation": 2
    },
    {
      "x": 0,
      "y": 1,
      "z": -1,
      "name": "Wood_Crystal_Trunk_Half",
      "rotation": 6
    },
    {
      "x": 0,
      "y": 5,
      "z": -1,
      "name": "Wood_Crystal_Trunk_Half",
      "rotation": 6
    },
    {
      "x": 0,
      "y": 6,
      "z": -1,
      "name": "Wood_Crystal_Trunk_Half",
      "rotation": 6
    },
    {
      "x": 0,
      "y": 7,
      "z": -1,
      "name": "Wood_Crystal_Trunk_Stairs",
      "rotation": 8
    },
    {
      "x": 0,
      "y": 8,
      "z": -1,
      "name": "Wood_Crystal_Trunk_Stairs",
      "rotation": 8
    },
    {
      "x": 0,
      "y": 9,
      "z": -1,
      "name": "PortalKey_Luminara_Red",
      "filler": 992,
      "rotation": 3
    },
    {
      "x": 0,
      "y": 0,
      "z": 0,
      "name": "Wood_Crystal_Trunk_Full",
      "support": 15
    },
    {
      "x": 0,
      "y": 1,
      "z": 0,
      "name": "Wood_Crystal_Trunk_Full",
      "support": 15
    },
    {
      "x": 0,
      "y": 2,
      "z": 0,
      "name": "Wood_Crystal_Trunk_Full",
      "support": 15
    },
    {
      "x": 0,
      "y": 3,
      "z": 0,
      "name": "Wood_Crystal_Trunk_Full",
      "support": 15
    },
    {
      "x": 0,
      "y": 4,
      "z": 0,
      "name": "Wood_Crystal_Trunk_Full",
      "support": 15
    },
    {
      "x": 0,
      "y": 5,
      "z": 0,
      "name": "Wood_Crystal_Trunk_Full",
      "support": 15
    },
    {
      "x": 0,
      "y": 6,
      "z": 0,
      "name": "Wood_Crystal_Trunk_Full",
      "support": 15
    },
    {
      "x": 0,
      "y": 7,
      "z": 0,
      "name": "Wood_Crystal_Trunk_Full",
      "support": 15
    },
    {
      "x": 0,
      "y": 8,
      "z": 0,
      "name": "Wood_Crystal_Trunk_Full",
      "support": 15
    },
    {
      "x": 0,
      "y": 9,
      "z": 0,
      "name": "PortalKey_Luminara_Red",
      "rotation": 3
    },
    {
      "x": 0,
      "y": 0,
      "z": 1,
      "name": "Wood_Crystal_Trunk_Stairs"
    },
    {
      "x": 0,
      "y": 1,
      "z": 1,
      "name": "Wood_Crystal_Trunk_Half",
      "rotation": 4
    },
    {
      "x": 0,
      "y": 5,
      "z": 1,
      "name": "Wood_Crystal_Trunk_Half",
      "rotation": 4
    },
    {
      "x": 0,
      "y": 6,
      "z": 1,
      "name": "Wood_Crystal_Trunk_Half",
      "rotation": 4
    },
    {
      "x": 0,
      "y": 7,
      "z": 1,
      "name": "Wood_Crystal_Trunk_Stairs",
      "rotation": 10
    },
    {
      "x": 0,
      "y": 8,
      "z": 1,
      "name": "Wood_Crystal_Trunk_Stairs",
      "rotation": 10
    },
    {
      "x": 0,
      "y": 9,
      "z": 1,
      "name": "PortalKey_Luminara_Red",
      "filler": 32,
      "rotation": 3
    },
    {
      "x": 1,
      "y": 8,
      "z": -1,
      "name": "Wood_Crystal_Trunk_Full",
      "support": 15,
      "rotation": 5
    },
    {
      "x": 1,
      "y": 9,
      "z": -1,
      "name": "PortalKey_Luminara_Red",
      "filler": 993,
      "rotation": 3
    },
    {
      "x": 1,
      "y": 0,
      "z": 0,
      "name": "Wood_Crystal_Trunk_Stairs",
      "rotation": 1
    },
    {
      "x": 1,
      "y": 1,
      "z": 0,
      "name": "Wood_Crystal_Trunk_Half",
      "rotation": 5
    },
    {
      "x": 1,
      "y": 2,
      "z": 0,
      "name": "Wood_Crystal_Trunk_Half",
      "rotation": 5
    },
    {
      "x": 1,
      "y": 6,
      "z": 0,
      "name": "Wood_Crystal_Trunk_Half",
      "rotation": 5
    },
    {
      "x": 1,
      "y": 7,
      "z": 0,
      "name": "Wood_Crystal_Trunk_Stairs",
      "rotation": 11
    },
    {
      "x": 1,
      "y": 8,
      "z": 0,
      "name": "Wood_Crystal_Trunk_Stairs",
      "rotation": 11
    },
    {
      "x": 1,
      "y": 9,
      "z": 0,
      "name": "PortalKey_Luminara_Red",
      "filler": 1,
      "rotation": 3
    },
    {
      "x": 1,
      "y": 8,
      "z": 1,
      "name": "Wood_Crystal_Trunk_Full",
      "support": 15,
      "rotation": 4
    },
    {
      "x": 1,
      "y": 9,
      "z": 1,
      "name": "PortalKey_Luminara_Red",
      "filler": 33,
      "rotation": 3
    }
  ],
  "fluids": [
    {
      "x": -2,
      "y": 0,
      "z": 0,
      "name": "Empty",
      "level": 0
    },
    {
      "x": -2,
      "y": 0,
      "z": 2,
      "name": "Empty",
      "level": 0
    },
    {
      "x": -1,
      "y": 0,
      "z": -2,
      "name": "Empty",
      "level": 0
    },
    {
      "x": -1,
      "y": 8,
      "z": -1,
      "name": "Empty",
      "level": 0
    },
    {
      "x": -1,
      "y": 9,
      "z": -1,
      "name": "Empty",
      "level": 0
    },
    {
      "x": -1,
      "y": 0,
      "z": 0,
      "name": "Empty",
      "level": 0
    },
    {
      "x": -1,
      "y": 1,
      "z": 0,
      "name": "Empty",
      "level": 0
    },
    {
      "x": -1,
      "y": 2,
      "z": 0,
      "name": "Empty",
      "level": 0
    },
    {
      "x": -1,
      "y": 6,
      "z": 0,
      "name": "Empty",
      "level": 0
    },
    {
      "x": -1,
      "y": 7,
      "z": 0,
      "name": "Empty",
      "level": 0
    },
    {
      "x": -1,
      "y": 8,
      "z": 0,
      "name": "Empty",
      "level": 0
    },
    {
      "x": -1,
      "y": 9,
      "z": 0,
      "name": "Empty",
      "level": 0
    },
    {
      "x": -1,
      "y": 8,
      "z": 1,
      "name": "Empty",
      "level": 0
    },
    {
      "x": -1,
      "y": 9,
      "z": 1,
      "name": "Empty",
      "level": 0
    },
    {
      "x": 0,
      "y": 0,
      "z": -2,
      "name": "Empty",
      "level": 0
    },
    {
      "x": 0,
      "y": 0,
      "z": -1,
      "name": "Empty",
      "level": 0
    },
    {
      "x": 0,
      "y": 1,
      "z": -1,
      "name": "Empty",
      "level": 0
    },
    {
      "x": 0,
      "y": 5,
      "z": -1,
      "name": "Empty",
      "level": 0
    },
    {
      "x": 0,
      "y": 6,
      "z": -1,
      "name": "Empty",
      "level": 0
    },
    {
      "x": 0,
      "y": 7,
      "z": -1,
      "name": "Empty",
      "level": 0
    },
    {
      "x": 0,
      "y": 8,
      "z": -1,
      "name": "Empty",
      "level": 0
    },
    {
      "x": 0,
      "y": 9,
      "z": -1,
      "name": "Empty",
      "level": 0
    },
    {
      "x": 0,
      "y": 0,
      "z": 0,
      "name": "Empty",
      "level": 0
    },
    {
      "x": 0,
      "y": 1,
      "z": 0,
      "name": "Empty",
      "level": 0
    },
    {
      "x": 0,
      "y": 2,
      "z": 0,
      "name": "Empty",
      "level": 0
    },
    {
      "x": 0,
      "y": 3,
      "z": 0,
      "name": "Empty",
      "level": 0
    },
    {
      "x": 0,
      "y": 4,
      "z": 0,
      "name": "Empty",
      "level": 0
    },
    {
      "x": 0,
      "y": 5,
      "z": 0,
      "name": "Empty",
      "level": 0
    },
    {
      "x": 0,
      "y": 6,
      "z": 0,
      "name": "Empty",
      "level": 0
    },
    {
      "x": 0,
      "y": 7,
      "z": 0,
      "name": "Empty",
      "level": 0
    },
    {
      "x": 0,
      "y": 8,
      "z": 0,
      "name": "Empty",
      "level": 0
    },
    {
      "x": 0,
      "y": 9,
      "z": 0,
      "name": "Empty",
      "level": 0
    },
    {
      "x": 0,
      "y": 0,
      "z": 1,
      "name": "Empty",
      "level": 0
    },
    {
      "x": 0,
      "y": 1,
      "z": 1,
      "name": "Empty",
      "level": 0
    },
    {
      "x": 0,
      "y": 5,
      "z": 1,
      "name": "Empty",
      "level": 0
    },
    {
      "x": 0,
      "y": 6,
      "z": 1,
      "name": "Empty",
      "level": 0
    },
    {
      "x": 0,
      "y": 7,
      "z": 1,
      "name": "Empty",
      "level": 0
    },
    {
      "x": 0,
      "y": 8,
      "z": 1,
      "name": "Empty",
      "level": 0
    },
    {
      "x": 0,
      "y": 9,
      "z": 1,
      "name": "Empty",
      "level": 0
    },
    {
      "x": 1,
      "y": 8,
      "z": -1,
      "name": "Empty",
      "level": 0
    },
    {
      "x": 1,
      "y": 9,
      "z": -1,
      "name": "Empty",
      "level": 0
    },
    {
      "x": 1,
      "y": 0,
      "z": 0,
      "name": "Empty",
      "level": 0
    },
    {
      "x": 1,
      "y": 1,
      "z": 0,
      "name": "Empty",
      "level": 0
    },
    {
      "x": 1,
      "y": 2,
      "z": 0,
      "name": "Empty",
      "level": 0
    },
    {
      "x": 1,
      "y": 6,
      "z": 0,
      "name": "Empty",
      "level": 0
    },
    {
      "x": 1,
      "y": 7,
      "z": 0,
      "name": "Empty",
      "level": 0
    },
    {
      "x": 1,
      "y": 8,
      "z": 0,
      "name": "Empty",
      "level": 0
    },
    {
      "x": 1,
      "y": 9,
      "z": 0,
      "name": "Empty",
      "level": 0
    },
    {
      "x": 1,
      "y": 8,
      "z": 1,
      "name": "Empty",
      "level": 0
    },
    {
      "x": 1,
      "y": 9,
      "z": 1,
      "name": "Empty",
      "level": 0
    }
  ]
}